{"time":2015-04-12 14:04:49,384, "file": /usr/local/lib/python3.4/dist-packages/flask/app.py, "line" :1423, "messageLevel":  ERROR, "message": Exception on /view/testaus 3 [GET]}
Traceback (most recent call last):
  File "/usr/local/lib/python3.4/dist-packages/flask/app.py", line 1817, in wsgi_app
    response = self.full_dispatch_request()
  File "/usr/local/lib/python3.4/dist-packages/flask/app.py", line 1477, in full_dispatch_request
    rv = self.handle_user_exception(e)
  File "/usr/local/lib/python3.4/dist-packages/flask/app.py", line 1381, in handle_user_exception
    reraise(exc_type, exc_value, tb)
  File "/usr/local/lib/python3.4/dist-packages/flask/_compat.py", line 33, in reraise
    raise value
  File "/usr/local/lib/python3.4/dist-packages/flask/app.py", line 1475, in full_dispatch_request
    rv = self.dispatch_request()
  File "/usr/local/lib/python3.4/dist-packages/flask/app.py", line 1461, in dispatch_request
    return self.view_functions[rule.endpoint](**req.view_args)
  File "/service/timApp/routes/view.py", line 28, in view_document
    return view(doc_name, 'view_html.html', view_range)
  File "/service/timApp/routes/view.py", line 104, in view
    questions = timdb.questions.get_doc_questions(doc_id)
  File "<string>", line 2, in get_doc_questions
  File "/usr/local/lib/python3.4/dist-packages/contracts/main.py", line 266, in contracts_checker
    result = function_(*args, **kwargs)
  File "/service/timApp/timdb/questions.py", line 83, in get_doc_questions
    """, [doc_id])
sqlite3.OperationalError: no such column: doc_id
{"time":2015-04-12 14:08:19,909, "file": /usr/local/lib/python3.4/dist-packages/flask/app.py, "line" :1423, "messageLevel":  ERROR, "message": Exception on /view/testaus 3 [GET]}
Traceback (most recent call last):
  File "/usr/local/lib/python3.4/dist-packages/flask/app.py", line 1817, in wsgi_app
    response = self.full_dispatch_request()
  File "/usr/local/lib/python3.4/dist-packages/flask/app.py", line 1477, in full_dispatch_request
    rv = self.handle_user_exception(e)
  File "/usr/local/lib/python3.4/dist-packages/flask/app.py", line 1381, in handle_user_exception
    reraise(exc_type, exc_value, tb)
  File "/usr/local/lib/python3.4/dist-packages/flask/_compat.py", line 33, in reraise
    raise value
  File "/usr/local/lib/python3.4/dist-packages/flask/app.py", line 1475, in full_dispatch_request
    rv = self.dispatch_request()
  File "/usr/local/lib/python3.4/dist-packages/flask/app.py", line 1461, in dispatch_request
    return self.view_functions[rule.endpoint](**req.view_args)
  File "/service/timApp/routes/view.py", line 28, in view_document
    return view(doc_name, 'view_html.html', view_range)
  File "/service/timApp/routes/view.py", line 104, in view
    questions = timdb.questions.get_doc_questions(doc_id)
  File "<string>", line 2, in get_doc_questions
  File "/usr/local/lib/python3.4/dist-packages/contracts/main.py", line 266, in contracts_checker
    result = function_(*args, **kwargs)
  File "/service/timApp/timdb/questions.py", line 83, in get_doc_questions
    """, [doc_id])
sqlite3.OperationalError: no such column: doc_id
{"time":2015-04-12 14:08:52,086, "file": /usr/local/lib/python3.4/dist-packages/flask/app.py, "line" :1423, "messageLevel":  ERROR, "message": Exception on /view/testaus 3 [GET]}
Traceback (most recent call last):
  File "/usr/local/lib/python3.4/dist-packages/flask/app.py", line 1817, in wsgi_app
    response = self.full_dispatch_request()
  File "/usr/local/lib/python3.4/dist-packages/flask/app.py", line 1477, in full_dispatch_request
    rv = self.handle_user_exception(e)
  File "/usr/local/lib/python3.4/dist-packages/flask/app.py", line 1381, in handle_user_exception
    reraise(exc_type, exc_value, tb)
  File "/usr/local/lib/python3.4/dist-packages/flask/_compat.py", line 33, in reraise
    raise value
  File "/usr/local/lib/python3.4/dist-packages/flask/app.py", line 1475, in full_dispatch_request
    rv = self.dispatch_request()
  File "/usr/local/lib/python3.4/dist-packages/flask/app.py", line 1461, in dispatch_request
    return self.view_functions[rule.endpoint](**req.view_args)
  File "/service/timApp/routes/view.py", line 28, in view_document
    return view(doc_name, 'view_html.html', view_range)
  File "/service/timApp/routes/view.py", line 104, in view
    questions = timdb.questions.get_doc_questions(doc_id)
  File "<string>", line 2, in get_doc_questions
  File "/usr/local/lib/python3.4/dist-packages/contracts/main.py", line 266, in contracts_checker
    result = function_(*args, **kwargs)
  File "/service/timApp/timdb/questions.py", line 83, in get_doc_questions
    """, [doc_id])
sqlite3.OperationalError: no such column: doc_id
{"time":2015-04-12 14:18:52,112, "file": /usr/local/lib/python3.4/dist-packages/flask/app.py, "line" :1423, "messageLevel":  ERROR, "message": Exception on /view/testaus 3 [GET]}
Traceback (most recent call last):
  File "/usr/local/lib/python3.4/dist-packages/flask/app.py", line 1817, in wsgi_app
    response = self.full_dispatch_request()
  File "/usr/local/lib/python3.4/dist-packages/flask/app.py", line 1477, in full_dispatch_request
    rv = self.handle_user_exception(e)
  File "/usr/local/lib/python3.4/dist-packages/flask/app.py", line 1381, in handle_user_exception
    reraise(exc_type, exc_value, tb)
  File "/usr/local/lib/python3.4/dist-packages/flask/_compat.py", line 33, in reraise
    raise value
  File "/usr/local/lib/python3.4/dist-packages/flask/app.py", line 1475, in full_dispatch_request
    rv = self.dispatch_request()
  File "/usr/local/lib/python3.4/dist-packages/flask/app.py", line 1461, in dispatch_request
    return self.view_functions[rule.endpoint](**req.view_args)
  File "/service/timApp/routes/view.py", line 28, in view_document
    return view(doc_name, 'view_html.html', view_range)
  File "/service/timApp/routes/view.py", line 104, in view
    questions = timdb.questions.get_doc_questions(doc_id)
  File "<string>", line 2, in get_doc_questions
  File "/usr/local/lib/python3.4/dist-packages/contracts/main.py", line 266, in contracts_checker
    result = function_(*args, **kwargs)
  File "/service/timApp/timdb/questions.py", line 83, in get_doc_questions
    """, [doc_id])
sqlite3.OperationalError: no such column: doc_id
{"time":2015-04-12 14:43:03,465, "file": /usr/local/lib/python3.4/dist-packages/flask/app.py, "line" :1423, "messageLevel":  ERROR, "message": Exception on /view/Testaus 2 [GET]}
Traceback (most recent call last):
  File "/usr/local/lib/python3.4/dist-packages/flask/app.py", line 1817, in wsgi_app
    response = self.full_dispatch_request()
  File "/usr/local/lib/python3.4/dist-packages/flask/app.py", line 1477, in full_dispatch_request
    rv = self.handle_user_exception(e)
  File "/usr/local/lib/python3.4/dist-packages/flask/app.py", line 1381, in handle_user_exception
    reraise(exc_type, exc_value, tb)
  File "/usr/local/lib/python3.4/dist-packages/flask/_compat.py", line 33, in reraise
    raise value
  File "/usr/local/lib/python3.4/dist-packages/flask/app.py", line 1475, in full_dispatch_request
    rv = self.dispatch_request()
  File "/usr/local/lib/python3.4/dist-packages/flask/app.py", line 1461, in dispatch_request
    return self.view_functions[rule.endpoint](**req.view_args)
  File "/service/timApp/routes/view.py", line 28, in view_document
    return view(doc_name, 'view_html.html', view_range)
  File "/service/timApp/routes/view.py", line 104, in view
    questions = timdb.questions.get_doc_questions(doc_id)
  File "<string>", line 2, in get_doc_questions
  File "/usr/local/lib/python3.4/dist-packages/contracts/main.py", line 266, in contracts_checker
    result = function_(*args, **kwargs)
  File "/service/timApp/timdb/questions.py", line 83, in get_doc_questions
    """, [doc_id])
sqlite3.OperationalError: no such column: doc_id
{"time":2015-04-13 06:08:19,111, "file": /usr/local/lib/python3.4/dist-packages/flask/app.py, "line" :1423, "messageLevel":  ERROR, "message": Exception on /view/testaus 3 [GET]}
Traceback (most recent call last):
  File "/usr/local/lib/python3.4/dist-packages/flask/app.py", line 1817, in wsgi_app
    response = self.full_dispatch_request()
  File "/usr/local/lib/python3.4/dist-packages/flask/app.py", line 1477, in full_dispatch_request
    rv = self.handle_user_exception(e)
  File "/usr/local/lib/python3.4/dist-packages/flask/app.py", line 1381, in handle_user_exception
    reraise(exc_type, exc_value, tb)
  File "/usr/local/lib/python3.4/dist-packages/flask/_compat.py", line 33, in reraise
    raise value
  File "/usr/local/lib/python3.4/dist-packages/flask/app.py", line 1475, in full_dispatch_request
    rv = self.dispatch_request()
  File "/usr/local/lib/python3.4/dist-packages/flask/app.py", line 1461, in dispatch_request
    return self.view_functions[rule.endpoint](**req.view_args)
  File "/service/timApp/routes/view.py", line 28, in view_document
    return view(doc_name, 'view_html.html', view_range)
  File "/service/timApp/routes/view.py", line 104, in view
    questions = timdb.questions.get_doc_questions(doc_id)
  File "<string>", line 2, in get_doc_questions
  File "/usr/local/lib/python3.4/dist-packages/contracts/main.py", line 266, in contracts_checker
    result = function_(*args, **kwargs)
  File "/service/timApp/timdb/questions.py", line 83, in get_doc_questions
    """, [doc_id])
sqlite3.OperationalError: no such column: doc_id
{"time":2015-04-13 06:10:00,710, "file": /usr/local/lib/python3.4/dist-packages/flask/app.py, "line" :1423, "messageLevel":  ERROR, "message": Exception on /view/testaus 3 [GET]}
Traceback (most recent call last):
  File "/usr/local/lib/python3.4/dist-packages/flask/app.py", line 1817, in wsgi_app
    response = self.full_dispatch_request()
  File "/usr/local/lib/python3.4/dist-packages/flask/app.py", line 1477, in full_dispatch_request
    rv = self.handle_user_exception(e)
  File "/usr/local/lib/python3.4/dist-packages/flask/app.py", line 1381, in handle_user_exception
    reraise(exc_type, exc_value, tb)
  File "/usr/local/lib/python3.4/dist-packages/flask/_compat.py", line 33, in reraise
    raise value
  File "/usr/local/lib/python3.4/dist-packages/flask/app.py", line 1475, in full_dispatch_request
    rv = self.dispatch_request()
  File "/usr/local/lib/python3.4/dist-packages/flask/app.py", line 1461, in dispatch_request
    return self.view_functions[rule.endpoint](**req.view_args)
  File "/service/timApp/routes/view.py", line 28, in view_document
    return view(doc_name, 'view_html.html', view_range)
  File "/service/timApp/routes/view.py", line 104, in view
    questions = timdb.questions.get_doc_questions(doc_id)
  File "<string>", line 2, in get_doc_questions
  File "/usr/local/lib/python3.4/dist-packages/contracts/main.py", line 266, in contracts_checker
    result = function_(*args, **kwargs)
  File "/service/timApp/timdb/questions.py", line 83, in get_doc_questions
    """, [doc_id])
sqlite3.OperationalError: no such column: doc_id
{"time":2015-04-13 06:11:16,452, "file": /usr/local/lib/python3.4/dist-packages/flask/app.py, "line" :1423, "messageLevel":  ERROR, "message": Exception on /view/testaus 3 [GET]}
Traceback (most recent call last):
  File "/usr/local/lib/python3.4/dist-packages/flask/app.py", line 1817, in wsgi_app
    response = self.full_dispatch_request()
  File "/usr/local/lib/python3.4/dist-packages/flask/app.py", line 1477, in full_dispatch_request
    rv = self.handle_user_exception(e)
  File "/usr/local/lib/python3.4/dist-packages/flask/app.py", line 1381, in handle_user_exception
    reraise(exc_type, exc_value, tb)
  File "/usr/local/lib/python3.4/dist-packages/flask/_compat.py", line 33, in reraise
    raise value
  File "/usr/local/lib/python3.4/dist-packages/flask/app.py", line 1475, in full_dispatch_request
    rv = self.dispatch_request()
  File "/usr/local/lib/python3.4/dist-packages/flask/app.py", line 1461, in dispatch_request
    return self.view_functions[rule.endpoint](**req.view_args)
  File "/service/timApp/routes/view.py", line 28, in view_document
    return view(doc_name, 'view_html.html', view_range)
  File "/service/timApp/routes/view.py", line 104, in view
    questions = timdb.questions.get_doc_questions(doc_id)
  File "<string>", line 2, in get_doc_questions
  File "/usr/local/lib/python3.4/dist-packages/contracts/main.py", line 266, in contracts_checker
    result = function_(*args, **kwargs)
  File "/service/timApp/timdb/questions.py", line 83, in get_doc_questions
    """, [doc_id])
sqlite3.OperationalError: no such column: doc_id
{"time":2015-04-13 06:19:16,245, "file": /usr/local/lib/python3.4/dist-packages/flask/app.py, "line" :1423, "messageLevel":  ERROR, "message": Exception on /view/testaus 3 [GET]}
Traceback (most recent call last):
  File "/usr/local/lib/python3.4/dist-packages/flask/app.py", line 1817, in wsgi_app
    response = self.full_dispatch_request()
  File "/usr/local/lib/python3.4/dist-packages/flask/app.py", line 1477, in full_dispatch_request
    rv = self.handle_user_exception(e)
  File "/usr/local/lib/python3.4/dist-packages/flask/app.py", line 1381, in handle_user_exception
    reraise(exc_type, exc_value, tb)
  File "/usr/local/lib/python3.4/dist-packages/flask/_compat.py", line 33, in reraise
    raise value
  File "/usr/local/lib/python3.4/dist-packages/flask/app.py", line 1475, in full_dispatch_request
    rv = self.dispatch_request()
  File "/usr/local/lib/python3.4/dist-packages/flask/app.py", line 1461, in dispatch_request
    return self.view_functions[rule.endpoint](**req.view_args)
  File "/service/timApp/routes/view.py", line 28, in view_document
    return view(doc_name, 'view_html.html', view_range)
  File "/service/timApp/routes/view.py", line 104, in view
    questions = timdb.questions.get_doc_questions(doc_id)
  File "<string>", line 2, in get_doc_questions
  File "/usr/local/lib/python3.4/dist-packages/contracts/main.py", line 266, in contracts_checker
    result = function_(*args, **kwargs)
  File "/service/timApp/timdb/questions.py", line 83, in get_doc_questions
    """, [doc_id])
sqlite3.OperationalError: no such column: doc_id
{"time":2015-04-13 06:19:18,128, "file": /usr/local/lib/python3.4/dist-packages/flask/app.py, "line" :1423, "messageLevel":  ERROR, "message": Exception on /view/testaus 3 [GET]}
Traceback (most recent call last):
  File "/usr/local/lib/python3.4/dist-packages/flask/app.py", line 1817, in wsgi_app
    response = self.full_dispatch_request()
  File "/usr/local/lib/python3.4/dist-packages/flask/app.py", line 1477, in full_dispatch_request
    rv = self.handle_user_exception(e)
  File "/usr/local/lib/python3.4/dist-packages/flask/app.py", line 1381, in handle_user_exception
    reraise(exc_type, exc_value, tb)
  File "/usr/local/lib/python3.4/dist-packages/flask/_compat.py", line 33, in reraise
    raise value
  File "/usr/local/lib/python3.4/dist-packages/flask/app.py", line 1475, in full_dispatch_request
    rv = self.dispatch_request()
  File "/usr/local/lib/python3.4/dist-packages/flask/app.py", line 1461, in dispatch_request
    return self.view_functions[rule.endpoint](**req.view_args)
  File "/service/timApp/routes/view.py", line 28, in view_document
    return view(doc_name, 'view_html.html', view_range)
  File "/service/timApp/routes/view.py", line 104, in view
    questions = timdb.questions.get_doc_questions(doc_id)
  File "<string>", line 2, in get_doc_questions
  File "/usr/local/lib/python3.4/dist-packages/contracts/main.py", line 266, in contracts_checker
    result = function_(*args, **kwargs)
  File "/service/timApp/timdb/questions.py", line 83, in get_doc_questions
    """, [doc_id])
sqlite3.OperationalError: no such column: doc_id
{"time":2015-04-13 06:19:18,710, "file": /usr/local/lib/python3.4/dist-packages/flask/app.py, "line" :1423, "messageLevel":  ERROR, "message": Exception on /view/testaus 3 [GET]}
Traceback (most recent call last):
  File "/usr/local/lib/python3.4/dist-packages/flask/app.py", line 1817, in wsgi_app
    response = self.full_dispatch_request()
  File "/usr/local/lib/python3.4/dist-packages/flask/app.py", line 1477, in full_dispatch_request
    rv = self.handle_user_exception(e)
  File "/usr/local/lib/python3.4/dist-packages/flask/app.py", line 1381, in handle_user_exception
    reraise(exc_type, exc_value, tb)
  File "/usr/local/lib/python3.4/dist-packages/flask/_compat.py", line 33, in reraise
    raise value
  File "/usr/local/lib/python3.4/dist-packages/flask/app.py", line 1475, in full_dispatch_request
    rv = self.dispatch_request()
  File "/usr/local/lib/python3.4/dist-packages/flask/app.py", line 1461, in dispatch_request
    return self.view_functions[rule.endpoint](**req.view_args)
  File "/service/timApp/routes/view.py", line 28, in view_document
    return view(doc_name, 'view_html.html', view_range)
  File "/service/timApp/routes/view.py", line 104, in view
    questions = timdb.questions.get_doc_questions(doc_id)
  File "<string>", line 2, in get_doc_questions
  File "/usr/local/lib/python3.4/dist-packages/contracts/main.py", line 266, in contracts_checker
    result = function_(*args, **kwargs)
  File "/service/timApp/timdb/questions.py", line 83, in get_doc_questions
    """, [doc_id])
sqlite3.OperationalError: no such column: doc_id
{"time":2015-04-13 06:19:19,001, "file": /usr/local/lib/python3.4/dist-packages/flask/app.py, "line" :1423, "messageLevel":  ERROR, "message": Exception on /view/testaus 3 [GET]}
Traceback (most recent call last):
  File "/usr/local/lib/python3.4/dist-packages/flask/app.py", line 1817, in wsgi_app
    response = self.full_dispatch_request()
  File "/usr/local/lib/python3.4/dist-packages/flask/app.py", line 1477, in full_dispatch_request
    rv = self.handle_user_exception(e)
  File "/usr/local/lib/python3.4/dist-packages/flask/app.py", line 1381, in handle_user_exception
    reraise(exc_type, exc_value, tb)
  File "/usr/local/lib/python3.4/dist-packages/flask/_compat.py", line 33, in reraise
    raise value
  File "/usr/local/lib/python3.4/dist-packages/flask/app.py", line 1475, in full_dispatch_request
    rv = self.dispatch_request()
  File "/usr/local/lib/python3.4/dist-packages/flask/app.py", line 1461, in dispatch_request
    return self.view_functions[rule.endpoint](**req.view_args)
  File "/service/timApp/routes/view.py", line 28, in view_document
    return view(doc_name, 'view_html.html', view_range)
  File "/service/timApp/routes/view.py", line 104, in view
    questions = timdb.questions.get_doc_questions(doc_id)
  File "<string>", line 2, in get_doc_questions
  File "/usr/local/lib/python3.4/dist-packages/contracts/main.py", line 266, in contracts_checker
    result = function_(*args, **kwargs)
  File "/service/timApp/timdb/questions.py", line 83, in get_doc_questions
    """, [doc_id])
sqlite3.OperationalError: no such column: doc_id
{"time":2015-04-13 06:19:19,200, "file": /usr/local/lib/python3.4/dist-packages/flask/app.py, "line" :1423, "messageLevel":  ERROR, "message": Exception on /view/testaus 3 [GET]}
Traceback (most recent call last):
  File "/usr/local/lib/python3.4/dist-packages/flask/app.py", line 1817, in wsgi_app
    response = self.full_dispatch_request()
  File "/usr/local/lib/python3.4/dist-packages/flask/app.py", line 1477, in full_dispatch_request
    rv = self.handle_user_exception(e)
  File "/usr/local/lib/python3.4/dist-packages/flask/app.py", line 1381, in handle_user_exception
    reraise(exc_type, exc_value, tb)
  File "/usr/local/lib/python3.4/dist-packages/flask/_compat.py", line 33, in reraise
    raise value
  File "/usr/local/lib/python3.4/dist-packages/flask/app.py", line 1475, in full_dispatch_request
    rv = self.dispatch_request()
  File "/usr/local/lib/python3.4/dist-packages/flask/app.py", line 1461, in dispatch_request
    return self.view_functions[rule.endpoint](**req.view_args)
  File "/service/timApp/routes/view.py", line 28, in view_document
    return view(doc_name, 'view_html.html', view_range)
  File "/service/timApp/routes/view.py", line 104, in view
    questions = timdb.questions.get_doc_questions(doc_id)
  File "<string>", line 2, in get_doc_questions
  File "/usr/local/lib/python3.4/dist-packages/contracts/main.py", line 266, in contracts_checker
    result = function_(*args, **kwargs)
  File "/service/timApp/timdb/questions.py", line 83, in get_doc_questions
    """, [doc_id])
sqlite3.OperationalError: no such column: doc_id
{"time":2015-04-13 06:19:19,399, "file": /usr/local/lib/python3.4/dist-packages/flask/app.py, "line" :1423, "messageLevel":  ERROR, "message": Exception on /view/testaus 3 [GET]}
Traceback (most recent call last):
  File "/usr/local/lib/python3.4/dist-packages/flask/app.py", line 1817, in wsgi_app
    response = self.full_dispatch_request()
  File "/usr/local/lib/python3.4/dist-packages/flask/app.py", line 1477, in full_dispatch_request
    rv = self.handle_user_exception(e)
  File "/usr/local/lib/python3.4/dist-packages/flask/app.py", line 1381, in handle_user_exception
    reraise(exc_type, exc_value, tb)
  File "/usr/local/lib/python3.4/dist-packages/flask/_compat.py", line 33, in reraise
    raise value
  File "/usr/local/lib/python3.4/dist-packages/flask/app.py", line 1475, in full_dispatch_request
    rv = self.dispatch_request()
  File "/usr/local/lib/python3.4/dist-packages/flask/app.py", line 1461, in dispatch_request
    return self.view_functions[rule.endpoint](**req.view_args)
  File "/service/timApp/routes/view.py", line 28, in view_document
    return view(doc_name, 'view_html.html', view_range)
  File "/service/timApp/routes/view.py", line 104, in view
    questions = timdb.questions.get_doc_questions(doc_id)
  File "<string>", line 2, in get_doc_questions
  File "/usr/local/lib/python3.4/dist-packages/contracts/main.py", line 266, in contracts_checker
    result = function_(*args, **kwargs)
  File "/service/timApp/timdb/questions.py", line 83, in get_doc_questions
    """, [doc_id])
sqlite3.OperationalError: no such column: doc_id
{"time":2015-04-13 06:19:24,365, "file": /usr/local/lib/python3.4/dist-packages/flask/app.py, "line" :1423, "messageLevel":  ERROR, "message": Exception on /view/testaus 3 [GET]}
Traceback (most recent call last):
  File "/usr/local/lib/python3.4/dist-packages/flask/app.py", line 1817, in wsgi_app
    response = self.full_dispatch_request()
  File "/usr/local/lib/python3.4/dist-packages/flask/app.py", line 1477, in full_dispatch_request
    rv = self.handle_user_exception(e)
  File "/usr/local/lib/python3.4/dist-packages/flask/app.py", line 1381, in handle_user_exception
    reraise(exc_type, exc_value, tb)
  File "/usr/local/lib/python3.4/dist-packages/flask/_compat.py", line 33, in reraise
    raise value
  File "/usr/local/lib/python3.4/dist-packages/flask/app.py", line 1475, in full_dispatch_request
    rv = self.dispatch_request()
  File "/usr/local/lib/python3.4/dist-packages/flask/app.py", line 1461, in dispatch_request
    return self.view_functions[rule.endpoint](**req.view_args)
  File "/service/timApp/routes/view.py", line 28, in view_document
    return view(doc_name, 'view_html.html', view_range)
  File "/service/timApp/routes/view.py", line 104, in view
    questions = timdb.questions.get_doc_questions(doc_id)
  File "<string>", line 2, in get_doc_questions
  File "/usr/local/lib/python3.4/dist-packages/contracts/main.py", line 266, in contracts_checker
    result = function_(*args, **kwargs)
  File "/service/timApp/timdb/questions.py", line 83, in get_doc_questions
    """, [doc_id])
sqlite3.OperationalError: no such column: doc_id
{"time":2015-04-13 06:19:27,980, "file": /usr/local/lib/python3.4/dist-packages/flask/app.py, "line" :1423, "messageLevel":  ERROR, "message": Exception on /view/testaus 3 [GET]}
Traceback (most recent call last):
  File "/usr/local/lib/python3.4/dist-packages/flask/app.py", line 1817, in wsgi_app
    response = self.full_dispatch_request()
  File "/usr/local/lib/python3.4/dist-packages/flask/app.py", line 1477, in full_dispatch_request
    rv = self.handle_user_exception(e)
  File "/usr/local/lib/python3.4/dist-packages/flask/app.py", line 1381, in handle_user_exception
    reraise(exc_type, exc_value, tb)
  File "/usr/local/lib/python3.4/dist-packages/flask/_compat.py", line 33, in reraise
    raise value
  File "/usr/local/lib/python3.4/dist-packages/flask/app.py", line 1475, in full_dispatch_request
    rv = self.dispatch_request()
  File "/usr/local/lib/python3.4/dist-packages/flask/app.py", line 1461, in dispatch_request
    return self.view_functions[rule.endpoint](**req.view_args)
  File "/service/timApp/routes/view.py", line 28, in view_document
    return view(doc_name, 'view_html.html', view_range)
  File "/service/timApp/routes/view.py", line 104, in view
    questions = timdb.questions.get_doc_questions(doc_id)
  File "<string>", line 2, in get_doc_questions
  File "/usr/local/lib/python3.4/dist-packages/contracts/main.py", line 266, in contracts_checker
    result = function_(*args, **kwargs)
  File "/service/timApp/timdb/questions.py", line 83, in get_doc_questions
    """, [doc_id])
sqlite3.OperationalError: no such column: doc_id
{"time":2015-04-13 10:54:04,785, "file": /usr/local/lib/python3.4/dist-packages/flask/app.py, "line" :1423, "messageLevel":  ERROR, "message": Exception on /question [GET]}
Traceback (most recent call last):
  File "/usr/local/lib/python3.4/dist-packages/flask/app.py", line 1817, in wsgi_app
    response = self.full_dispatch_request()
  File "/usr/local/lib/python3.4/dist-packages/flask/app.py", line 1477, in full_dispatch_request
    rv = self.handle_user_exception(e)
  File "/usr/local/lib/python3.4/dist-packages/flask/app.py", line 1381, in handle_user_exception
    reraise(exc_type, exc_value, tb)
  File "/usr/local/lib/python3.4/dist-packages/flask/_compat.py", line 33, in reraise
    raise value
  File "/usr/local/lib/python3.4/dist-packages/flask/app.py", line 1475, in full_dispatch_request
    rv = self.dispatch_request()
  File "/usr/local/lib/python3.4/dist-packages/flask/app.py", line 1461, in dispatch_request
    return self.view_functions[rule.endpoint](**req.view_args)
  File "/service/timApp/tim.py", line 269, in show_question
    return render_template('question.html')
  File "/usr/local/lib/python3.4/dist-packages/flask/templating.py", line 128, in render_template
    context, ctx.app)
  File "/usr/local/lib/python3.4/dist-packages/flask/templating.py", line 110, in _render
    rv = template.render(context)
  File "/usr/local/lib/python3.4/dist-packages/jinja2/environment.py", line 969, in render
    return self.environment.handle_exception(exc_info, True)
  File "/usr/local/lib/python3.4/dist-packages/jinja2/environment.py", line 742, in handle_exception
    reraise(exc_type, exc_value, tb)
  File "/usr/local/lib/python3.4/dist-packages/jinja2/_compat.py", line 36, in reraise
    raise value.with_traceback(tb)
  File "/service/timApp/templates/question.html", line 16, in <module>
    {% include 'matriisi.html' %}
  File "/service/timApp/templates/matriisi.html", line 13, in <module>
    Koko: {{ rows.length }} x {{ columns.length }}
  File "/usr/local/lib/python3.4/dist-packages/jinja2/environment.py", line 397, in getattr
    return getattr(obj, attribute)
jinja2.exceptions.UndefinedError: 'rows' is undefined
{"time":2015-04-17 17:29:03,256, "file": /usr/local/lib/python3.4/dist-packages/flask/app.py, "line" :1423, "messageLevel":  ERROR, "message": Exception on /addQuestion [POST]}
Traceback (most recent call last):
  File "/usr/local/lib/python3.4/dist-packages/flask/app.py", line 1817, in wsgi_app
    response = self.full_dispatch_request()
  File "/usr/local/lib/python3.4/dist-packages/flask/app.py", line 1477, in full_dispatch_request
    rv = self.handle_user_exception(e)
  File "/usr/local/lib/python3.4/dist-packages/flask/app.py", line 1381, in handle_user_exception
    reraise(exc_type, exc_value, tb)
  File "/usr/local/lib/python3.4/dist-packages/flask/_compat.py", line 33, in reraise
    raise value
  File "/usr/local/lib/python3.4/dist-packages/flask/app.py", line 1475, in full_dispatch_request
    rv = self.dispatch_request()
  File "/usr/local/lib/python3.4/dist-packages/flask/app.py", line 1461, in dispatch_request
    return self.view_functions[rule.endpoint](**req.view_args)
  File "/service/timApp/tim.py", line 305, in add_question
    questions = timdb.questions.add_questions(doc_id, par_index, question, answer, questionJson)
  File "<string>", line 2, in add_questions
  File "/usr/local/lib/python3.4/dist-packages/contracts/main.py", line 266, in contracts_checker
    result = function_(*args, **kwargs)
  File "/service/timApp/timdb/questions.py", line 66, in add_questions
    """, [doc_id, par_index, question, answer, questionJson])
sqlite3.OperationalError: table Question has no column named questionJson
{"time":2015-04-17 19:05:19,361, "file": /usr/local/lib/python3.4/dist-packages/flask/app.py, "line" :1423, "messageLevel":  ERROR, "message": Exception on /read/3 [GET]}
Traceback (most recent call last):
  File "/usr/local/lib/python3.4/dist-packages/flask/app.py", line 1817, in wsgi_app
    response = self.full_dispatch_request()
  File "/usr/local/lib/python3.4/dist-packages/flask/app.py", line 1477, in full_dispatch_request
    rv = self.handle_user_exception(e)
  File "/usr/local/lib/python3.4/dist-packages/flask/app.py", line 1381, in handle_user_exception
    reraise(exc_type, exc_value, tb)
  File "/usr/local/lib/python3.4/dist-packages/flask/_compat.py", line 33, in reraise
    raise value
  File "/usr/local/lib/python3.4/dist-packages/flask/app.py", line 1475, in full_dispatch_request
    rv = self.dispatch_request()
  File "/usr/local/lib/python3.4/dist-packages/flask/app.py", line 1461, in dispatch_request
    return self.view_functions[rule.endpoint](**req.view_args)
  File "/service/timApp/tim.py", line 667, in getReadParagraphs
    doc_ver = timdb.documents.getNewestVersionHash(doc_id)
  File "<string>", line 2, in getNewestVersionHash
  File "/usr/local/lib/python3.4/dist-packages/contracts/main.py", line 266, in contracts_checker
    result = function_(*args, **kwargs)
  File "/service/timApp/timdb/documents.py", line 430, in getNewestVersionHash
    return cursor.fetchone()[0]
TypeError: 'NoneType' object is not subscriptable
{"time":2015-04-17 19:05:19,365, "file": /usr/local/lib/python3.4/dist-packages/flask/app.py, "line" :1423, "messageLevel":  ERROR, "message": Exception on /index/3 [GET]}
Traceback (most recent call last):
  File "/usr/local/lib/python3.4/dist-packages/flask/app.py", line 1817, in wsgi_app
    response = self.full_dispatch_request()
  File "/usr/local/lib/python3.4/dist-packages/flask/app.py", line 1477, in full_dispatch_request
    rv = self.handle_user_exception(e)
  File "/usr/local/lib/python3.4/dist-packages/flask/app.py", line 1381, in handle_user_exception
    reraise(exc_type, exc_value, tb)
  File "/usr/local/lib/python3.4/dist-packages/flask/_compat.py", line 33, in reraise
    raise value
  File "/usr/local/lib/python3.4/dist-packages/flask/app.py", line 1475, in full_dispatch_request
    rv = self.dispatch_request()
  File "/usr/local/lib/python3.4/dist-packages/flask/app.py", line 1461, in dispatch_request
    return self.view_functions[rule.endpoint](**req.view_args)
  File "/service/timApp/tim.py", line 568, in getIndex
    index = timdb.documents.getIndex(getNewest(docId))
  File "/service/timApp/routes/common.py", line 80, in getNewest
    version = timdb.documents.getNewestVersionHash(docId)
  File "<string>", line 2, in getNewestVersionHash
  File "/usr/local/lib/python3.4/dist-packages/contracts/main.py", line 266, in contracts_checker
    result = function_(*args, **kwargs)
  File "/service/timApp/timdb/documents.py", line 430, in getNewestVersionHash
    return cursor.fetchone()[0]
TypeError: 'NoneType' object is not subscriptable
{"time":2015-04-17 19:05:19,376, "file": /usr/local/lib/python3.4/dist-packages/flask/app.py, "line" :1423, "messageLevel":  ERROR, "message": Exception on /notes/3 [GET]}
Traceback (most recent call last):
  File "/usr/local/lib/python3.4/dist-packages/flask/app.py", line 1817, in wsgi_app
    response = self.full_dispatch_request()
  File "/usr/local/lib/python3.4/dist-packages/flask/app.py", line 1477, in full_dispatch_request
    rv = self.handle_user_exception(e)
  File "/usr/local/lib/python3.4/dist-packages/flask/app.py", line 1381, in handle_user_exception
    reraise(exc_type, exc_value, tb)
  File "/usr/local/lib/python3.4/dist-packages/flask/_compat.py", line 33, in reraise
    raise value
  File "/usr/local/lib/python3.4/dist-packages/flask/app.py", line 1475, in full_dispatch_request
    rv = self.dispatch_request()
  File "/usr/local/lib/python3.4/dist-packages/flask/app.py", line 1461, in dispatch_request
    return self.view_functions[rule.endpoint](**req.view_args)
  File "/service/timApp/tim.py", line 651, in getNotes
    doc_ver = timdb.documents.getNewestVersionHash(doc_id)
  File "<string>", line 2, in getNewestVersionHash
  File "/usr/local/lib/python3.4/dist-packages/contracts/main.py", line 266, in contracts_checker
    result = function_(*args, **kwargs)
  File "/service/timApp/timdb/documents.py", line 430, in getNewestVersionHash
    return cursor.fetchone()[0]
TypeError: 'NoneType' object is not subscriptable
{"time":2015-04-17 19:05:29,537, "file": /usr/local/lib/python3.4/dist-packages/flask/app.py, "line" :1423, "messageLevel":  ERROR, "message": Exception on /notes/3 [GET]}
Traceback (most recent call last):
  File "/usr/local/lib/python3.4/dist-packages/flask/app.py", line 1817, in wsgi_app
    response = self.full_dispatch_request()
  File "/usr/local/lib/python3.4/dist-packages/flask/app.py", line 1477, in full_dispatch_request
    rv = self.handle_user_exception(e)
  File "/usr/local/lib/python3.4/dist-packages/flask/app.py", line 1381, in handle_user_exception
    reraise(exc_type, exc_value, tb)
  File "/usr/local/lib/python3.4/dist-packages/flask/_compat.py", line 33, in reraise
    raise value
  File "/usr/local/lib/python3.4/dist-packages/flask/app.py", line 1475, in full_dispatch_request
    rv = self.dispatch_request()
  File "/usr/local/lib/python3.4/dist-packages/flask/app.py", line 1461, in dispatch_request
    return self.view_functions[rule.endpoint](**req.view_args)
  File "/service/timApp/tim.py", line 651, in getNotes
    doc_ver = timdb.documents.getNewestVersionHash(doc_id)
  File "<string>", line 2, in getNewestVersionHash
  File "/usr/local/lib/python3.4/dist-packages/contracts/main.py", line 266, in contracts_checker
    result = function_(*args, **kwargs)
  File "/service/timApp/timdb/documents.py", line 430, in getNewestVersionHash
    return cursor.fetchone()[0]
TypeError: 'NoneType' object is not subscriptable
{"time":2015-04-17 19:05:34,471, "file": /usr/local/lib/python3.4/dist-packages/flask/app.py, "line" :1423, "messageLevel":  ERROR, "message": Exception on /index/3 [GET]}
Traceback (most recent call last):
  File "/usr/local/lib/python3.4/dist-packages/flask/app.py", line 1817, in wsgi_app
    response = self.full_dispatch_request()
  File "/usr/local/lib/python3.4/dist-packages/flask/app.py", line 1477, in full_dispatch_request
    rv = self.handle_user_exception(e)
  File "/usr/local/lib/python3.4/dist-packages/flask/app.py", line 1381, in handle_user_exception
    reraise(exc_type, exc_value, tb)
  File "/usr/local/lib/python3.4/dist-packages/flask/_compat.py", line 33, in reraise
    raise value
  File "/usr/local/lib/python3.4/dist-packages/flask/app.py", line 1475, in full_dispatch_request
    rv = self.dispatch_request()
  File "/usr/local/lib/python3.4/dist-packages/flask/app.py", line 1461, in dispatch_request
    return self.view_functions[rule.endpoint](**req.view_args)
  File "/service/timApp/tim.py", line 568, in getIndex
    index = timdb.documents.getIndex(getNewest(docId))
  File "/service/timApp/routes/common.py", line 80, in getNewest
    version = timdb.documents.getNewestVersionHash(docId)
  File "<string>", line 2, in getNewestVersionHash
  File "/usr/local/lib/python3.4/dist-packages/contracts/main.py", line 266, in contracts_checker
    result = function_(*args, **kwargs)
  File "/service/timApp/timdb/documents.py", line 430, in getNewestVersionHash
    return cursor.fetchone()[0]
TypeError: 'NoneType' object is not subscriptable
{"time":2015-04-17 19:05:34,473, "file": /usr/local/lib/python3.4/dist-packages/flask/app.py, "line" :1423, "messageLevel":  ERROR, "message": Exception on /read/3 [GET]}
Traceback (most recent call last):
  File "/usr/local/lib/python3.4/dist-packages/flask/app.py", line 1817, in wsgi_app
    response = self.full_dispatch_request()
  File "/usr/local/lib/python3.4/dist-packages/flask/app.py", line 1477, in full_dispatch_request
    rv = self.handle_user_exception(e)
  File "/usr/local/lib/python3.4/dist-packages/flask/app.py", line 1381, in handle_user_exception
    reraise(exc_type, exc_value, tb)
  File "/usr/local/lib/python3.4/dist-packages/flask/_compat.py", line 33, in reraise
    raise value
  File "/usr/local/lib/python3.4/dist-packages/flask/app.py", line 1475, in full_dispatch_request
    rv = self.dispatch_request()
  File "/usr/local/lib/python3.4/dist-packages/flask/app.py", line 1461, in dispatch_request
    return self.view_functions[rule.endpoint](**req.view_args)
  File "/service/timApp/tim.py", line 667, in getReadParagraphs
    doc_ver = timdb.documents.getNewestVersionHash(doc_id)
  File "<string>", line 2, in getNewestVersionHash
  File "/usr/local/lib/python3.4/dist-packages/contracts/main.py", line 266, in contracts_checker
    result = function_(*args, **kwargs)
  File "/service/timApp/timdb/documents.py", line 430, in getNewestVersionHash
    return cursor.fetchone()[0]
TypeError: 'NoneType' object is not subscriptable
{"time":2015-04-17 19:05:34,473, "file": /usr/local/lib/python3.4/dist-packages/flask/app.py, "line" :1423, "messageLevel":  ERROR, "message": Exception on /notes/3 [GET]}
Traceback (most recent call last):
  File "/usr/local/lib/python3.4/dist-packages/flask/app.py", line 1817, in wsgi_app
    response = self.full_dispatch_request()
  File "/usr/local/lib/python3.4/dist-packages/flask/app.py", line 1477, in full_dispatch_request
    rv = self.handle_user_exception(e)
  File "/usr/local/lib/python3.4/dist-packages/flask/app.py", line 1381, in handle_user_exception
    reraise(exc_type, exc_value, tb)
  File "/usr/local/lib/python3.4/dist-packages/flask/_compat.py", line 33, in reraise
    raise value
  File "/usr/local/lib/python3.4/dist-packages/flask/app.py", line 1475, in full_dispatch_request
    rv = self.dispatch_request()
  File "/usr/local/lib/python3.4/dist-packages/flask/app.py", line 1461, in dispatch_request
    return self.view_functions[rule.endpoint](**req.view_args)
  File "/service/timApp/tim.py", line 651, in getNotes
    doc_ver = timdb.documents.getNewestVersionHash(doc_id)
  File "<string>", line 2, in getNewestVersionHash
  File "/usr/local/lib/python3.4/dist-packages/contracts/main.py", line 266, in contracts_checker
    result = function_(*args, **kwargs)
  File "/service/timApp/timdb/documents.py", line 430, in getNewestVersionHash
    return cursor.fetchone()[0]
TypeError: 'NoneType' object is not subscriptable
{"time":2015-04-17 19:06:08,731, "file": /usr/local/lib/python3.4/dist-packages/flask/app.py, "line" :1423, "messageLevel":  ERROR, "message": Exception on /index/3 [GET]}
Traceback (most recent call last):
  File "/usr/local/lib/python3.4/dist-packages/flask/app.py", line 1817, in wsgi_app
    response = self.full_dispatch_request()
  File "/usr/local/lib/python3.4/dist-packages/flask/app.py", line 1477, in full_dispatch_request
    rv = self.handle_user_exception(e)
  File "/usr/local/lib/python3.4/dist-packages/flask/app.py", line 1381, in handle_user_exception
    reraise(exc_type, exc_value, tb)
  File "/usr/local/lib/python3.4/dist-packages/flask/_compat.py", line 33, in reraise
    raise value
  File "/usr/local/lib/python3.4/dist-packages/flask/app.py", line 1475, in full_dispatch_request
    rv = self.dispatch_request()
  File "/usr/local/lib/python3.4/dist-packages/flask/app.py", line 1461, in dispatch_request
    return self.view_functions[rule.endpoint](**req.view_args)
  File "/service/timApp/tim.py", line 568, in getIndex
    index = timdb.documents.getIndex(getNewest(docId))
  File "/service/timApp/routes/common.py", line 80, in getNewest
    version = timdb.documents.getNewestVersionHash(docId)
  File "<string>", line 2, in getNewestVersionHash
  File "/usr/local/lib/python3.4/dist-packages/contracts/main.py", line 266, in contracts_checker
    result = function_(*args, **kwargs)
  File "/service/timApp/timdb/documents.py", line 430, in getNewestVersionHash
    return cursor.fetchone()[0]
TypeError: 'NoneType' object is not subscriptable
{"time":2015-04-17 19:06:08,750, "file": /usr/local/lib/python3.4/dist-packages/flask/app.py, "line" :1423, "messageLevel":  ERROR, "message": Exception on /read/3 [GET]}
Traceback (most recent call last):
  File "/usr/local/lib/python3.4/dist-packages/flask/app.py", line 1817, in wsgi_app
    response = self.full_dispatch_request()
  File "/usr/local/lib/python3.4/dist-packages/flask/app.py", line 1477, in full_dispatch_request
    rv = self.handle_user_exception(e)
  File "/usr/local/lib/python3.4/dist-packages/flask/app.py", line 1381, in handle_user_exception
    reraise(exc_type, exc_value, tb)
  File "/usr/local/lib/python3.4/dist-packages/flask/_compat.py", line 33, in reraise
    raise value
  File "/usr/local/lib/python3.4/dist-packages/flask/app.py", line 1475, in full_dispatch_request
    rv = self.dispatch_request()
  File "/usr/local/lib/python3.4/dist-packages/flask/app.py", line 1461, in dispatch_request
    return self.view_functions[rule.endpoint](**req.view_args)
  File "/service/timApp/tim.py", line 667, in getReadParagraphs
    doc_ver = timdb.documents.getNewestVersionHash(doc_id)
  File "<string>", line 2, in getNewestVersionHash
  File "/usr/local/lib/python3.4/dist-packages/contracts/main.py", line 266, in contracts_checker
    result = function_(*args, **kwargs)
  File "/service/timApp/timdb/documents.py", line 430, in getNewestVersionHash
    return cursor.fetchone()[0]
TypeError: 'NoneType' object is not subscriptable
{"time":2015-04-17 19:06:08,760, "file": /usr/local/lib/python3.4/dist-packages/flask/app.py, "line" :1423, "messageLevel":  ERROR, "message": Exception on /notes/3 [GET]}
Traceback (most recent call last):
  File "/usr/local/lib/python3.4/dist-packages/flask/app.py", line 1817, in wsgi_app
    response = self.full_dispatch_request()
  File "/usr/local/lib/python3.4/dist-packages/flask/app.py", line 1477, in full_dispatch_request
    rv = self.handle_user_exception(e)
  File "/usr/local/lib/python3.4/dist-packages/flask/app.py", line 1381, in handle_user_exception
    reraise(exc_type, exc_value, tb)
  File "/usr/local/lib/python3.4/dist-packages/flask/_compat.py", line 33, in reraise
    raise value
  File "/usr/local/lib/python3.4/dist-packages/flask/app.py", line 1475, in full_dispatch_request
    rv = self.dispatch_request()
  File "/usr/local/lib/python3.4/dist-packages/flask/app.py", line 1461, in dispatch_request
    return self.view_functions[rule.endpoint](**req.view_args)
  File "/service/timApp/tim.py", line 651, in getNotes
    doc_ver = timdb.documents.getNewestVersionHash(doc_id)
  File "<string>", line 2, in getNewestVersionHash
  File "/usr/local/lib/python3.4/dist-packages/contracts/main.py", line 266, in contracts_checker
    result = function_(*args, **kwargs)
  File "/service/timApp/timdb/documents.py", line 430, in getNewestVersionHash
    return cursor.fetchone()[0]
TypeError: 'NoneType' object is not subscriptable
{"time":2015-04-17 19:06:26,113, "file": /usr/local/lib/python3.4/dist-packages/flask/app.py, "line" :1423, "messageLevel":  ERROR, "message": Exception on /index/3 [GET]}
Traceback (most recent call last):
  File "/usr/local/lib/python3.4/dist-packages/flask/app.py", line 1817, in wsgi_app
    response = self.full_dispatch_request()
  File "/usr/local/lib/python3.4/dist-packages/flask/app.py", line 1477, in full_dispatch_request
    rv = self.handle_user_exception(e)
  File "/usr/local/lib/python3.4/dist-packages/flask/app.py", line 1381, in handle_user_exception
    reraise(exc_type, exc_value, tb)
  File "/usr/local/lib/python3.4/dist-packages/flask/_compat.py", line 33, in reraise
    raise value
  File "/usr/local/lib/python3.4/dist-packages/flask/app.py", line 1475, in full_dispatch_request
    rv = self.dispatch_request()
  File "/usr/local/lib/python3.4/dist-packages/flask/app.py", line 1461, in dispatch_request
    return self.view_functions[rule.endpoint](**req.view_args)
  File "/service/timApp/tim.py", line 568, in getIndex
    index = timdb.documents.getIndex(getNewest(docId))
  File "/service/timApp/routes/common.py", line 80, in getNewest
    version = timdb.documents.getNewestVersionHash(docId)
  File "<string>", line 2, in getNewestVersionHash
  File "/usr/local/lib/python3.4/dist-packages/contracts/main.py", line 266, in contracts_checker
    result = function_(*args, **kwargs)
  File "/service/timApp/timdb/documents.py", line 430, in getNewestVersionHash
    return cursor.fetchone()[0]
TypeError: 'NoneType' object is not subscriptable
{"time":2015-04-17 19:06:26,124, "file": /usr/local/lib/python3.4/dist-packages/flask/app.py, "line" :1423, "messageLevel":  ERROR, "message": Exception on /read/3 [GET]}
Traceback (most recent call last):
  File "/usr/local/lib/python3.4/dist-packages/flask/app.py", line 1817, in wsgi_app
    response = self.full_dispatch_request()
  File "/usr/local/lib/python3.4/dist-packages/flask/app.py", line 1477, in full_dispatch_request
    rv = self.handle_user_exception(e)
  File "/usr/local/lib/python3.4/dist-packages/flask/app.py", line 1381, in handle_user_exception
    reraise(exc_type, exc_value, tb)
  File "/usr/local/lib/python3.4/dist-packages/flask/_compat.py", line 33, in reraise
    raise value
  File "/usr/local/lib/python3.4/dist-packages/flask/app.py", line 1475, in full_dispatch_request
    rv = self.dispatch_request()
  File "/usr/local/lib/python3.4/dist-packages/flask/app.py", line 1461, in dispatch_request
    return self.view_functions[rule.endpoint](**req.view_args)
  File "/service/timApp/tim.py", line 667, in getReadParagraphs
    doc_ver = timdb.documents.getNewestVersionHash(doc_id)
  File "<string>", line 2, in getNewestVersionHash
  File "/usr/local/lib/python3.4/dist-packages/contracts/main.py", line 266, in contracts_checker
    result = function_(*args, **kwargs)
  File "/service/timApp/timdb/documents.py", line 430, in getNewestVersionHash
    return cursor.fetchone()[0]
TypeError: 'NoneType' object is not subscriptable
{"time":2015-04-17 19:06:26,130, "file": /usr/local/lib/python3.4/dist-packages/flask/app.py, "line" :1423, "messageLevel":  ERROR, "message": Exception on /notes/3 [GET]}
Traceback (most recent call last):
  File "/usr/local/lib/python3.4/dist-packages/flask/app.py", line 1817, in wsgi_app
    response = self.full_dispatch_request()
  File "/usr/local/lib/python3.4/dist-packages/flask/app.py", line 1477, in full_dispatch_request
    rv = self.handle_user_exception(e)
  File "/usr/local/lib/python3.4/dist-packages/flask/app.py", line 1381, in handle_user_exception
    reraise(exc_type, exc_value, tb)
  File "/usr/local/lib/python3.4/dist-packages/flask/_compat.py", line 33, in reraise
    raise value
  File "/usr/local/lib/python3.4/dist-packages/flask/app.py", line 1475, in full_dispatch_request
    rv = self.dispatch_request()
  File "/usr/local/lib/python3.4/dist-packages/flask/app.py", line 1461, in dispatch_request
    return self.view_functions[rule.endpoint](**req.view_args)
  File "/service/timApp/tim.py", line 651, in getNotes
    doc_ver = timdb.documents.getNewestVersionHash(doc_id)
  File "<string>", line 2, in getNewestVersionHash
  File "/usr/local/lib/python3.4/dist-packages/contracts/main.py", line 266, in contracts_checker
    result = function_(*args, **kwargs)
  File "/service/timApp/timdb/documents.py", line 430, in getNewestVersionHash
    return cursor.fetchone()[0]
TypeError: 'NoneType' object is not subscriptable
{"time":2015-04-17 19:08:34,210, "file": /usr/local/lib/python3.4/dist-packages/flask/app.py, "line" :1423, "messageLevel":  ERROR, "message": Exception on /notes/3 [GET]}
Traceback (most recent call last):
  File "/usr/local/lib/python3.4/dist-packages/flask/app.py", line 1817, in wsgi_app
    response = self.full_dispatch_request()
  File "/usr/local/lib/python3.4/dist-packages/flask/app.py", line 1477, in full_dispatch_request
    rv = self.handle_user_exception(e)
  File "/usr/local/lib/python3.4/dist-packages/flask/app.py", line 1381, in handle_user_exception
    reraise(exc_type, exc_value, tb)
  File "/usr/local/lib/python3.4/dist-packages/flask/_compat.py", line 33, in reraise
    raise value
  File "/usr/local/lib/python3.4/dist-packages/flask/app.py", line 1475, in full_dispatch_request
    rv = self.dispatch_request()
  File "/usr/local/lib/python3.4/dist-packages/flask/app.py", line 1461, in dispatch_request
    return self.view_functions[rule.endpoint](**req.view_args)
  File "/service/timApp/tim.py", line 651, in getNotes
    doc_ver = timdb.documents.getNewestVersionHash(doc_id)
  File "<string>", line 2, in getNewestVersionHash
  File "/usr/local/lib/python3.4/dist-packages/contracts/main.py", line 266, in contracts_checker
    result = function_(*args, **kwargs)
  File "/service/timApp/timdb/documents.py", line 430, in getNewestVersionHash
    return cursor.fetchone()[0]
TypeError: 'NoneType' object is not subscriptable
{"time":2015-04-17 19:10:09,523, "file": /usr/local/lib/python3.4/dist-packages/flask/app.py, "line" :1423, "messageLevel":  ERROR, "message": Exception on /index/3 [GET]}
Traceback (most recent call last):
  File "/usr/local/lib/python3.4/dist-packages/flask/app.py", line 1817, in wsgi_app
    response = self.full_dispatch_request()
  File "/usr/local/lib/python3.4/dist-packages/flask/app.py", line 1477, in full_dispatch_request
    rv = self.handle_user_exception(e)
  File "/usr/local/lib/python3.4/dist-packages/flask/app.py", line 1381, in handle_user_exception
    reraise(exc_type, exc_value, tb)
  File "/usr/local/lib/python3.4/dist-packages/flask/_compat.py", line 33, in reraise
    raise value
  File "/usr/local/lib/python3.4/dist-packages/flask/app.py", line 1475, in full_dispatch_request
    rv = self.dispatch_request()
  File "/usr/local/lib/python3.4/dist-packages/flask/app.py", line 1461, in dispatch_request
    return self.view_functions[rule.endpoint](**req.view_args)
  File "/service/timApp/tim.py", line 568, in getIndex
    index = timdb.documents.getIndex(getNewest(docId))
  File "/service/timApp/routes/common.py", line 80, in getNewest
    version = timdb.documents.getNewestVersionHash(docId)
  File "<string>", line 2, in getNewestVersionHash
  File "/usr/local/lib/python3.4/dist-packages/contracts/main.py", line 266, in contracts_checker
    result = function_(*args, **kwargs)
  File "/service/timApp/timdb/documents.py", line 430, in getNewestVersionHash
    return cursor.fetchone()[0]
TypeError: 'NoneType' object is not subscriptable
{"time":2015-04-17 19:10:09,525, "file": /usr/local/lib/python3.4/dist-packages/flask/app.py, "line" :1423, "messageLevel":  ERROR, "message": Exception on /read/3 [GET]}
Traceback (most recent call last):
  File "/usr/local/lib/python3.4/dist-packages/flask/app.py", line 1817, in wsgi_app
    response = self.full_dispatch_request()
  File "/usr/local/lib/python3.4/dist-packages/flask/app.py", line 1477, in full_dispatch_request
    rv = self.handle_user_exception(e)
  File "/usr/local/lib/python3.4/dist-packages/flask/app.py", line 1381, in handle_user_exception
    reraise(exc_type, exc_value, tb)
  File "/usr/local/lib/python3.4/dist-packages/flask/_compat.py", line 33, in reraise
    raise value
  File "/usr/local/lib/python3.4/dist-packages/flask/app.py", line 1475, in full_dispatch_request
    rv = self.dispatch_request()
  File "/usr/local/lib/python3.4/dist-packages/flask/app.py", line 1461, in dispatch_request
    return self.view_functions[rule.endpoint](**req.view_args)
  File "/service/timApp/tim.py", line 667, in getReadParagraphs
    doc_ver = timdb.documents.getNewestVersionHash(doc_id)
  File "<string>", line 2, in getNewestVersionHash
  File "/usr/local/lib/python3.4/dist-packages/contracts/main.py", line 266, in contracts_checker
    result = function_(*args, **kwargs)
  File "/service/timApp/timdb/documents.py", line 430, in getNewestVersionHash
    return cursor.fetchone()[0]
TypeError: 'NoneType' object is not subscriptable
{"time":2015-04-17 19:10:09,534, "file": /usr/local/lib/python3.4/dist-packages/flask/app.py, "line" :1423, "messageLevel":  ERROR, "message": Exception on /notes/3 [GET]}
Traceback (most recent call last):
  File "/usr/local/lib/python3.4/dist-packages/flask/app.py", line 1817, in wsgi_app
    response = self.full_dispatch_request()
  File "/usr/local/lib/python3.4/dist-packages/flask/app.py", line 1477, in full_dispatch_request
    rv = self.handle_user_exception(e)
  File "/usr/local/lib/python3.4/dist-packages/flask/app.py", line 1381, in handle_user_exception
    reraise(exc_type, exc_value, tb)
  File "/usr/local/lib/python3.4/dist-packages/flask/_compat.py", line 33, in reraise
    raise value
  File "/usr/local/lib/python3.4/dist-packages/flask/app.py", line 1475, in full_dispatch_request
    rv = self.dispatch_request()
  File "/usr/local/lib/python3.4/dist-packages/flask/app.py", line 1461, in dispatch_request
    return self.view_functions[rule.endpoint](**req.view_args)
  File "/service/timApp/tim.py", line 651, in getNotes
    doc_ver = timdb.documents.getNewestVersionHash(doc_id)
  File "<string>", line 2, in getNewestVersionHash
  File "/usr/local/lib/python3.4/dist-packages/contracts/main.py", line 266, in contracts_checker
    result = function_(*args, **kwargs)
  File "/service/timApp/timdb/documents.py", line 430, in getNewestVersionHash
    return cursor.fetchone()[0]
TypeError: 'NoneType' object is not subscriptable
{"time":2015-04-18 09:57:02,996, "file": /usr/local/lib/python3.4/dist-packages/flask/app.py, "line" :1423, "messageLevel":  ERROR, "message": Exception on /index/4 [GET]}
Traceback (most recent call last):
  File "/usr/local/lib/python3.4/dist-packages/flask/app.py", line 1817, in wsgi_app
    response = self.full_dispatch_request()
  File "/usr/local/lib/python3.4/dist-packages/flask/app.py", line 1477, in full_dispatch_request
    rv = self.handle_user_exception(e)
  File "/usr/local/lib/python3.4/dist-packages/flask/app.py", line 1381, in handle_user_exception
    reraise(exc_type, exc_value, tb)
  File "/usr/local/lib/python3.4/dist-packages/flask/_compat.py", line 33, in reraise
    raise value
  File "/usr/local/lib/python3.4/dist-packages/flask/app.py", line 1475, in full_dispatch_request
    rv = self.dispatch_request()
  File "/usr/local/lib/python3.4/dist-packages/flask/app.py", line 1461, in dispatch_request
    return self.view_functions[rule.endpoint](**req.view_args)
  File "/service/timApp/tim.py", line 568, in getIndex
    index = timdb.documents.getIndex(getNewest(docId))
  File "/service/timApp/routes/common.py", line 80, in getNewest
    version = timdb.documents.getNewestVersionHash(docId)
  File "<string>", line 2, in getNewestVersionHash
  File "/usr/local/lib/python3.4/dist-packages/contracts/main.py", line 266, in contracts_checker
    result = function_(*args, **kwargs)
  File "/service/timApp/timdb/documents.py", line 430, in getNewestVersionHash
    return cursor.fetchone()[0]
TypeError: 'NoneType' object is not subscriptable
{"time":2015-04-18 09:57:03,023, "file": /usr/local/lib/python3.4/dist-packages/flask/app.py, "line" :1423, "messageLevel":  ERROR, "message": Exception on /read/4 [GET]}
Traceback (most recent call last):
  File "/usr/local/lib/python3.4/dist-packages/flask/app.py", line 1817, in wsgi_app
    response = self.full_dispatch_request()
  File "/usr/local/lib/python3.4/dist-packages/flask/app.py", line 1477, in full_dispatch_request
    rv = self.handle_user_exception(e)
  File "/usr/local/lib/python3.4/dist-packages/flask/app.py", line 1381, in handle_user_exception
    reraise(exc_type, exc_value, tb)
  File "/usr/local/lib/python3.4/dist-packages/flask/_compat.py", line 33, in reraise
    raise value
  File "/usr/local/lib/python3.4/dist-packages/flask/app.py", line 1475, in full_dispatch_request
    rv = self.dispatch_request()
  File "/usr/local/lib/python3.4/dist-packages/flask/app.py", line 1461, in dispatch_request
    return self.view_functions[rule.endpoint](**req.view_args)
  File "/service/timApp/tim.py", line 667, in getReadParagraphs
    doc_ver = timdb.documents.getNewestVersionHash(doc_id)
  File "<string>", line 2, in getNewestVersionHash
  File "/usr/local/lib/python3.4/dist-packages/contracts/main.py", line 266, in contracts_checker
    result = function_(*args, **kwargs)
  File "/service/timApp/timdb/documents.py", line 430, in getNewestVersionHash
    return cursor.fetchone()[0]
TypeError: 'NoneType' object is not subscriptable
{"time":2015-04-18 09:57:03,024, "file": /usr/local/lib/python3.4/dist-packages/flask/app.py, "line" :1423, "messageLevel":  ERROR, "message": Exception on /notes/4 [GET]}
Traceback (most recent call last):
  File "/usr/local/lib/python3.4/dist-packages/flask/app.py", line 1817, in wsgi_app
    response = self.full_dispatch_request()
  File "/usr/local/lib/python3.4/dist-packages/flask/app.py", line 1477, in full_dispatch_request
    rv = self.handle_user_exception(e)
  File "/usr/local/lib/python3.4/dist-packages/flask/app.py", line 1381, in handle_user_exception
    reraise(exc_type, exc_value, tb)
  File "/usr/local/lib/python3.4/dist-packages/flask/_compat.py", line 33, in reraise
    raise value
  File "/usr/local/lib/python3.4/dist-packages/flask/app.py", line 1475, in full_dispatch_request
    rv = self.dispatch_request()
  File "/usr/local/lib/python3.4/dist-packages/flask/app.py", line 1461, in dispatch_request
    return self.view_functions[rule.endpoint](**req.view_args)
  File "/service/timApp/tim.py", line 651, in getNotes
    doc_ver = timdb.documents.getNewestVersionHash(doc_id)
  File "<string>", line 2, in getNewestVersionHash
  File "/usr/local/lib/python3.4/dist-packages/contracts/main.py", line 266, in contracts_checker
    result = function_(*args, **kwargs)
  File "/service/timApp/timdb/documents.py", line 430, in getNewestVersionHash
    return cursor.fetchone()[0]
TypeError: 'NoneType' object is not subscriptable
{"time":2015-04-18 09:57:25,572, "file": /usr/local/lib/python3.4/dist-packages/flask/app.py, "line" :1423, "messageLevel":  ERROR, "message": Exception on /notes/4 [GET]}
Traceback (most recent call last):
  File "/usr/local/lib/python3.4/dist-packages/flask/app.py", line 1817, in wsgi_app
    response = self.full_dispatch_request()
  File "/usr/local/lib/python3.4/dist-packages/flask/app.py", line 1477, in full_dispatch_request
    rv = self.handle_user_exception(e)
  File "/usr/local/lib/python3.4/dist-packages/flask/app.py", line 1381, in handle_user_exception
    reraise(exc_type, exc_value, tb)
  File "/usr/local/lib/python3.4/dist-packages/flask/_compat.py", line 33, in reraise
    raise value
  File "/usr/local/lib/python3.4/dist-packages/flask/app.py", line 1475, in full_dispatch_request
    rv = self.dispatch_request()
  File "/usr/local/lib/python3.4/dist-packages/flask/app.py", line 1461, in dispatch_request
    return self.view_functions[rule.endpoint](**req.view_args)
  File "/service/timApp/tim.py", line 651, in getNotes
    doc_ver = timdb.documents.getNewestVersionHash(doc_id)
  File "<string>", line 2, in getNewestVersionHash
  File "/usr/local/lib/python3.4/dist-packages/contracts/main.py", line 266, in contracts_checker
    result = function_(*args, **kwargs)
  File "/service/timApp/timdb/documents.py", line 430, in getNewestVersionHash
    return cursor.fetchone()[0]
TypeError: 'NoneType' object is not subscriptable
{"time":2015-04-18 09:57:25,580, "file": /usr/local/lib/python3.4/dist-packages/flask/app.py, "line" :1423, "messageLevel":  ERROR, "message": Exception on /read/4 [GET]}
Traceback (most recent call last):
  File "/usr/local/lib/python3.4/dist-packages/flask/app.py", line 1817, in wsgi_app
    response = self.full_dispatch_request()
  File "/usr/local/lib/python3.4/dist-packages/flask/app.py", line 1477, in full_dispatch_request
    rv = self.handle_user_exception(e)
  File "/usr/local/lib/python3.4/dist-packages/flask/app.py", line 1381, in handle_user_exception
    reraise(exc_type, exc_value, tb)
  File "/usr/local/lib/python3.4/dist-packages/flask/_compat.py", line 33, in reraise
    raise value
  File "/usr/local/lib/python3.4/dist-packages/flask/app.py", line 1475, in full_dispatch_request
    rv = self.dispatch_request()
  File "/usr/local/lib/python3.4/dist-packages/flask/app.py", line 1461, in dispatch_request
    return self.view_functions[rule.endpoint](**req.view_args)
  File "/service/timApp/tim.py", line 667, in getReadParagraphs
    doc_ver = timdb.documents.getNewestVersionHash(doc_id)
  File "<string>", line 2, in getNewestVersionHash
  File "/usr/local/lib/python3.4/dist-packages/contracts/main.py", line 266, in contracts_checker
    result = function_(*args, **kwargs)
  File "/service/timApp/timdb/documents.py", line 430, in getNewestVersionHash
    return cursor.fetchone()[0]
TypeError: 'NoneType' object is not subscriptable
{"time":2015-04-18 09:57:25,604, "file": /usr/local/lib/python3.4/dist-packages/flask/app.py, "line" :1423, "messageLevel":  ERROR, "message": Exception on /index/4 [GET]}
Traceback (most recent call last):
  File "/usr/local/lib/python3.4/dist-packages/flask/app.py", line 1817, in wsgi_app
    response = self.full_dispatch_request()
  File "/usr/local/lib/python3.4/dist-packages/flask/app.py", line 1477, in full_dispatch_request
    rv = self.handle_user_exception(e)
  File "/usr/local/lib/python3.4/dist-packages/flask/app.py", line 1381, in handle_user_exception
    reraise(exc_type, exc_value, tb)
  File "/usr/local/lib/python3.4/dist-packages/flask/_compat.py", line 33, in reraise
    raise value
  File "/usr/local/lib/python3.4/dist-packages/flask/app.py", line 1475, in full_dispatch_request
    rv = self.dispatch_request()
  File "/usr/local/lib/python3.4/dist-packages/flask/app.py", line 1461, in dispatch_request
    return self.view_functions[rule.endpoint](**req.view_args)
  File "/service/timApp/tim.py", line 568, in getIndex
    index = timdb.documents.getIndex(getNewest(docId))
  File "/service/timApp/routes/common.py", line 80, in getNewest
    version = timdb.documents.getNewestVersionHash(docId)
  File "<string>", line 2, in getNewestVersionHash
  File "/usr/local/lib/python3.4/dist-packages/contracts/main.py", line 266, in contracts_checker
    result = function_(*args, **kwargs)
  File "/service/timApp/timdb/documents.py", line 430, in getNewestVersionHash
    return cursor.fetchone()[0]
TypeError: 'NoneType' object is not subscriptable
{"time":2015-04-22 12:52:28,085, "file": /usr/local/lib/python3.4/dist-packages/flask/app.py, "line" :1423, "messageLevel":  ERROR, "message": Exception on /question [GET]}
Traceback (most recent call last):
  File "/usr/local/lib/python3.4/dist-packages/flask/app.py", line 1817, in wsgi_app
    response = self.full_dispatch_request()
  File "/usr/local/lib/python3.4/dist-packages/flask/app.py", line 1477, in full_dispatch_request
    rv = self.handle_user_exception(e)
  File "/usr/local/lib/python3.4/dist-packages/flask/app.py", line 1381, in handle_user_exception
    reraise(exc_type, exc_value, tb)
  File "/usr/local/lib/python3.4/dist-packages/flask/_compat.py", line 33, in reraise
    raise value
  File "/usr/local/lib/python3.4/dist-packages/flask/app.py", line 1475, in full_dispatch_request
    rv = self.dispatch_request()
  File "/usr/local/lib/python3.4/dist-packages/flask/app.py", line 1461, in dispatch_request
    return self.view_functions[rule.endpoint](**req.view_args)
  File "/service/timApp/tim.py", line 298, in show_question
    return render_template('question.html')
  File "/usr/local/lib/python3.4/dist-packages/flask/templating.py", line 128, in render_template
    context, ctx.app)
  File "/usr/local/lib/python3.4/dist-packages/flask/templating.py", line 110, in _render
    rv = template.render(context)
  File "/usr/local/lib/python3.4/dist-packages/jinja2/environment.py", line 969, in render
    return self.environment.handle_exception(exc_info, True)
  File "/usr/local/lib/python3.4/dist-packages/jinja2/environment.py", line 742, in handle_exception
    reraise(exc_type, exc_value, tb)
  File "/usr/local/lib/python3.4/dist-packages/jinja2/_compat.py", line 36, in reraise
    raise value.with_traceback(tb)
  File "/service/timApp/templates/question.html", line 16, in <module>
    {% include 'matriisi.html' %}
  File "/service/timApp/templates/matriisi.html", line 66, in <module>
    <textarea style="margin-left:5px" id="{{"question:"+row.id}}" form="question-form" rows="1" cols="20"></textarea>
  File "/usr/local/lib/python3.4/dist-packages/jinja2/environment.py", line 397, in getattr
    return getattr(obj, attribute)
jinja2.exceptions.UndefinedError: 'row' is undefined
{"time":2015-04-22 12:52:31,061, "file": /usr/local/lib/python3.4/dist-packages/flask/app.py, "line" :1423, "messageLevel":  ERROR, "message": Exception on /question [GET]}
Traceback (most recent call last):
  File "/usr/local/lib/python3.4/dist-packages/flask/app.py", line 1817, in wsgi_app
    response = self.full_dispatch_request()
  File "/usr/local/lib/python3.4/dist-packages/flask/app.py", line 1477, in full_dispatch_request
    rv = self.handle_user_exception(e)
  File "/usr/local/lib/python3.4/dist-packages/flask/app.py", line 1381, in handle_user_exception
    reraise(exc_type, exc_value, tb)
  File "/usr/local/lib/python3.4/dist-packages/flask/_compat.py", line 33, in reraise
    raise value
  File "/usr/local/lib/python3.4/dist-packages/flask/app.py", line 1475, in full_dispatch_request
    rv = self.dispatch_request()
  File "/usr/local/lib/python3.4/dist-packages/flask/app.py", line 1461, in dispatch_request
    return self.view_functions[rule.endpoint](**req.view_args)
  File "/service/timApp/tim.py", line 298, in show_question
    return render_template('question.html')
  File "/usr/local/lib/python3.4/dist-packages/flask/templating.py", line 128, in render_template
    context, ctx.app)
  File "/usr/local/lib/python3.4/dist-packages/flask/templating.py", line 110, in _render
    rv = template.render(context)
  File "/usr/local/lib/python3.4/dist-packages/jinja2/environment.py", line 969, in render
    return self.environment.handle_exception(exc_info, True)
  File "/usr/local/lib/python3.4/dist-packages/jinja2/environment.py", line 742, in handle_exception
    reraise(exc_type, exc_value, tb)
  File "/usr/local/lib/python3.4/dist-packages/jinja2/_compat.py", line 36, in reraise
    raise value.with_traceback(tb)
  File "/service/timApp/templates/question.html", line 16, in <module>
    {% include 'matriisi.html' %}
  File "/service/timApp/templates/matriisi.html", line 66, in <module>
    <textarea style="margin-left:5px" id="{{"question:"+row.id}}" form="question-form" rows="1" cols="20"></textarea>
  File "/usr/local/lib/python3.4/dist-packages/jinja2/environment.py", line 397, in getattr
    return getattr(obj, attribute)
jinja2.exceptions.UndefinedError: 'row' is undefined
{"time":2015-04-23 07:22:10,550, "file": /usr/local/lib/python3.4/dist-packages/flask/app.py, "line" :1423, "messageLevel":  ERROR, "message": Exception on /question [GET]}
Traceback (most recent call last):
  File "/usr/local/lib/python3.4/dist-packages/flask/app.py", line 1817, in wsgi_app
    response = self.full_dispatch_request()
  File "/usr/local/lib/python3.4/dist-packages/flask/app.py", line 1477, in full_dispatch_request
    rv = self.handle_user_exception(e)
  File "/usr/local/lib/python3.4/dist-packages/flask/app.py", line 1381, in handle_user_exception
    reraise(exc_type, exc_value, tb)
  File "/usr/local/lib/python3.4/dist-packages/flask/_compat.py", line 33, in reraise
    raise value
  File "/usr/local/lib/python3.4/dist-packages/flask/app.py", line 1475, in full_dispatch_request
    rv = self.dispatch_request()
  File "/usr/local/lib/python3.4/dist-packages/flask/app.py", line 1461, in dispatch_request
    return self.view_functions[rule.endpoint](**req.view_args)
  File "/service/timApp/tim.py", line 298, in show_question
    {"status": "results", "data": list_of_new_messages, "lastid": last_message_id,
  File "/usr/local/lib/python3.4/dist-packages/flask/templating.py", line 128, in render_template
    context, ctx.app)
  File "/usr/local/lib/python3.4/dist-packages/flask/templating.py", line 110, in _render
    rv = template.render(context)
  File "/usr/local/lib/python3.4/dist-packages/jinja2/environment.py", line 969, in render
    return self.environment.handle_exception(exc_info, True)
  File "/usr/local/lib/python3.4/dist-packages/jinja2/environment.py", line 742, in handle_exception
    reraise(exc_type, exc_value, tb)
  File "/usr/local/lib/python3.4/dist-packages/jinja2/_compat.py", line 36, in reraise
    raise value.with_traceback(tb)
  File "/service/timApp/templates/question.html", line 16, in <module>
    {% include 'matriisi.html' %}
  File "/service/timApp/templates/matriisi.html", line 6, in <module>
    <option ng-repeat="item in answerFieldTypes" value="{{item.label}}">{{item.label}}
  File "/usr/local/lib/python3.4/dist-packages/jinja2/environment.py", line 397, in getattr
    return getattr(obj, attribute)
jinja2.exceptions.UndefinedError: 'item' is undefined
{"time":2015-04-23 07:22:22,655, "file": /usr/local/lib/python3.4/dist-packages/flask/app.py, "line" :1423, "messageLevel":  ERROR, "message": Exception on /question [GET]}
Traceback (most recent call last):
  File "/usr/local/lib/python3.4/dist-packages/flask/app.py", line 1817, in wsgi_app
    response = self.full_dispatch_request()
  File "/usr/local/lib/python3.4/dist-packages/flask/app.py", line 1477, in full_dispatch_request
    rv = self.handle_user_exception(e)
  File "/usr/local/lib/python3.4/dist-packages/flask/app.py", line 1381, in handle_user_exception
    reraise(exc_type, exc_value, tb)
  File "/usr/local/lib/python3.4/dist-packages/flask/_compat.py", line 33, in reraise
    raise value
  File "/usr/local/lib/python3.4/dist-packages/flask/app.py", line 1475, in full_dispatch_request
    rv = self.dispatch_request()
  File "/usr/local/lib/python3.4/dist-packages/flask/app.py", line 1461, in dispatch_request
    return self.view_functions[rule.endpoint](**req.view_args)
  File "/service/timApp/tim.py", line 298, in show_question
    {"status": "results", "data": list_of_new_messages, "lastid": last_message_id,
  File "/usr/local/lib/python3.4/dist-packages/flask/templating.py", line 128, in render_template
    context, ctx.app)
  File "/usr/local/lib/python3.4/dist-packages/flask/templating.py", line 110, in _render
    rv = template.render(context)
  File "/usr/local/lib/python3.4/dist-packages/jinja2/environment.py", line 969, in render
    return self.environment.handle_exception(exc_info, True)
  File "/usr/local/lib/python3.4/dist-packages/jinja2/environment.py", line 742, in handle_exception
    reraise(exc_type, exc_value, tb)
  File "/usr/local/lib/python3.4/dist-packages/jinja2/_compat.py", line 36, in reraise
    raise value.with_traceback(tb)
  File "/service/timApp/templates/question.html", line 16, in <module>
    {% include 'matriisi.html' %}
  File "/service/timApp/templates/matriisi.html", line 6, in <module>
    <option ng-repeat="item in answerFieldTypes" value="{{item.label}}">{{item.label}}
  File "/usr/local/lib/python3.4/dist-packages/jinja2/environment.py", line 397, in getattr
    return getattr(obj, attribute)
jinja2.exceptions.UndefinedError: 'item' is undefined
{"time":2015-04-23 07:43:04,496, "file": /usr/local/lib/python3.4/dist-packages/flask/app.py, "line" :1423, "messageLevel":  ERROR, "message": Exception on /question [GET]}
Traceback (most recent call last):
  File "/usr/local/lib/python3.4/dist-packages/flask/app.py", line 1817, in wsgi_app
    response = self.full_dispatch_request()
  File "/usr/local/lib/python3.4/dist-packages/flask/app.py", line 1477, in full_dispatch_request
    rv = self.handle_user_exception(e)
  File "/usr/local/lib/python3.4/dist-packages/flask/app.py", line 1381, in handle_user_exception
    reraise(exc_type, exc_value, tb)
  File "/usr/local/lib/python3.4/dist-packages/flask/_compat.py", line 33, in reraise
    raise value
  File "/usr/local/lib/python3.4/dist-packages/flask/app.py", line 1475, in full_dispatch_request
    rv = self.dispatch_request()
  File "/usr/local/lib/python3.4/dist-packages/flask/app.py", line 1461, in dispatch_request
    return self.view_functions[rule.endpoint](**req.view_args)
  File "/service/timApp/tim.py", line 298, in show_question
    {"status": "results", "data": list_of_new_messages, "lastid": last_message_id,
  File "/usr/local/lib/python3.4/dist-packages/flask/templating.py", line 127, in render_template
    return _render(ctx.app.jinja_env.get_or_select_template(template_name_or_list),
  File "/usr/local/lib/python3.4/dist-packages/jinja2/environment.py", line 830, in get_or_select_template
    return self.get_template(template_name_or_list, parent, globals)
  File "/usr/local/lib/python3.4/dist-packages/jinja2/environment.py", line 791, in get_template
    return self._load_template(name, self.make_globals(globals))
  File "/usr/local/lib/python3.4/dist-packages/jinja2/environment.py", line 765, in _load_template
    template = self.loader.load(self, name, globals)
  File "/usr/local/lib/python3.4/dist-packages/jinja2/loaders.py", line 113, in load
    source, filename, uptodate = self.get_source(environment, name)
  File "/usr/local/lib/python3.4/dist-packages/flask/templating.py", line 64, in get_source
    raise TemplateNotFound(template)
jinja2.exceptions.TemplateNotFound: question.html
{"time":2015-04-23 07:43:46,103, "file": /usr/local/lib/python3.4/dist-packages/flask/app.py, "line" :1423, "messageLevel":  ERROR, "message": Exception on /question [GET]}
Traceback (most recent call last):
  File "/usr/local/lib/python3.4/dist-packages/flask/app.py", line 1817, in wsgi_app
    response = self.full_dispatch_request()
  File "/usr/local/lib/python3.4/dist-packages/flask/app.py", line 1477, in full_dispatch_request
    rv = self.handle_user_exception(e)
  File "/usr/local/lib/python3.4/dist-packages/flask/app.py", line 1381, in handle_user_exception
    reraise(exc_type, exc_value, tb)
  File "/usr/local/lib/python3.4/dist-packages/flask/_compat.py", line 33, in reraise
    raise value
  File "/usr/local/lib/python3.4/dist-packages/flask/app.py", line 1475, in full_dispatch_request
    rv = self.dispatch_request()
  File "/usr/local/lib/python3.4/dist-packages/flask/app.py", line 1461, in dispatch_request
    return self.view_functions[rule.endpoint](**req.view_args)
  File "/service/timApp/tim.py", line 298, in show_question
    {"status": "results", "data": list_of_new_messages, "lastid": last_message_id,
  File "/usr/local/lib/python3.4/dist-packages/flask/templating.py", line 127, in render_template
    return _render(ctx.app.jinja_env.get_or_select_template(template_name_or_list),
  File "/usr/local/lib/python3.4/dist-packages/jinja2/environment.py", line 830, in get_or_select_template
    return self.get_template(template_name_or_list, parent, globals)
  File "/usr/local/lib/python3.4/dist-packages/jinja2/environment.py", line 791, in get_template
    return self._load_template(name, self.make_globals(globals))
  File "/usr/local/lib/python3.4/dist-packages/jinja2/environment.py", line 765, in _load_template
    template = self.loader.load(self, name, globals)
  File "/usr/local/lib/python3.4/dist-packages/jinja2/loaders.py", line 113, in load
    source, filename, uptodate = self.get_source(environment, name)
  File "/usr/local/lib/python3.4/dist-packages/flask/templating.py", line 64, in get_source
    raise TemplateNotFound(template)
jinja2.exceptions.TemplateNotFound: question.html
{"time":2015-04-23 07:46:15,890, "file": /usr/local/lib/python3.4/dist-packages/flask/app.py, "line" :1423, "messageLevel":  ERROR, "message": Exception on /question [GET]}
Traceback (most recent call last):
  File "/usr/local/lib/python3.4/dist-packages/flask/app.py", line 1817, in wsgi_app
    response = self.full_dispatch_request()
  File "/usr/local/lib/python3.4/dist-packages/flask/app.py", line 1477, in full_dispatch_request
    rv = self.handle_user_exception(e)
  File "/usr/local/lib/python3.4/dist-packages/flask/app.py", line 1381, in handle_user_exception
    reraise(exc_type, exc_value, tb)
  File "/usr/local/lib/python3.4/dist-packages/flask/_compat.py", line 33, in reraise
    raise value
  File "/usr/local/lib/python3.4/dist-packages/flask/app.py", line 1475, in full_dispatch_request
    rv = self.dispatch_request()
  File "/usr/local/lib/python3.4/dist-packages/flask/app.py", line 1461, in dispatch_request
    return self.view_functions[rule.endpoint](**req.view_args)
  File "/service/timApp/tim.py", line 298, in show_question
    {"status": "results", "data": list_of_new_messages, "lastid": last_message_id,
  File "/usr/local/lib/python3.4/dist-packages/flask/templating.py", line 127, in render_template
    return _render(ctx.app.jinja_env.get_or_select_template(template_name_or_list),
  File "/usr/local/lib/python3.4/dist-packages/jinja2/environment.py", line 830, in get_or_select_template
    return self.get_template(template_name_or_list, parent, globals)
  File "/usr/local/lib/python3.4/dist-packages/jinja2/environment.py", line 791, in get_template
    return self._load_template(name, self.make_globals(globals))
  File "/usr/local/lib/python3.4/dist-packages/jinja2/environment.py", line 765, in _load_template
    template = self.loader.load(self, name, globals)
  File "/usr/local/lib/python3.4/dist-packages/jinja2/loaders.py", line 113, in load
    source, filename, uptodate = self.get_source(environment, name)
  File "/usr/local/lib/python3.4/dist-packages/flask/templating.py", line 64, in get_source
    raise TemplateNotFound(template)
jinja2.exceptions.TemplateNotFound: question.html
{"time":2015-04-23 07:46:24,199, "file": /usr/local/lib/python3.4/dist-packages/flask/app.py, "line" :1423, "messageLevel":  ERROR, "message": Exception on /question [GET]}
Traceback (most recent call last):
  File "/usr/local/lib/python3.4/dist-packages/flask/app.py", line 1817, in wsgi_app
    response = self.full_dispatch_request()
  File "/usr/local/lib/python3.4/dist-packages/flask/app.py", line 1477, in full_dispatch_request
    rv = self.handle_user_exception(e)
  File "/usr/local/lib/python3.4/dist-packages/flask/app.py", line 1381, in handle_user_exception
    reraise(exc_type, exc_value, tb)
  File "/usr/local/lib/python3.4/dist-packages/flask/_compat.py", line 33, in reraise
    raise value
  File "/usr/local/lib/python3.4/dist-packages/flask/app.py", line 1475, in full_dispatch_request
    rv = self.dispatch_request()
  File "/usr/local/lib/python3.4/dist-packages/flask/app.py", line 1461, in dispatch_request
    return self.view_functions[rule.endpoint](**req.view_args)
  File "/service/timApp/tim.py", line 298, in show_question
    {"status": "results", "data": list_of_new_messages, "lastid": last_message_id,
  File "/usr/local/lib/python3.4/dist-packages/flask/templating.py", line 127, in render_template
    return _render(ctx.app.jinja_env.get_or_select_template(template_name_or_list),
  File "/usr/local/lib/python3.4/dist-packages/jinja2/environment.py", line 830, in get_or_select_template
    return self.get_template(template_name_or_list, parent, globals)
  File "/usr/local/lib/python3.4/dist-packages/jinja2/environment.py", line 791, in get_template
    return self._load_template(name, self.make_globals(globals))
  File "/usr/local/lib/python3.4/dist-packages/jinja2/environment.py", line 765, in _load_template
    template = self.loader.load(self, name, globals)
  File "/usr/local/lib/python3.4/dist-packages/jinja2/loaders.py", line 113, in load
    source, filename, uptodate = self.get_source(environment, name)
  File "/usr/local/lib/python3.4/dist-packages/flask/templating.py", line 64, in get_source
    raise TemplateNotFound(template)
jinja2.exceptions.TemplateNotFound: question.html
{"time":2015-04-23 07:46:37,137, "file": /usr/local/lib/python3.4/dist-packages/flask/app.py, "line" :1423, "messageLevel":  ERROR, "message": Exception on /question [GET]}
Traceback (most recent call last):
  File "/usr/local/lib/python3.4/dist-packages/flask/app.py", line 1817, in wsgi_app
    response = self.full_dispatch_request()
  File "/usr/local/lib/python3.4/dist-packages/flask/app.py", line 1477, in full_dispatch_request
    rv = self.handle_user_exception(e)
  File "/usr/local/lib/python3.4/dist-packages/flask/app.py", line 1381, in handle_user_exception
    reraise(exc_type, exc_value, tb)
  File "/usr/local/lib/python3.4/dist-packages/flask/_compat.py", line 33, in reraise
    raise value
  File "/usr/local/lib/python3.4/dist-packages/flask/app.py", line 1475, in full_dispatch_request
    rv = self.dispatch_request()
  File "/usr/local/lib/python3.4/dist-packages/flask/app.py", line 1461, in dispatch_request
    return self.view_functions[rule.endpoint](**req.view_args)
  File "/service/timApp/tim.py", line 298, in show_question
    {"status": "results", "data": list_of_new_messages, "lastid": last_message_id,
  File "/usr/local/lib/python3.4/dist-packages/flask/templating.py", line 127, in render_template
    return _render(ctx.app.jinja_env.get_or_select_template(template_name_or_list),
  File "/usr/local/lib/python3.4/dist-packages/jinja2/environment.py", line 830, in get_or_select_template
    return self.get_template(template_name_or_list, parent, globals)
  File "/usr/local/lib/python3.4/dist-packages/jinja2/environment.py", line 791, in get_template
    return self._load_template(name, self.make_globals(globals))
  File "/usr/local/lib/python3.4/dist-packages/jinja2/environment.py", line 765, in _load_template
    template = self.loader.load(self, name, globals)
  File "/usr/local/lib/python3.4/dist-packages/jinja2/loaders.py", line 113, in load
    source, filename, uptodate = self.get_source(environment, name)
  File "/usr/local/lib/python3.4/dist-packages/flask/templating.py", line 64, in get_source
    raise TemplateNotFound(template)
jinja2.exceptions.TemplateNotFound: question.html
{"time":2015-04-23 07:46:59,238, "file": /usr/local/lib/python3.4/dist-packages/flask/app.py, "line" :1423, "messageLevel":  ERROR, "message": Exception on /question [GET]}
Traceback (most recent call last):
  File "/usr/local/lib/python3.4/dist-packages/flask/app.py", line 1817, in wsgi_app
    response = self.full_dispatch_request()
  File "/usr/local/lib/python3.4/dist-packages/flask/app.py", line 1477, in full_dispatch_request
    rv = self.handle_user_exception(e)
  File "/usr/local/lib/python3.4/dist-packages/flask/app.py", line 1381, in handle_user_exception
    reraise(exc_type, exc_value, tb)
  File "/usr/local/lib/python3.4/dist-packages/flask/_compat.py", line 33, in reraise
    raise value
  File "/usr/local/lib/python3.4/dist-packages/flask/app.py", line 1475, in full_dispatch_request
    rv = self.dispatch_request()
  File "/usr/local/lib/python3.4/dist-packages/flask/app.py", line 1461, in dispatch_request
    return self.view_functions[rule.endpoint](**req.view_args)
  File "/service/timApp/tim.py", line 298, in show_question
    {"status": "results", "data": list_of_new_messages, "lastid": last_message_id,
  File "/usr/local/lib/python3.4/dist-packages/flask/templating.py", line 127, in render_template
    return _render(ctx.app.jinja_env.get_or_select_template(template_name_or_list),
  File "/usr/local/lib/python3.4/dist-packages/jinja2/environment.py", line 830, in get_or_select_template
    return self.get_template(template_name_or_list, parent, globals)
  File "/usr/local/lib/python3.4/dist-packages/jinja2/environment.py", line 791, in get_template
    return self._load_template(name, self.make_globals(globals))
  File "/usr/local/lib/python3.4/dist-packages/jinja2/environment.py", line 765, in _load_template
    template = self.loader.load(self, name, globals)
  File "/usr/local/lib/python3.4/dist-packages/jinja2/loaders.py", line 113, in load
    source, filename, uptodate = self.get_source(environment, name)
  File "/usr/local/lib/python3.4/dist-packages/flask/templating.py", line 64, in get_source
    raise TemplateNotFound(template)
jinja2.exceptions.TemplateNotFound: question.html
{"time":2015-04-23 07:48:11,993, "file": /usr/local/lib/python3.4/dist-packages/flask/app.py, "line" :1423, "messageLevel":  ERROR, "message": Exception on /question [GET]}
Traceback (most recent call last):
  File "/usr/local/lib/python3.4/dist-packages/flask/app.py", line 1817, in wsgi_app
    response = self.full_dispatch_request()
  File "/usr/local/lib/python3.4/dist-packages/flask/app.py", line 1477, in full_dispatch_request
    rv = self.handle_user_exception(e)
  File "/usr/local/lib/python3.4/dist-packages/flask/app.py", line 1381, in handle_user_exception
    reraise(exc_type, exc_value, tb)
  File "/usr/local/lib/python3.4/dist-packages/flask/_compat.py", line 33, in reraise
    raise value
  File "/usr/local/lib/python3.4/dist-packages/flask/app.py", line 1475, in full_dispatch_request
    rv = self.dispatch_request()
  File "/usr/local/lib/python3.4/dist-packages/flask/app.py", line 1461, in dispatch_request
    return self.view_functions[rule.endpoint](**req.view_args)
  File "/service/timApp/tim.py", line 298, in show_question
    {"status": "results", "data": list_of_new_messages, "lastid": last_message_id,
  File "/usr/local/lib/python3.4/dist-packages/flask/templating.py", line 127, in render_template
    return _render(ctx.app.jinja_env.get_or_select_template(template_name_or_list),
  File "/usr/local/lib/python3.4/dist-packages/jinja2/environment.py", line 830, in get_or_select_template
    return self.get_template(template_name_or_list, parent, globals)
  File "/usr/local/lib/python3.4/dist-packages/jinja2/environment.py", line 791, in get_template
    return self._load_template(name, self.make_globals(globals))
  File "/usr/local/lib/python3.4/dist-packages/jinja2/environment.py", line 765, in _load_template
    template = self.loader.load(self, name, globals)
  File "/usr/local/lib/python3.4/dist-packages/jinja2/loaders.py", line 113, in load
    source, filename, uptodate = self.get_source(environment, name)
  File "/usr/local/lib/python3.4/dist-packages/flask/templating.py", line 64, in get_source
    raise TemplateNotFound(template)
jinja2.exceptions.TemplateNotFound: question.html
{"time":2015-04-23 07:48:25,071, "file": /usr/local/lib/python3.4/dist-packages/flask/app.py, "line" :1423, "messageLevel":  ERROR, "message": Exception on /question [GET]}
Traceback (most recent call last):
  File "/usr/local/lib/python3.4/dist-packages/flask/app.py", line 1817, in wsgi_app
    response = self.full_dispatch_request()
  File "/usr/local/lib/python3.4/dist-packages/flask/app.py", line 1477, in full_dispatch_request
    rv = self.handle_user_exception(e)
  File "/usr/local/lib/python3.4/dist-packages/flask/app.py", line 1381, in handle_user_exception
    reraise(exc_type, exc_value, tb)
  File "/usr/local/lib/python3.4/dist-packages/flask/_compat.py", line 33, in reraise
    raise value
  File "/usr/local/lib/python3.4/dist-packages/flask/app.py", line 1475, in full_dispatch_request
    rv = self.dispatch_request()
  File "/usr/local/lib/python3.4/dist-packages/flask/app.py", line 1461, in dispatch_request
    return self.view_functions[rule.endpoint](**req.view_args)
  File "/service/timApp/tim.py", line 298, in show_question
    {"status": "results", "data": list_of_new_messages, "lastid": last_message_id,
  File "/usr/local/lib/python3.4/dist-packages/flask/templating.py", line 127, in render_template
    return _render(ctx.app.jinja_env.get_or_select_template(template_name_or_list),
  File "/usr/local/lib/python3.4/dist-packages/jinja2/environment.py", line 830, in get_or_select_template
    return self.get_template(template_name_or_list, parent, globals)
  File "/usr/local/lib/python3.4/dist-packages/jinja2/environment.py", line 791, in get_template
    return self._load_template(name, self.make_globals(globals))
  File "/usr/local/lib/python3.4/dist-packages/jinja2/environment.py", line 765, in _load_template
    template = self.loader.load(self, name, globals)
  File "/usr/local/lib/python3.4/dist-packages/jinja2/loaders.py", line 113, in load
    source, filename, uptodate = self.get_source(environment, name)
  File "/usr/local/lib/python3.4/dist-packages/flask/templating.py", line 64, in get_source
    raise TemplateNotFound(template)
jinja2.exceptions.TemplateNotFound: question.html
{"time":2015-04-23 07:48:37,897, "file": /usr/local/lib/python3.4/dist-packages/flask/app.py, "line" :1423, "messageLevel":  ERROR, "message": Exception on /question [GET]}
Traceback (most recent call last):
  File "/usr/local/lib/python3.4/dist-packages/flask/app.py", line 1817, in wsgi_app
    response = self.full_dispatch_request()
  File "/usr/local/lib/python3.4/dist-packages/flask/app.py", line 1477, in full_dispatch_request
    rv = self.handle_user_exception(e)
  File "/usr/local/lib/python3.4/dist-packages/flask/app.py", line 1381, in handle_user_exception
    reraise(exc_type, exc_value, tb)
  File "/usr/local/lib/python3.4/dist-packages/flask/_compat.py", line 33, in reraise
    raise value
  File "/usr/local/lib/python3.4/dist-packages/flask/app.py", line 1475, in full_dispatch_request
    rv = self.dispatch_request()
  File "/usr/local/lib/python3.4/dist-packages/flask/app.py", line 1461, in dispatch_request
    return self.view_functions[rule.endpoint](**req.view_args)
  File "/service/timApp/tim.py", line 298, in show_question
    {"status": "results", "data": list_of_new_messages, "lastid": last_message_id,
  File "/usr/local/lib/python3.4/dist-packages/flask/templating.py", line 127, in render_template
    return _render(ctx.app.jinja_env.get_or_select_template(template_name_or_list),
  File "/usr/local/lib/python3.4/dist-packages/jinja2/environment.py", line 830, in get_or_select_template
    return self.get_template(template_name_or_list, parent, globals)
  File "/usr/local/lib/python3.4/dist-packages/jinja2/environment.py", line 791, in get_template
    return self._load_template(name, self.make_globals(globals))
  File "/usr/local/lib/python3.4/dist-packages/jinja2/environment.py", line 765, in _load_template
    template = self.loader.load(self, name, globals)
  File "/usr/local/lib/python3.4/dist-packages/jinja2/loaders.py", line 113, in load
    source, filename, uptodate = self.get_source(environment, name)
  File "/usr/local/lib/python3.4/dist-packages/flask/templating.py", line 64, in get_source
    raise TemplateNotFound(template)
jinja2.exceptions.TemplateNotFound: question.html
{"time":2015-04-23 07:48:51,543, "file": /usr/local/lib/python3.4/dist-packages/flask/app.py, "line" :1423, "messageLevel":  ERROR, "message": Exception on /question [GET]}
Traceback (most recent call last):
  File "/usr/local/lib/python3.4/dist-packages/flask/app.py", line 1817, in wsgi_app
    response = self.full_dispatch_request()
  File "/usr/local/lib/python3.4/dist-packages/flask/app.py", line 1477, in full_dispatch_request
    rv = self.handle_user_exception(e)
  File "/usr/local/lib/python3.4/dist-packages/flask/app.py", line 1381, in handle_user_exception
    reraise(exc_type, exc_value, tb)
  File "/usr/local/lib/python3.4/dist-packages/flask/_compat.py", line 33, in reraise
    raise value
  File "/usr/local/lib/python3.4/dist-packages/flask/app.py", line 1475, in full_dispatch_request
    rv = self.dispatch_request()
  File "/usr/local/lib/python3.4/dist-packages/flask/app.py", line 1461, in dispatch_request
    return self.view_functions[rule.endpoint](**req.view_args)
  File "/service/timApp/tim.py", line 298, in show_question
    {"status": "results", "data": list_of_new_messages, "lastid": last_message_id,
  File "/usr/local/lib/python3.4/dist-packages/flask/templating.py", line 127, in render_template
    return _render(ctx.app.jinja_env.get_or_select_template(template_name_or_list),
  File "/usr/local/lib/python3.4/dist-packages/jinja2/environment.py", line 830, in get_or_select_template
    return self.get_template(template_name_or_list, parent, globals)
  File "/usr/local/lib/python3.4/dist-packages/jinja2/environment.py", line 791, in get_template
    return self._load_template(name, self.make_globals(globals))
  File "/usr/local/lib/python3.4/dist-packages/jinja2/environment.py", line 765, in _load_template
    template = self.loader.load(self, name, globals)
  File "/usr/local/lib/python3.4/dist-packages/jinja2/loaders.py", line 113, in load
    source, filename, uptodate = self.get_source(environment, name)
  File "/usr/local/lib/python3.4/dist-packages/flask/templating.py", line 64, in get_source
    raise TemplateNotFound(template)
jinja2.exceptions.TemplateNotFound: question.html
{"time":2015-04-23 07:49:22,435, "file": /usr/local/lib/python3.4/dist-packages/flask/app.py, "line" :1423, "messageLevel":  ERROR, "message": Exception on /question [GET]}
Traceback (most recent call last):
  File "/usr/local/lib/python3.4/dist-packages/flask/app.py", line 1817, in wsgi_app
    response = self.full_dispatch_request()
  File "/usr/local/lib/python3.4/dist-packages/flask/app.py", line 1477, in full_dispatch_request
    rv = self.handle_user_exception(e)
  File "/usr/local/lib/python3.4/dist-packages/flask/app.py", line 1381, in handle_user_exception
    reraise(exc_type, exc_value, tb)
  File "/usr/local/lib/python3.4/dist-packages/flask/_compat.py", line 33, in reraise
    raise value
  File "/usr/local/lib/python3.4/dist-packages/flask/app.py", line 1475, in full_dispatch_request
    rv = self.dispatch_request()
  File "/usr/local/lib/python3.4/dist-packages/flask/app.py", line 1461, in dispatch_request
    return self.view_functions[rule.endpoint](**req.view_args)
  File "/service/timApp/tim.py", line 298, in show_question
    {"status": "results", "data": list_of_new_messages, "lastid": last_message_id,
  File "/usr/local/lib/python3.4/dist-packages/flask/templating.py", line 127, in render_template
    return _render(ctx.app.jinja_env.get_or_select_template(template_name_or_list),
  File "/usr/local/lib/python3.4/dist-packages/jinja2/environment.py", line 830, in get_or_select_template
    return self.get_template(template_name_or_list, parent, globals)
  File "/usr/local/lib/python3.4/dist-packages/jinja2/environment.py", line 791, in get_template
    return self._load_template(name, self.make_globals(globals))
  File "/usr/local/lib/python3.4/dist-packages/jinja2/environment.py", line 765, in _load_template
    template = self.loader.load(self, name, globals)
  File "/usr/local/lib/python3.4/dist-packages/jinja2/loaders.py", line 113, in load
    source, filename, uptodate = self.get_source(environment, name)
  File "/usr/local/lib/python3.4/dist-packages/flask/templating.py", line 64, in get_source
    raise TemplateNotFound(template)
jinja2.exceptions.TemplateNotFound: question.html
{"time":2015-04-23 07:49:38,245, "file": /usr/local/lib/python3.4/dist-packages/flask/app.py, "line" :1423, "messageLevel":  ERROR, "message": Exception on /question [GET]}
Traceback (most recent call last):
  File "/usr/local/lib/python3.4/dist-packages/flask/app.py", line 1817, in wsgi_app
    response = self.full_dispatch_request()
  File "/usr/local/lib/python3.4/dist-packages/flask/app.py", line 1477, in full_dispatch_request
    rv = self.handle_user_exception(e)
  File "/usr/local/lib/python3.4/dist-packages/flask/app.py", line 1381, in handle_user_exception
    reraise(exc_type, exc_value, tb)
  File "/usr/local/lib/python3.4/dist-packages/flask/_compat.py", line 33, in reraise
    raise value
  File "/usr/local/lib/python3.4/dist-packages/flask/app.py", line 1475, in full_dispatch_request
    rv = self.dispatch_request()
  File "/usr/local/lib/python3.4/dist-packages/flask/app.py", line 1461, in dispatch_request
    return self.view_functions[rule.endpoint](**req.view_args)
  File "/service/timApp/tim.py", line 298, in show_question
    {"status": "results", "data": list_of_new_messages, "lastid": last_message_id,
  File "/usr/local/lib/python3.4/dist-packages/flask/templating.py", line 127, in render_template
    return _render(ctx.app.jinja_env.get_or_select_template(template_name_or_list),
  File "/usr/local/lib/python3.4/dist-packages/jinja2/environment.py", line 830, in get_or_select_template
    return self.get_template(template_name_or_list, parent, globals)
  File "/usr/local/lib/python3.4/dist-packages/jinja2/environment.py", line 791, in get_template
    return self._load_template(name, self.make_globals(globals))
  File "/usr/local/lib/python3.4/dist-packages/jinja2/environment.py", line 765, in _load_template
    template = self.loader.load(self, name, globals)
  File "/usr/local/lib/python3.4/dist-packages/jinja2/loaders.py", line 113, in load
    source, filename, uptodate = self.get_source(environment, name)
  File "/usr/local/lib/python3.4/dist-packages/flask/templating.py", line 64, in get_source
    raise TemplateNotFound(template)
jinja2.exceptions.TemplateNotFound: question.html
{"time":2015-04-23 07:49:57,406, "file": /usr/local/lib/python3.4/dist-packages/flask/app.py, "line" :1423, "messageLevel":  ERROR, "message": Exception on /question [GET]}
Traceback (most recent call last):
  File "/usr/local/lib/python3.4/dist-packages/flask/app.py", line 1817, in wsgi_app
    response = self.full_dispatch_request()
  File "/usr/local/lib/python3.4/dist-packages/flask/app.py", line 1477, in full_dispatch_request
    rv = self.handle_user_exception(e)
  File "/usr/local/lib/python3.4/dist-packages/flask/app.py", line 1381, in handle_user_exception
    reraise(exc_type, exc_value, tb)
  File "/usr/local/lib/python3.4/dist-packages/flask/_compat.py", line 33, in reraise
    raise value
  File "/usr/local/lib/python3.4/dist-packages/flask/app.py", line 1475, in full_dispatch_request
    rv = self.dispatch_request()
  File "/usr/local/lib/python3.4/dist-packages/flask/app.py", line 1461, in dispatch_request
    return self.view_functions[rule.endpoint](**req.view_args)
  File "/service/timApp/tim.py", line 298, in show_question
    {"status": "results", "data": list_of_new_messages, "lastid": last_message_id,
  File "/usr/local/lib/python3.4/dist-packages/flask/templating.py", line 127, in render_template
    return _render(ctx.app.jinja_env.get_or_select_template(template_name_or_list),
  File "/usr/local/lib/python3.4/dist-packages/jinja2/environment.py", line 830, in get_or_select_template
    return self.get_template(template_name_or_list, parent, globals)
  File "/usr/local/lib/python3.4/dist-packages/jinja2/environment.py", line 791, in get_template
    return self._load_template(name, self.make_globals(globals))
  File "/usr/local/lib/python3.4/dist-packages/jinja2/environment.py", line 765, in _load_template
    template = self.loader.load(self, name, globals)
  File "/usr/local/lib/python3.4/dist-packages/jinja2/loaders.py", line 113, in load
    source, filename, uptodate = self.get_source(environment, name)
  File "/usr/local/lib/python3.4/dist-packages/flask/templating.py", line 64, in get_source
    raise TemplateNotFound(template)
jinja2.exceptions.TemplateNotFound: question.html
{"time":2015-04-23 07:50:12,255, "file": /usr/local/lib/python3.4/dist-packages/flask/app.py, "line" :1423, "messageLevel":  ERROR, "message": Exception on /question [GET]}
Traceback (most recent call last):
  File "/usr/local/lib/python3.4/dist-packages/flask/app.py", line 1817, in wsgi_app
    response = self.full_dispatch_request()
  File "/usr/local/lib/python3.4/dist-packages/flask/app.py", line 1477, in full_dispatch_request
    rv = self.handle_user_exception(e)
  File "/usr/local/lib/python3.4/dist-packages/flask/app.py", line 1381, in handle_user_exception
    reraise(exc_type, exc_value, tb)
  File "/usr/local/lib/python3.4/dist-packages/flask/_compat.py", line 33, in reraise
    raise value
  File "/usr/local/lib/python3.4/dist-packages/flask/app.py", line 1475, in full_dispatch_request
    rv = self.dispatch_request()
  File "/usr/local/lib/python3.4/dist-packages/flask/app.py", line 1461, in dispatch_request
    return self.view_functions[rule.endpoint](**req.view_args)
  File "/service/timApp/tim.py", line 298, in show_question
    {"status": "results", "data": list_of_new_messages, "lastid": last_message_id,
  File "/usr/local/lib/python3.4/dist-packages/flask/templating.py", line 127, in render_template
    return _render(ctx.app.jinja_env.get_or_select_template(template_name_or_list),
  File "/usr/local/lib/python3.4/dist-packages/jinja2/environment.py", line 830, in get_or_select_template
    return self.get_template(template_name_or_list, parent, globals)
  File "/usr/local/lib/python3.4/dist-packages/jinja2/environment.py", line 791, in get_template
    return self._load_template(name, self.make_globals(globals))
  File "/usr/local/lib/python3.4/dist-packages/jinja2/environment.py", line 765, in _load_template
    template = self.loader.load(self, name, globals)
  File "/usr/local/lib/python3.4/dist-packages/jinja2/loaders.py", line 113, in load
    source, filename, uptodate = self.get_source(environment, name)
  File "/usr/local/lib/python3.4/dist-packages/flask/templating.py", line 64, in get_source
    raise TemplateNotFound(template)
jinja2.exceptions.TemplateNotFound: question.html
{"time":2015-04-23 07:50:59,274, "file": /usr/local/lib/python3.4/dist-packages/flask/app.py, "line" :1423, "messageLevel":  ERROR, "message": Exception on /question [GET]}
Traceback (most recent call last):
  File "/usr/local/lib/python3.4/dist-packages/flask/app.py", line 1817, in wsgi_app
    response = self.full_dispatch_request()
  File "/usr/local/lib/python3.4/dist-packages/flask/app.py", line 1477, in full_dispatch_request
    rv = self.handle_user_exception(e)
  File "/usr/local/lib/python3.4/dist-packages/flask/app.py", line 1381, in handle_user_exception
    reraise(exc_type, exc_value, tb)
  File "/usr/local/lib/python3.4/dist-packages/flask/_compat.py", line 33, in reraise
    raise value
  File "/usr/local/lib/python3.4/dist-packages/flask/app.py", line 1475, in full_dispatch_request
    rv = self.dispatch_request()
  File "/usr/local/lib/python3.4/dist-packages/flask/app.py", line 1461, in dispatch_request
    return self.view_functions[rule.endpoint](**req.view_args)
  File "/service/timApp/tim.py", line 298, in show_question
    {"status": "results", "data": list_of_new_messages, "lastid": last_message_id,
  File "/usr/local/lib/python3.4/dist-packages/flask/templating.py", line 127, in render_template
    return _render(ctx.app.jinja_env.get_or_select_template(template_name_or_list),
  File "/usr/local/lib/python3.4/dist-packages/jinja2/environment.py", line 830, in get_or_select_template
    return self.get_template(template_name_or_list, parent, globals)
  File "/usr/local/lib/python3.4/dist-packages/jinja2/environment.py", line 791, in get_template
    return self._load_template(name, self.make_globals(globals))
  File "/usr/local/lib/python3.4/dist-packages/jinja2/environment.py", line 765, in _load_template
    template = self.loader.load(self, name, globals)
  File "/usr/local/lib/python3.4/dist-packages/jinja2/loaders.py", line 113, in load
    source, filename, uptodate = self.get_source(environment, name)
  File "/usr/local/lib/python3.4/dist-packages/flask/templating.py", line 64, in get_source
    raise TemplateNotFound(template)
jinja2.exceptions.TemplateNotFound: question.html
{"time":2015-04-23 07:51:17,233, "file": /usr/local/lib/python3.4/dist-packages/flask/app.py, "line" :1423, "messageLevel":  ERROR, "message": Exception on /question [GET]}
Traceback (most recent call last):
  File "/usr/local/lib/python3.4/dist-packages/flask/app.py", line 1817, in wsgi_app
    response = self.full_dispatch_request()
  File "/usr/local/lib/python3.4/dist-packages/flask/app.py", line 1477, in full_dispatch_request
    rv = self.handle_user_exception(e)
  File "/usr/local/lib/python3.4/dist-packages/flask/app.py", line 1381, in handle_user_exception
    reraise(exc_type, exc_value, tb)
  File "/usr/local/lib/python3.4/dist-packages/flask/_compat.py", line 33, in reraise
    raise value
  File "/usr/local/lib/python3.4/dist-packages/flask/app.py", line 1475, in full_dispatch_request
    rv = self.dispatch_request()
  File "/usr/local/lib/python3.4/dist-packages/flask/app.py", line 1461, in dispatch_request
    return self.view_functions[rule.endpoint](**req.view_args)
  File "/service/timApp/tim.py", line 298, in show_question
    {"status": "results", "data": list_of_new_messages, "lastid": last_message_id,
  File "/usr/local/lib/python3.4/dist-packages/flask/templating.py", line 127, in render_template
    return _render(ctx.app.jinja_env.get_or_select_template(template_name_or_list),
  File "/usr/local/lib/python3.4/dist-packages/jinja2/environment.py", line 830, in get_or_select_template
    return self.get_template(template_name_or_list, parent, globals)
  File "/usr/local/lib/python3.4/dist-packages/jinja2/environment.py", line 791, in get_template
    return self._load_template(name, self.make_globals(globals))
  File "/usr/local/lib/python3.4/dist-packages/jinja2/environment.py", line 765, in _load_template
    template = self.loader.load(self, name, globals)
  File "/usr/local/lib/python3.4/dist-packages/jinja2/loaders.py", line 113, in load
    source, filename, uptodate = self.get_source(environment, name)
  File "/usr/local/lib/python3.4/dist-packages/flask/templating.py", line 64, in get_source
    raise TemplateNotFound(template)
jinja2.exceptions.TemplateNotFound: question.html
{"time":2015-04-23 07:51:37,579, "file": /usr/local/lib/python3.4/dist-packages/flask/app.py, "line" :1423, "messageLevel":  ERROR, "message": Exception on /question [GET]}
Traceback (most recent call last):
  File "/usr/local/lib/python3.4/dist-packages/flask/app.py", line 1817, in wsgi_app
    response = self.full_dispatch_request()
  File "/usr/local/lib/python3.4/dist-packages/flask/app.py", line 1477, in full_dispatch_request
    rv = self.handle_user_exception(e)
  File "/usr/local/lib/python3.4/dist-packages/flask/app.py", line 1381, in handle_user_exception
    reraise(exc_type, exc_value, tb)
  File "/usr/local/lib/python3.4/dist-packages/flask/_compat.py", line 33, in reraise
    raise value
  File "/usr/local/lib/python3.4/dist-packages/flask/app.py", line 1475, in full_dispatch_request
    rv = self.dispatch_request()
  File "/usr/local/lib/python3.4/dist-packages/flask/app.py", line 1461, in dispatch_request
    return self.view_functions[rule.endpoint](**req.view_args)
  File "/service/timApp/tim.py", line 298, in show_question
    {"status": "results", "data": list_of_new_messages, "lastid": last_message_id,
  File "/usr/local/lib/python3.4/dist-packages/flask/templating.py", line 127, in render_template
    return _render(ctx.app.jinja_env.get_or_select_template(template_name_or_list),
  File "/usr/local/lib/python3.4/dist-packages/jinja2/environment.py", line 830, in get_or_select_template
    return self.get_template(template_name_or_list, parent, globals)
  File "/usr/local/lib/python3.4/dist-packages/jinja2/environment.py", line 791, in get_template
    return self._load_template(name, self.make_globals(globals))
  File "/usr/local/lib/python3.4/dist-packages/jinja2/environment.py", line 765, in _load_template
    template = self.loader.load(self, name, globals)
  File "/usr/local/lib/python3.4/dist-packages/jinja2/loaders.py", line 113, in load
    source, filename, uptodate = self.get_source(environment, name)
  File "/usr/local/lib/python3.4/dist-packages/flask/templating.py", line 64, in get_source
    raise TemplateNotFound(template)
jinja2.exceptions.TemplateNotFound: question.html
{"time":2015-04-23 07:52:18,805, "file": /usr/local/lib/python3.4/dist-packages/flask/app.py, "line" :1423, "messageLevel":  ERROR, "message": Exception on /question [GET]}
Traceback (most recent call last):
  File "/usr/local/lib/python3.4/dist-packages/flask/app.py", line 1817, in wsgi_app
    response = self.full_dispatch_request()
  File "/usr/local/lib/python3.4/dist-packages/flask/app.py", line 1477, in full_dispatch_request
    rv = self.handle_user_exception(e)
  File "/usr/local/lib/python3.4/dist-packages/flask/app.py", line 1381, in handle_user_exception
    reraise(exc_type, exc_value, tb)
  File "/usr/local/lib/python3.4/dist-packages/flask/_compat.py", line 33, in reraise
    raise value
  File "/usr/local/lib/python3.4/dist-packages/flask/app.py", line 1475, in full_dispatch_request
    rv = self.dispatch_request()
  File "/usr/local/lib/python3.4/dist-packages/flask/app.py", line 1461, in dispatch_request
    return self.view_functions[rule.endpoint](**req.view_args)
  File "/service/timApp/tim.py", line 298, in show_question
    {"status": "results", "data": list_of_new_messages, "lastid": last_message_id,
  File "/usr/local/lib/python3.4/dist-packages/flask/templating.py", line 127, in render_template
    return _render(ctx.app.jinja_env.get_or_select_template(template_name_or_list),
  File "/usr/local/lib/python3.4/dist-packages/jinja2/environment.py", line 830, in get_or_select_template
    return self.get_template(template_name_or_list, parent, globals)
  File "/usr/local/lib/python3.4/dist-packages/jinja2/environment.py", line 791, in get_template
    return self._load_template(name, self.make_globals(globals))
  File "/usr/local/lib/python3.4/dist-packages/jinja2/environment.py", line 765, in _load_template
    template = self.loader.load(self, name, globals)
  File "/usr/local/lib/python3.4/dist-packages/jinja2/loaders.py", line 113, in load
    source, filename, uptodate = self.get_source(environment, name)
  File "/usr/local/lib/python3.4/dist-packages/flask/templating.py", line 64, in get_source
    raise TemplateNotFound(template)
jinja2.exceptions.TemplateNotFound: question.html
{"time":2015-04-23 07:53:28,645, "file": /usr/local/lib/python3.4/dist-packages/flask/app.py, "line" :1423, "messageLevel":  ERROR, "message": Exception on /question [GET]}
Traceback (most recent call last):
  File "/usr/local/lib/python3.4/dist-packages/flask/app.py", line 1817, in wsgi_app
    response = self.full_dispatch_request()
  File "/usr/local/lib/python3.4/dist-packages/flask/app.py", line 1477, in full_dispatch_request
    rv = self.handle_user_exception(e)
  File "/usr/local/lib/python3.4/dist-packages/flask/app.py", line 1381, in handle_user_exception
    reraise(exc_type, exc_value, tb)
  File "/usr/local/lib/python3.4/dist-packages/flask/_compat.py", line 33, in reraise
    raise value
  File "/usr/local/lib/python3.4/dist-packages/flask/app.py", line 1475, in full_dispatch_request
    rv = self.dispatch_request()
  File "/usr/local/lib/python3.4/dist-packages/flask/app.py", line 1461, in dispatch_request
    return self.view_functions[rule.endpoint](**req.view_args)
  File "/service/timApp/tim.py", line 298, in show_question
    {"status": "results", "data": list_of_new_messages, "lastid": last_message_id,
  File "/usr/local/lib/python3.4/dist-packages/flask/templating.py", line 127, in render_template
    return _render(ctx.app.jinja_env.get_or_select_template(template_name_or_list),
  File "/usr/local/lib/python3.4/dist-packages/jinja2/environment.py", line 830, in get_or_select_template
    return self.get_template(template_name_or_list, parent, globals)
  File "/usr/local/lib/python3.4/dist-packages/jinja2/environment.py", line 791, in get_template
    return self._load_template(name, self.make_globals(globals))
  File "/usr/local/lib/python3.4/dist-packages/jinja2/environment.py", line 765, in _load_template
    template = self.loader.load(self, name, globals)
  File "/usr/local/lib/python3.4/dist-packages/jinja2/loaders.py", line 113, in load
    source, filename, uptodate = self.get_source(environment, name)
  File "/usr/local/lib/python3.4/dist-packages/flask/templating.py", line 64, in get_source
    raise TemplateNotFound(template)
jinja2.exceptions.TemplateNotFound: question.html
{"time":2015-04-23 07:54:24,311, "file": /usr/local/lib/python3.4/dist-packages/flask/app.py, "line" :1423, "messageLevel":  ERROR, "message": Exception on /question [GET]}
Traceback (most recent call last):
  File "/usr/local/lib/python3.4/dist-packages/flask/app.py", line 1817, in wsgi_app
    response = self.full_dispatch_request()
  File "/usr/local/lib/python3.4/dist-packages/flask/app.py", line 1477, in full_dispatch_request
    rv = self.handle_user_exception(e)
  File "/usr/local/lib/python3.4/dist-packages/flask/app.py", line 1381, in handle_user_exception
    reraise(exc_type, exc_value, tb)
  File "/usr/local/lib/python3.4/dist-packages/flask/_compat.py", line 33, in reraise
    raise value
  File "/usr/local/lib/python3.4/dist-packages/flask/app.py", line 1475, in full_dispatch_request
    rv = self.dispatch_request()
  File "/usr/local/lib/python3.4/dist-packages/flask/app.py", line 1461, in dispatch_request
    return self.view_functions[rule.endpoint](**req.view_args)
  File "/service/timApp/tim.py", line 298, in show_question
    {"status": "results", "data": list_of_new_messages, "lastid": last_message_id,
  File "/usr/local/lib/python3.4/dist-packages/flask/templating.py", line 127, in render_template
    return _render(ctx.app.jinja_env.get_or_select_template(template_name_or_list),
  File "/usr/local/lib/python3.4/dist-packages/jinja2/environment.py", line 830, in get_or_select_template
    return self.get_template(template_name_or_list, parent, globals)
  File "/usr/local/lib/python3.4/dist-packages/jinja2/environment.py", line 791, in get_template
    return self._load_template(name, self.make_globals(globals))
  File "/usr/local/lib/python3.4/dist-packages/jinja2/environment.py", line 765, in _load_template
    template = self.loader.load(self, name, globals)
  File "/usr/local/lib/python3.4/dist-packages/jinja2/loaders.py", line 113, in load
    source, filename, uptodate = self.get_source(environment, name)
  File "/usr/local/lib/python3.4/dist-packages/flask/templating.py", line 64, in get_source
    raise TemplateNotFound(template)
jinja2.exceptions.TemplateNotFound: question.html
{"time":2015-04-23 07:55:07,729, "file": /usr/local/lib/python3.4/dist-packages/flask/app.py, "line" :1423, "messageLevel":  ERROR, "message": Exception on /question [GET]}
Traceback (most recent call last):
  File "/usr/local/lib/python3.4/dist-packages/flask/app.py", line 1817, in wsgi_app
    response = self.full_dispatch_request()
  File "/usr/local/lib/python3.4/dist-packages/flask/app.py", line 1477, in full_dispatch_request
    rv = self.handle_user_exception(e)
  File "/usr/local/lib/python3.4/dist-packages/flask/app.py", line 1381, in handle_user_exception
    reraise(exc_type, exc_value, tb)
  File "/usr/local/lib/python3.4/dist-packages/flask/_compat.py", line 33, in reraise
    raise value
  File "/usr/local/lib/python3.4/dist-packages/flask/app.py", line 1475, in full_dispatch_request
    rv = self.dispatch_request()
  File "/usr/local/lib/python3.4/dist-packages/flask/app.py", line 1461, in dispatch_request
    return self.view_functions[rule.endpoint](**req.view_args)
  File "/service/timApp/tim.py", line 298, in show_question
    {"status": "results", "data": list_of_new_messages, "lastid": last_message_id,
  File "/usr/local/lib/python3.4/dist-packages/flask/templating.py", line 127, in render_template
    return _render(ctx.app.jinja_env.get_or_select_template(template_name_or_list),
  File "/usr/local/lib/python3.4/dist-packages/jinja2/environment.py", line 830, in get_or_select_template
    return self.get_template(template_name_or_list, parent, globals)
  File "/usr/local/lib/python3.4/dist-packages/jinja2/environment.py", line 791, in get_template
    return self._load_template(name, self.make_globals(globals))
  File "/usr/local/lib/python3.4/dist-packages/jinja2/environment.py", line 765, in _load_template
    template = self.loader.load(self, name, globals)
  File "/usr/local/lib/python3.4/dist-packages/jinja2/loaders.py", line 113, in load
    source, filename, uptodate = self.get_source(environment, name)
  File "/usr/local/lib/python3.4/dist-packages/flask/templating.py", line 64, in get_source
    raise TemplateNotFound(template)
jinja2.exceptions.TemplateNotFound: question.html
{"time":2015-04-23 07:55:34,091, "file": /usr/local/lib/python3.4/dist-packages/flask/app.py, "line" :1423, "messageLevel":  ERROR, "message": Exception on /question [GET]}
Traceback (most recent call last):
  File "/usr/local/lib/python3.4/dist-packages/flask/app.py", line 1817, in wsgi_app
    response = self.full_dispatch_request()
  File "/usr/local/lib/python3.4/dist-packages/flask/app.py", line 1477, in full_dispatch_request
    rv = self.handle_user_exception(e)
  File "/usr/local/lib/python3.4/dist-packages/flask/app.py", line 1381, in handle_user_exception
    reraise(exc_type, exc_value, tb)
  File "/usr/local/lib/python3.4/dist-packages/flask/_compat.py", line 33, in reraise
    raise value
  File "/usr/local/lib/python3.4/dist-packages/flask/app.py", line 1475, in full_dispatch_request
    rv = self.dispatch_request()
  File "/usr/local/lib/python3.4/dist-packages/flask/app.py", line 1461, in dispatch_request
    return self.view_functions[rule.endpoint](**req.view_args)
  File "/service/timApp/tim.py", line 298, in show_question
    {"status": "results", "data": list_of_new_messages, "lastid": last_message_id,
  File "/usr/local/lib/python3.4/dist-packages/flask/templating.py", line 127, in render_template
    return _render(ctx.app.jinja_env.get_or_select_template(template_name_or_list),
  File "/usr/local/lib/python3.4/dist-packages/jinja2/environment.py", line 830, in get_or_select_template
    return self.get_template(template_name_or_list, parent, globals)
  File "/usr/local/lib/python3.4/dist-packages/jinja2/environment.py", line 791, in get_template
    return self._load_template(name, self.make_globals(globals))
  File "/usr/local/lib/python3.4/dist-packages/jinja2/environment.py", line 765, in _load_template
    template = self.loader.load(self, name, globals)
  File "/usr/local/lib/python3.4/dist-packages/jinja2/loaders.py", line 113, in load
    source, filename, uptodate = self.get_source(environment, name)
  File "/usr/local/lib/python3.4/dist-packages/flask/templating.py", line 64, in get_source
    raise TemplateNotFound(template)
jinja2.exceptions.TemplateNotFound: question.html
{"time":2015-04-23 07:57:11,557, "file": /usr/local/lib/python3.4/dist-packages/flask/app.py, "line" :1423, "messageLevel":  ERROR, "message": Exception on /question [GET]}
Traceback (most recent call last):
  File "/usr/local/lib/python3.4/dist-packages/flask/app.py", line 1817, in wsgi_app
    response = self.full_dispatch_request()
  File "/usr/local/lib/python3.4/dist-packages/flask/app.py", line 1477, in full_dispatch_request
    rv = self.handle_user_exception(e)
  File "/usr/local/lib/python3.4/dist-packages/flask/app.py", line 1381, in handle_user_exception
    reraise(exc_type, exc_value, tb)
  File "/usr/local/lib/python3.4/dist-packages/flask/_compat.py", line 33, in reraise
    raise value
  File "/usr/local/lib/python3.4/dist-packages/flask/app.py", line 1475, in full_dispatch_request
    rv = self.dispatch_request()
  File "/usr/local/lib/python3.4/dist-packages/flask/app.py", line 1461, in dispatch_request
    return self.view_functions[rule.endpoint](**req.view_args)
  File "/service/timApp/tim.py", line 298, in show_question
    {"status": "results", "data": list_of_new_messages, "lastid": last_message_id,
  File "/usr/local/lib/python3.4/dist-packages/flask/templating.py", line 127, in render_template
    return _render(ctx.app.jinja_env.get_or_select_template(template_name_or_list),
  File "/usr/local/lib/python3.4/dist-packages/jinja2/environment.py", line 830, in get_or_select_template
    return self.get_template(template_name_or_list, parent, globals)
  File "/usr/local/lib/python3.4/dist-packages/jinja2/environment.py", line 791, in get_template
    return self._load_template(name, self.make_globals(globals))
  File "/usr/local/lib/python3.4/dist-packages/jinja2/environment.py", line 765, in _load_template
    template = self.loader.load(self, name, globals)
  File "/usr/local/lib/python3.4/dist-packages/jinja2/loaders.py", line 113, in load
    source, filename, uptodate = self.get_source(environment, name)
  File "/usr/local/lib/python3.4/dist-packages/flask/templating.py", line 64, in get_source
    raise TemplateNotFound(template)
jinja2.exceptions.TemplateNotFound: question.html
{"time":2015-04-23 07:57:59,354, "file": /usr/local/lib/python3.4/dist-packages/flask/app.py, "line" :1423, "messageLevel":  ERROR, "message": Exception on /question [GET]}
Traceback (most recent call last):
  File "/usr/local/lib/python3.4/dist-packages/flask/app.py", line 1817, in wsgi_app
    response = self.full_dispatch_request()
  File "/usr/local/lib/python3.4/dist-packages/flask/app.py", line 1477, in full_dispatch_request
    rv = self.handle_user_exception(e)
  File "/usr/local/lib/python3.4/dist-packages/flask/app.py", line 1381, in handle_user_exception
    reraise(exc_type, exc_value, tb)
  File "/usr/local/lib/python3.4/dist-packages/flask/_compat.py", line 33, in reraise
    raise value
  File "/usr/local/lib/python3.4/dist-packages/flask/app.py", line 1475, in full_dispatch_request
    rv = self.dispatch_request()
  File "/usr/local/lib/python3.4/dist-packages/flask/app.py", line 1461, in dispatch_request
    return self.view_functions[rule.endpoint](**req.view_args)
  File "/service/timApp/tim.py", line 298, in show_question
    {"status": "results", "data": list_of_new_messages, "lastid": last_message_id,
  File "/usr/local/lib/python3.4/dist-packages/flask/templating.py", line 127, in render_template
    return _render(ctx.app.jinja_env.get_or_select_template(template_name_or_list),
  File "/usr/local/lib/python3.4/dist-packages/jinja2/environment.py", line 830, in get_or_select_template
    return self.get_template(template_name_or_list, parent, globals)
  File "/usr/local/lib/python3.4/dist-packages/jinja2/environment.py", line 791, in get_template
    return self._load_template(name, self.make_globals(globals))
  File "/usr/local/lib/python3.4/dist-packages/jinja2/environment.py", line 765, in _load_template
    template = self.loader.load(self, name, globals)
  File "/usr/local/lib/python3.4/dist-packages/jinja2/loaders.py", line 113, in load
    source, filename, uptodate = self.get_source(environment, name)
  File "/usr/local/lib/python3.4/dist-packages/flask/templating.py", line 64, in get_source
    raise TemplateNotFound(template)
jinja2.exceptions.TemplateNotFound: question.html
{"time":2015-04-23 08:00:40,526, "file": /usr/local/lib/python3.4/dist-packages/flask/app.py, "line" :1423, "messageLevel":  ERROR, "message": Exception on /question [GET]}
Traceback (most recent call last):
  File "/usr/local/lib/python3.4/dist-packages/flask/app.py", line 1817, in wsgi_app
    response = self.full_dispatch_request()
  File "/usr/local/lib/python3.4/dist-packages/flask/app.py", line 1477, in full_dispatch_request
    rv = self.handle_user_exception(e)
  File "/usr/local/lib/python3.4/dist-packages/flask/app.py", line 1381, in handle_user_exception
    reraise(exc_type, exc_value, tb)
  File "/usr/local/lib/python3.4/dist-packages/flask/_compat.py", line 33, in reraise
    raise value
  File "/usr/local/lib/python3.4/dist-packages/flask/app.py", line 1475, in full_dispatch_request
    rv = self.dispatch_request()
  File "/usr/local/lib/python3.4/dist-packages/flask/app.py", line 1461, in dispatch_request
    return self.view_functions[rule.endpoint](**req.view_args)
  File "/service/timApp/tim.py", line 298, in show_question
    {"status": "results", "data": list_of_new_messages, "lastid": last_message_id,
  File "/usr/local/lib/python3.4/dist-packages/flask/templating.py", line 127, in render_template
    return _render(ctx.app.jinja_env.get_or_select_template(template_name_or_list),
  File "/usr/local/lib/python3.4/dist-packages/jinja2/environment.py", line 830, in get_or_select_template
    return self.get_template(template_name_or_list, parent, globals)
  File "/usr/local/lib/python3.4/dist-packages/jinja2/environment.py", line 791, in get_template
    return self._load_template(name, self.make_globals(globals))
  File "/usr/local/lib/python3.4/dist-packages/jinja2/environment.py", line 765, in _load_template
    template = self.loader.load(self, name, globals)
  File "/usr/local/lib/python3.4/dist-packages/jinja2/loaders.py", line 113, in load
    source, filename, uptodate = self.get_source(environment, name)
  File "/usr/local/lib/python3.4/dist-packages/flask/templating.py", line 64, in get_source
    raise TemplateNotFound(template)
jinja2.exceptions.TemplateNotFound: question.html
{"time":2015-04-23 08:01:17,015, "file": /usr/local/lib/python3.4/dist-packages/flask/app.py, "line" :1423, "messageLevel":  ERROR, "message": Exception on /question [GET]}
Traceback (most recent call last):
  File "/usr/local/lib/python3.4/dist-packages/flask/app.py", line 1817, in wsgi_app
    response = self.full_dispatch_request()
  File "/usr/local/lib/python3.4/dist-packages/flask/app.py", line 1477, in full_dispatch_request
    rv = self.handle_user_exception(e)
  File "/usr/local/lib/python3.4/dist-packages/flask/app.py", line 1381, in handle_user_exception
    reraise(exc_type, exc_value, tb)
  File "/usr/local/lib/python3.4/dist-packages/flask/_compat.py", line 33, in reraise
    raise value
  File "/usr/local/lib/python3.4/dist-packages/flask/app.py", line 1475, in full_dispatch_request
    rv = self.dispatch_request()
  File "/usr/local/lib/python3.4/dist-packages/flask/app.py", line 1461, in dispatch_request
    return self.view_functions[rule.endpoint](**req.view_args)
  File "/service/timApp/tim.py", line 298, in show_question
    {"status": "results", "data": list_of_new_messages, "lastid": last_message_id,
  File "/usr/local/lib/python3.4/dist-packages/flask/templating.py", line 127, in render_template
    return _render(ctx.app.jinja_env.get_or_select_template(template_name_or_list),
  File "/usr/local/lib/python3.4/dist-packages/jinja2/environment.py", line 830, in get_or_select_template
    return self.get_template(template_name_or_list, parent, globals)
  File "/usr/local/lib/python3.4/dist-packages/jinja2/environment.py", line 791, in get_template
    return self._load_template(name, self.make_globals(globals))
  File "/usr/local/lib/python3.4/dist-packages/jinja2/environment.py", line 765, in _load_template
    template = self.loader.load(self, name, globals)
  File "/usr/local/lib/python3.4/dist-packages/jinja2/loaders.py", line 113, in load
    source, filename, uptodate = self.get_source(environment, name)
  File "/usr/local/lib/python3.4/dist-packages/flask/templating.py", line 64, in get_source
    raise TemplateNotFound(template)
jinja2.exceptions.TemplateNotFound: question.html
{"time":2015-04-23 08:02:00,351, "file": /usr/local/lib/python3.4/dist-packages/flask/app.py, "line" :1423, "messageLevel":  ERROR, "message": Exception on /question [GET]}
Traceback (most recent call last):
  File "/usr/local/lib/python3.4/dist-packages/flask/app.py", line 1817, in wsgi_app
    response = self.full_dispatch_request()
  File "/usr/local/lib/python3.4/dist-packages/flask/app.py", line 1477, in full_dispatch_request
    rv = self.handle_user_exception(e)
  File "/usr/local/lib/python3.4/dist-packages/flask/app.py", line 1381, in handle_user_exception
    reraise(exc_type, exc_value, tb)
  File "/usr/local/lib/python3.4/dist-packages/flask/_compat.py", line 33, in reraise
    raise value
  File "/usr/local/lib/python3.4/dist-packages/flask/app.py", line 1475, in full_dispatch_request
    rv = self.dispatch_request()
  File "/usr/local/lib/python3.4/dist-packages/flask/app.py", line 1461, in dispatch_request
    return self.view_functions[rule.endpoint](**req.view_args)
  File "/service/timApp/tim.py", line 298, in show_question
    {"status": "results", "data": list_of_new_messages, "lastid": last_message_id,
  File "/usr/local/lib/python3.4/dist-packages/flask/templating.py", line 127, in render_template
    return _render(ctx.app.jinja_env.get_or_select_template(template_name_or_list),
  File "/usr/local/lib/python3.4/dist-packages/jinja2/environment.py", line 830, in get_or_select_template
    return self.get_template(template_name_or_list, parent, globals)
  File "/usr/local/lib/python3.4/dist-packages/jinja2/environment.py", line 791, in get_template
    return self._load_template(name, self.make_globals(globals))
  File "/usr/local/lib/python3.4/dist-packages/jinja2/environment.py", line 765, in _load_template
    template = self.loader.load(self, name, globals)
  File "/usr/local/lib/python3.4/dist-packages/jinja2/loaders.py", line 113, in load
    source, filename, uptodate = self.get_source(environment, name)
  File "/usr/local/lib/python3.4/dist-packages/flask/templating.py", line 64, in get_source
    raise TemplateNotFound(template)
jinja2.exceptions.TemplateNotFound: question.html
{"time":2015-04-23 08:02:13,553, "file": /usr/local/lib/python3.4/dist-packages/flask/app.py, "line" :1423, "messageLevel":  ERROR, "message": Exception on /question [GET]}
Traceback (most recent call last):
  File "/usr/local/lib/python3.4/dist-packages/flask/app.py", line 1817, in wsgi_app
    response = self.full_dispatch_request()
  File "/usr/local/lib/python3.4/dist-packages/flask/app.py", line 1477, in full_dispatch_request
    rv = self.handle_user_exception(e)
  File "/usr/local/lib/python3.4/dist-packages/flask/app.py", line 1381, in handle_user_exception
    reraise(exc_type, exc_value, tb)
  File "/usr/local/lib/python3.4/dist-packages/flask/_compat.py", line 33, in reraise
    raise value
  File "/usr/local/lib/python3.4/dist-packages/flask/app.py", line 1475, in full_dispatch_request
    rv = self.dispatch_request()
  File "/usr/local/lib/python3.4/dist-packages/flask/app.py", line 1461, in dispatch_request
    return self.view_functions[rule.endpoint](**req.view_args)
  File "/service/timApp/tim.py", line 298, in show_question
    {"status": "results", "data": list_of_new_messages, "lastid": last_message_id,
  File "/usr/local/lib/python3.4/dist-packages/flask/templating.py", line 127, in render_template
    return _render(ctx.app.jinja_env.get_or_select_template(template_name_or_list),
  File "/usr/local/lib/python3.4/dist-packages/jinja2/environment.py", line 830, in get_or_select_template
    return self.get_template(template_name_or_list, parent, globals)
  File "/usr/local/lib/python3.4/dist-packages/jinja2/environment.py", line 791, in get_template
    return self._load_template(name, self.make_globals(globals))
  File "/usr/local/lib/python3.4/dist-packages/jinja2/environment.py", line 765, in _load_template
    template = self.loader.load(self, name, globals)
  File "/usr/local/lib/python3.4/dist-packages/jinja2/loaders.py", line 113, in load
    source, filename, uptodate = self.get_source(environment, name)
  File "/usr/local/lib/python3.4/dist-packages/flask/templating.py", line 64, in get_source
    raise TemplateNotFound(template)
jinja2.exceptions.TemplateNotFound: question.html
{"time":2015-04-23 08:05:07,626, "file": /usr/local/lib/python3.4/dist-packages/flask/app.py, "line" :1423, "messageLevel":  ERROR, "message": Exception on /question [GET]}
Traceback (most recent call last):
  File "/usr/local/lib/python3.4/dist-packages/flask/app.py", line 1817, in wsgi_app
    response = self.full_dispatch_request()
  File "/usr/local/lib/python3.4/dist-packages/flask/app.py", line 1477, in full_dispatch_request
    rv = self.handle_user_exception(e)
  File "/usr/local/lib/python3.4/dist-packages/flask/app.py", line 1381, in handle_user_exception
    reraise(exc_type, exc_value, tb)
  File "/usr/local/lib/python3.4/dist-packages/flask/_compat.py", line 33, in reraise
    raise value
  File "/usr/local/lib/python3.4/dist-packages/flask/app.py", line 1475, in full_dispatch_request
    rv = self.dispatch_request()
  File "/usr/local/lib/python3.4/dist-packages/flask/app.py", line 1461, in dispatch_request
    return self.view_functions[rule.endpoint](**req.view_args)
  File "/service/timApp/tim.py", line 298, in show_question
    {"status": "results", "data": list_of_new_messages, "lastid": last_message_id,
  File "/usr/local/lib/python3.4/dist-packages/flask/templating.py", line 127, in render_template
    return _render(ctx.app.jinja_env.get_or_select_template(template_name_or_list),
  File "/usr/local/lib/python3.4/dist-packages/jinja2/environment.py", line 830, in get_or_select_template
    return self.get_template(template_name_or_list, parent, globals)
  File "/usr/local/lib/python3.4/dist-packages/jinja2/environment.py", line 791, in get_template
    return self._load_template(name, self.make_globals(globals))
  File "/usr/local/lib/python3.4/dist-packages/jinja2/environment.py", line 765, in _load_template
    template = self.loader.load(self, name, globals)
  File "/usr/local/lib/python3.4/dist-packages/jinja2/loaders.py", line 113, in load
    source, filename, uptodate = self.get_source(environment, name)
  File "/usr/local/lib/python3.4/dist-packages/flask/templating.py", line 64, in get_source
    raise TemplateNotFound(template)
jinja2.exceptions.TemplateNotFound: question.html
{"time":2015-04-23 08:05:15,188, "file": /usr/local/lib/python3.4/dist-packages/flask/app.py, "line" :1423, "messageLevel":  ERROR, "message": Exception on /question [GET]}
Traceback (most recent call last):
  File "/usr/local/lib/python3.4/dist-packages/flask/app.py", line 1817, in wsgi_app
    response = self.full_dispatch_request()
  File "/usr/local/lib/python3.4/dist-packages/flask/app.py", line 1477, in full_dispatch_request
    rv = self.handle_user_exception(e)
  File "/usr/local/lib/python3.4/dist-packages/flask/app.py", line 1381, in handle_user_exception
    reraise(exc_type, exc_value, tb)
  File "/usr/local/lib/python3.4/dist-packages/flask/_compat.py", line 33, in reraise
    raise value
  File "/usr/local/lib/python3.4/dist-packages/flask/app.py", line 1475, in full_dispatch_request
    rv = self.dispatch_request()
  File "/usr/local/lib/python3.4/dist-packages/flask/app.py", line 1461, in dispatch_request
    return self.view_functions[rule.endpoint](**req.view_args)
  File "/service/timApp/tim.py", line 298, in show_question
    {"status": "results", "data": list_of_new_messages, "lastid": last_message_id,
  File "/usr/local/lib/python3.4/dist-packages/flask/templating.py", line 127, in render_template
    return _render(ctx.app.jinja_env.get_or_select_template(template_name_or_list),
  File "/usr/local/lib/python3.4/dist-packages/jinja2/environment.py", line 830, in get_or_select_template
    return self.get_template(template_name_or_list, parent, globals)
  File "/usr/local/lib/python3.4/dist-packages/jinja2/environment.py", line 791, in get_template
    return self._load_template(name, self.make_globals(globals))
  File "/usr/local/lib/python3.4/dist-packages/jinja2/environment.py", line 765, in _load_template
    template = self.loader.load(self, name, globals)
  File "/usr/local/lib/python3.4/dist-packages/jinja2/loaders.py", line 113, in load
    source, filename, uptodate = self.get_source(environment, name)
  File "/usr/local/lib/python3.4/dist-packages/flask/templating.py", line 64, in get_source
    raise TemplateNotFound(template)
jinja2.exceptions.TemplateNotFound: question.html
