{"time":2015-04-12 14:04:49,384, "file": /usr/local/lib/python3.4/dist-packages/flask/app.py, "line" :1423, "messageLevel":  ERROR, "message": Exception on /view/testaus 3 [GET]}
Traceback (most recent call last):
  File "/usr/local/lib/python3.4/dist-packages/flask/app.py", line 1817, in wsgi_app
    response = self.full_dispatch_request()
  File "/usr/local/lib/python3.4/dist-packages/flask/app.py", line 1477, in full_dispatch_request
    rv = self.handle_user_exception(e)
  File "/usr/local/lib/python3.4/dist-packages/flask/app.py", line 1381, in handle_user_exception
    reraise(exc_type, exc_value, tb)
  File "/usr/local/lib/python3.4/dist-packages/flask/_compat.py", line 33, in reraise
    raise value
  File "/usr/local/lib/python3.4/dist-packages/flask/app.py", line 1475, in full_dispatch_request
    rv = self.dispatch_request()
  File "/usr/local/lib/python3.4/dist-packages/flask/app.py", line 1461, in dispatch_request
    return self.view_functions[rule.endpoint](**req.view_args)
  File "/service/timApp/routes/view.py", line 28, in view_document
    return view(doc_name, 'view_html.html', view_range)
  File "/service/timApp/routes/view.py", line 104, in view
    questions = timdb.questions.get_doc_questions(doc_id)
  File "<string>", line 2, in get_doc_questions
  File "/usr/local/lib/python3.4/dist-packages/contracts/main.py", line 266, in contracts_checker
    result = function_(*args, **kwargs)
  File "/service/timApp/timdb/questions.py", line 83, in get_doc_questions
    """, [doc_id])
sqlite3.OperationalError: no such column: doc_id
{"time":2015-04-12 14:08:19,909, "file": /usr/local/lib/python3.4/dist-packages/flask/app.py, "line" :1423, "messageLevel":  ERROR, "message": Exception on /view/testaus 3 [GET]}
Traceback (most recent call last):
  File "/usr/local/lib/python3.4/dist-packages/flask/app.py", line 1817, in wsgi_app
    response = self.full_dispatch_request()
  File "/usr/local/lib/python3.4/dist-packages/flask/app.py", line 1477, in full_dispatch_request
    rv = self.handle_user_exception(e)
  File "/usr/local/lib/python3.4/dist-packages/flask/app.py", line 1381, in handle_user_exception
    reraise(exc_type, exc_value, tb)
  File "/usr/local/lib/python3.4/dist-packages/flask/_compat.py", line 33, in reraise
    raise value
  File "/usr/local/lib/python3.4/dist-packages/flask/app.py", line 1475, in full_dispatch_request
    rv = self.dispatch_request()
  File "/usr/local/lib/python3.4/dist-packages/flask/app.py", line 1461, in dispatch_request
    return self.view_functions[rule.endpoint](**req.view_args)
  File "/service/timApp/routes/view.py", line 28, in view_document
    return view(doc_name, 'view_html.html', view_range)
  File "/service/timApp/routes/view.py", line 104, in view
    questions = timdb.questions.get_doc_questions(doc_id)
  File "<string>", line 2, in get_doc_questions
  File "/usr/local/lib/python3.4/dist-packages/contracts/main.py", line 266, in contracts_checker
    result = function_(*args, **kwargs)
  File "/service/timApp/timdb/questions.py", line 83, in get_doc_questions
    """, [doc_id])
sqlite3.OperationalError: no such column: doc_id
{"time":2015-04-12 14:08:52,086, "file": /usr/local/lib/python3.4/dist-packages/flask/app.py, "line" :1423, "messageLevel":  ERROR, "message": Exception on /view/testaus 3 [GET]}
Traceback (most recent call last):
  File "/usr/local/lib/python3.4/dist-packages/flask/app.py", line 1817, in wsgi_app
    response = self.full_dispatch_request()
  File "/usr/local/lib/python3.4/dist-packages/flask/app.py", line 1477, in full_dispatch_request
    rv = self.handle_user_exception(e)
  File "/usr/local/lib/python3.4/dist-packages/flask/app.py", line 1381, in handle_user_exception
    reraise(exc_type, exc_value, tb)
  File "/usr/local/lib/python3.4/dist-packages/flask/_compat.py", line 33, in reraise
    raise value
  File "/usr/local/lib/python3.4/dist-packages/flask/app.py", line 1475, in full_dispatch_request
    rv = self.dispatch_request()
  File "/usr/local/lib/python3.4/dist-packages/flask/app.py", line 1461, in dispatch_request
    return self.view_functions[rule.endpoint](**req.view_args)
  File "/service/timApp/routes/view.py", line 28, in view_document
    return view(doc_name, 'view_html.html', view_range)
  File "/service/timApp/routes/view.py", line 104, in view
    questions = timdb.questions.get_doc_questions(doc_id)
  File "<string>", line 2, in get_doc_questions
  File "/usr/local/lib/python3.4/dist-packages/contracts/main.py", line 266, in contracts_checker
    result = function_(*args, **kwargs)
  File "/service/timApp/timdb/questions.py", line 83, in get_doc_questions
    """, [doc_id])
sqlite3.OperationalError: no such column: doc_id
{"time":2015-04-12 14:18:52,112, "file": /usr/local/lib/python3.4/dist-packages/flask/app.py, "line" :1423, "messageLevel":  ERROR, "message": Exception on /view/testaus 3 [GET]}
Traceback (most recent call last):
  File "/usr/local/lib/python3.4/dist-packages/flask/app.py", line 1817, in wsgi_app
    response = self.full_dispatch_request()
  File "/usr/local/lib/python3.4/dist-packages/flask/app.py", line 1477, in full_dispatch_request
    rv = self.handle_user_exception(e)
  File "/usr/local/lib/python3.4/dist-packages/flask/app.py", line 1381, in handle_user_exception
    reraise(exc_type, exc_value, tb)
  File "/usr/local/lib/python3.4/dist-packages/flask/_compat.py", line 33, in reraise
    raise value
  File "/usr/local/lib/python3.4/dist-packages/flask/app.py", line 1475, in full_dispatch_request
    rv = self.dispatch_request()
  File "/usr/local/lib/python3.4/dist-packages/flask/app.py", line 1461, in dispatch_request
    return self.view_functions[rule.endpoint](**req.view_args)
  File "/service/timApp/routes/view.py", line 28, in view_document
    return view(doc_name, 'view_html.html', view_range)
  File "/service/timApp/routes/view.py", line 104, in view
    questions = timdb.questions.get_doc_questions(doc_id)
  File "<string>", line 2, in get_doc_questions
  File "/usr/local/lib/python3.4/dist-packages/contracts/main.py", line 266, in contracts_checker
    result = function_(*args, **kwargs)
  File "/service/timApp/timdb/questions.py", line 83, in get_doc_questions
    """, [doc_id])
sqlite3.OperationalError: no such column: doc_id
{"time":2015-04-12 14:43:03,465, "file": /usr/local/lib/python3.4/dist-packages/flask/app.py, "line" :1423, "messageLevel":  ERROR, "message": Exception on /view/Testaus 2 [GET]}
Traceback (most recent call last):
  File "/usr/local/lib/python3.4/dist-packages/flask/app.py", line 1817, in wsgi_app
    response = self.full_dispatch_request()
  File "/usr/local/lib/python3.4/dist-packages/flask/app.py", line 1477, in full_dispatch_request
    rv = self.handle_user_exception(e)
  File "/usr/local/lib/python3.4/dist-packages/flask/app.py", line 1381, in handle_user_exception
    reraise(exc_type, exc_value, tb)
  File "/usr/local/lib/python3.4/dist-packages/flask/_compat.py", line 33, in reraise
    raise value
  File "/usr/local/lib/python3.4/dist-packages/flask/app.py", line 1475, in full_dispatch_request
    rv = self.dispatch_request()
  File "/usr/local/lib/python3.4/dist-packages/flask/app.py", line 1461, in dispatch_request
    return self.view_functions[rule.endpoint](**req.view_args)
  File "/service/timApp/routes/view.py", line 28, in view_document
    return view(doc_name, 'view_html.html', view_range)
  File "/service/timApp/routes/view.py", line 104, in view
    questions = timdb.questions.get_doc_questions(doc_id)
  File "<string>", line 2, in get_doc_questions
  File "/usr/local/lib/python3.4/dist-packages/contracts/main.py", line 266, in contracts_checker
    result = function_(*args, **kwargs)
  File "/service/timApp/timdb/questions.py", line 83, in get_doc_questions
    """, [doc_id])
sqlite3.OperationalError: no such column: doc_id
{"time":2015-04-13 06:08:19,111, "file": /usr/local/lib/python3.4/dist-packages/flask/app.py, "line" :1423, "messageLevel":  ERROR, "message": Exception on /view/testaus 3 [GET]}
Traceback (most recent call last):
  File "/usr/local/lib/python3.4/dist-packages/flask/app.py", line 1817, in wsgi_app
    response = self.full_dispatch_request()
  File "/usr/local/lib/python3.4/dist-packages/flask/app.py", line 1477, in full_dispatch_request
    rv = self.handle_user_exception(e)
  File "/usr/local/lib/python3.4/dist-packages/flask/app.py", line 1381, in handle_user_exception
    reraise(exc_type, exc_value, tb)
  File "/usr/local/lib/python3.4/dist-packages/flask/_compat.py", line 33, in reraise
    raise value
  File "/usr/local/lib/python3.4/dist-packages/flask/app.py", line 1475, in full_dispatch_request
    rv = self.dispatch_request()
  File "/usr/local/lib/python3.4/dist-packages/flask/app.py", line 1461, in dispatch_request
    return self.view_functions[rule.endpoint](**req.view_args)
  File "/service/timApp/routes/view.py", line 28, in view_document
    return view(doc_name, 'view_html.html', view_range)
  File "/service/timApp/routes/view.py", line 104, in view
    questions = timdb.questions.get_doc_questions(doc_id)
  File "<string>", line 2, in get_doc_questions
  File "/usr/local/lib/python3.4/dist-packages/contracts/main.py", line 266, in contracts_checker
    result = function_(*args, **kwargs)
  File "/service/timApp/timdb/questions.py", line 83, in get_doc_questions
    """, [doc_id])
sqlite3.OperationalError: no such column: doc_id
{"time":2015-04-13 06:10:00,710, "file": /usr/local/lib/python3.4/dist-packages/flask/app.py, "line" :1423, "messageLevel":  ERROR, "message": Exception on /view/testaus 3 [GET]}
Traceback (most recent call last):
  File "/usr/local/lib/python3.4/dist-packages/flask/app.py", line 1817, in wsgi_app
    response = self.full_dispatch_request()
  File "/usr/local/lib/python3.4/dist-packages/flask/app.py", line 1477, in full_dispatch_request
    rv = self.handle_user_exception(e)
  File "/usr/local/lib/python3.4/dist-packages/flask/app.py", line 1381, in handle_user_exception
    reraise(exc_type, exc_value, tb)
  File "/usr/local/lib/python3.4/dist-packages/flask/_compat.py", line 33, in reraise
    raise value
  File "/usr/local/lib/python3.4/dist-packages/flask/app.py", line 1475, in full_dispatch_request
    rv = self.dispatch_request()
  File "/usr/local/lib/python3.4/dist-packages/flask/app.py", line 1461, in dispatch_request
    return self.view_functions[rule.endpoint](**req.view_args)
  File "/service/timApp/routes/view.py", line 28, in view_document
    return view(doc_name, 'view_html.html', view_range)
  File "/service/timApp/routes/view.py", line 104, in view
    questions = timdb.questions.get_doc_questions(doc_id)
  File "<string>", line 2, in get_doc_questions
  File "/usr/local/lib/python3.4/dist-packages/contracts/main.py", line 266, in contracts_checker
    result = function_(*args, **kwargs)
  File "/service/timApp/timdb/questions.py", line 83, in get_doc_questions
    """, [doc_id])
sqlite3.OperationalError: no such column: doc_id
{"time":2015-04-13 06:11:16,452, "file": /usr/local/lib/python3.4/dist-packages/flask/app.py, "line" :1423, "messageLevel":  ERROR, "message": Exception on /view/testaus 3 [GET]}
Traceback (most recent call last):
  File "/usr/local/lib/python3.4/dist-packages/flask/app.py", line 1817, in wsgi_app
    response = self.full_dispatch_request()
  File "/usr/local/lib/python3.4/dist-packages/flask/app.py", line 1477, in full_dispatch_request
    rv = self.handle_user_exception(e)
  File "/usr/local/lib/python3.4/dist-packages/flask/app.py", line 1381, in handle_user_exception
    reraise(exc_type, exc_value, tb)
  File "/usr/local/lib/python3.4/dist-packages/flask/_compat.py", line 33, in reraise
    raise value
  File "/usr/local/lib/python3.4/dist-packages/flask/app.py", line 1475, in full_dispatch_request
    rv = self.dispatch_request()
  File "/usr/local/lib/python3.4/dist-packages/flask/app.py", line 1461, in dispatch_request
    return self.view_functions[rule.endpoint](**req.view_args)
  File "/service/timApp/routes/view.py", line 28, in view_document
    return view(doc_name, 'view_html.html', view_range)
  File "/service/timApp/routes/view.py", line 104, in view
    questions = timdb.questions.get_doc_questions(doc_id)
  File "<string>", line 2, in get_doc_questions
  File "/usr/local/lib/python3.4/dist-packages/contracts/main.py", line 266, in contracts_checker
    result = function_(*args, **kwargs)
  File "/service/timApp/timdb/questions.py", line 83, in get_doc_questions
    """, [doc_id])
sqlite3.OperationalError: no such column: doc_id
{"time":2015-04-13 06:19:16,245, "file": /usr/local/lib/python3.4/dist-packages/flask/app.py, "line" :1423, "messageLevel":  ERROR, "message": Exception on /view/testaus 3 [GET]}
Traceback (most recent call last):
  File "/usr/local/lib/python3.4/dist-packages/flask/app.py", line 1817, in wsgi_app
    response = self.full_dispatch_request()
  File "/usr/local/lib/python3.4/dist-packages/flask/app.py", line 1477, in full_dispatch_request
    rv = self.handle_user_exception(e)
  File "/usr/local/lib/python3.4/dist-packages/flask/app.py", line 1381, in handle_user_exception
    reraise(exc_type, exc_value, tb)
  File "/usr/local/lib/python3.4/dist-packages/flask/_compat.py", line 33, in reraise
    raise value
  File "/usr/local/lib/python3.4/dist-packages/flask/app.py", line 1475, in full_dispatch_request
    rv = self.dispatch_request()
  File "/usr/local/lib/python3.4/dist-packages/flask/app.py", line 1461, in dispatch_request
    return self.view_functions[rule.endpoint](**req.view_args)
  File "/service/timApp/routes/view.py", line 28, in view_document
    return view(doc_name, 'view_html.html', view_range)
  File "/service/timApp/routes/view.py", line 104, in view
    questions = timdb.questions.get_doc_questions(doc_id)
  File "<string>", line 2, in get_doc_questions
  File "/usr/local/lib/python3.4/dist-packages/contracts/main.py", line 266, in contracts_checker
    result = function_(*args, **kwargs)
  File "/service/timApp/timdb/questions.py", line 83, in get_doc_questions
    """, [doc_id])
sqlite3.OperationalError: no such column: doc_id
{"time":2015-04-13 06:19:18,128, "file": /usr/local/lib/python3.4/dist-packages/flask/app.py, "line" :1423, "messageLevel":  ERROR, "message": Exception on /view/testaus 3 [GET]}
Traceback (most recent call last):
  File "/usr/local/lib/python3.4/dist-packages/flask/app.py", line 1817, in wsgi_app
    response = self.full_dispatch_request()
  File "/usr/local/lib/python3.4/dist-packages/flask/app.py", line 1477, in full_dispatch_request
    rv = self.handle_user_exception(e)
  File "/usr/local/lib/python3.4/dist-packages/flask/app.py", line 1381, in handle_user_exception
    reraise(exc_type, exc_value, tb)
  File "/usr/local/lib/python3.4/dist-packages/flask/_compat.py", line 33, in reraise
    raise value
  File "/usr/local/lib/python3.4/dist-packages/flask/app.py", line 1475, in full_dispatch_request
    rv = self.dispatch_request()
  File "/usr/local/lib/python3.4/dist-packages/flask/app.py", line 1461, in dispatch_request
    return self.view_functions[rule.endpoint](**req.view_args)
  File "/service/timApp/routes/view.py", line 28, in view_document
    return view(doc_name, 'view_html.html', view_range)
  File "/service/timApp/routes/view.py", line 104, in view
    questions = timdb.questions.get_doc_questions(doc_id)
  File "<string>", line 2, in get_doc_questions
  File "/usr/local/lib/python3.4/dist-packages/contracts/main.py", line 266, in contracts_checker
    result = function_(*args, **kwargs)
  File "/service/timApp/timdb/questions.py", line 83, in get_doc_questions
    """, [doc_id])
sqlite3.OperationalError: no such column: doc_id
{"time":2015-04-13 06:19:18,710, "file": /usr/local/lib/python3.4/dist-packages/flask/app.py, "line" :1423, "messageLevel":  ERROR, "message": Exception on /view/testaus 3 [GET]}
Traceback (most recent call last):
  File "/usr/local/lib/python3.4/dist-packages/flask/app.py", line 1817, in wsgi_app
    response = self.full_dispatch_request()
  File "/usr/local/lib/python3.4/dist-packages/flask/app.py", line 1477, in full_dispatch_request
    rv = self.handle_user_exception(e)
  File "/usr/local/lib/python3.4/dist-packages/flask/app.py", line 1381, in handle_user_exception
    reraise(exc_type, exc_value, tb)
  File "/usr/local/lib/python3.4/dist-packages/flask/_compat.py", line 33, in reraise
    raise value
  File "/usr/local/lib/python3.4/dist-packages/flask/app.py", line 1475, in full_dispatch_request
    rv = self.dispatch_request()
  File "/usr/local/lib/python3.4/dist-packages/flask/app.py", line 1461, in dispatch_request
    return self.view_functions[rule.endpoint](**req.view_args)
  File "/service/timApp/routes/view.py", line 28, in view_document
    return view(doc_name, 'view_html.html', view_range)
  File "/service/timApp/routes/view.py", line 104, in view
    questions = timdb.questions.get_doc_questions(doc_id)
  File "<string>", line 2, in get_doc_questions
  File "/usr/local/lib/python3.4/dist-packages/contracts/main.py", line 266, in contracts_checker
    result = function_(*args, **kwargs)
  File "/service/timApp/timdb/questions.py", line 83, in get_doc_questions
    """, [doc_id])
sqlite3.OperationalError: no such column: doc_id
{"time":2015-04-13 06:19:19,001, "file": /usr/local/lib/python3.4/dist-packages/flask/app.py, "line" :1423, "messageLevel":  ERROR, "message": Exception on /view/testaus 3 [GET]}
Traceback (most recent call last):
  File "/usr/local/lib/python3.4/dist-packages/flask/app.py", line 1817, in wsgi_app
    response = self.full_dispatch_request()
  File "/usr/local/lib/python3.4/dist-packages/flask/app.py", line 1477, in full_dispatch_request
    rv = self.handle_user_exception(e)
  File "/usr/local/lib/python3.4/dist-packages/flask/app.py", line 1381, in handle_user_exception
    reraise(exc_type, exc_value, tb)
  File "/usr/local/lib/python3.4/dist-packages/flask/_compat.py", line 33, in reraise
    raise value
  File "/usr/local/lib/python3.4/dist-packages/flask/app.py", line 1475, in full_dispatch_request
    rv = self.dispatch_request()
  File "/usr/local/lib/python3.4/dist-packages/flask/app.py", line 1461, in dispatch_request
    return self.view_functions[rule.endpoint](**req.view_args)
  File "/service/timApp/routes/view.py", line 28, in view_document
    return view(doc_name, 'view_html.html', view_range)
  File "/service/timApp/routes/view.py", line 104, in view
    questions = timdb.questions.get_doc_questions(doc_id)
  File "<string>", line 2, in get_doc_questions
  File "/usr/local/lib/python3.4/dist-packages/contracts/main.py", line 266, in contracts_checker
    result = function_(*args, **kwargs)
  File "/service/timApp/timdb/questions.py", line 83, in get_doc_questions
    """, [doc_id])
sqlite3.OperationalError: no such column: doc_id
{"time":2015-04-13 06:19:19,200, "file": /usr/local/lib/python3.4/dist-packages/flask/app.py, "line" :1423, "messageLevel":  ERROR, "message": Exception on /view/testaus 3 [GET]}
Traceback (most recent call last):
  File "/usr/local/lib/python3.4/dist-packages/flask/app.py", line 1817, in wsgi_app
    response = self.full_dispatch_request()
  File "/usr/local/lib/python3.4/dist-packages/flask/app.py", line 1477, in full_dispatch_request
    rv = self.handle_user_exception(e)
  File "/usr/local/lib/python3.4/dist-packages/flask/app.py", line 1381, in handle_user_exception
    reraise(exc_type, exc_value, tb)
  File "/usr/local/lib/python3.4/dist-packages/flask/_compat.py", line 33, in reraise
    raise value
  File "/usr/local/lib/python3.4/dist-packages/flask/app.py", line 1475, in full_dispatch_request
    rv = self.dispatch_request()
  File "/usr/local/lib/python3.4/dist-packages/flask/app.py", line 1461, in dispatch_request
    return self.view_functions[rule.endpoint](**req.view_args)
  File "/service/timApp/routes/view.py", line 28, in view_document
    return view(doc_name, 'view_html.html', view_range)
  File "/service/timApp/routes/view.py", line 104, in view
    questions = timdb.questions.get_doc_questions(doc_id)
  File "<string>", line 2, in get_doc_questions
  File "/usr/local/lib/python3.4/dist-packages/contracts/main.py", line 266, in contracts_checker
    result = function_(*args, **kwargs)
  File "/service/timApp/timdb/questions.py", line 83, in get_doc_questions
    """, [doc_id])
sqlite3.OperationalError: no such column: doc_id
{"time":2015-04-13 06:19:19,399, "file": /usr/local/lib/python3.4/dist-packages/flask/app.py, "line" :1423, "messageLevel":  ERROR, "message": Exception on /view/testaus 3 [GET]}
Traceback (most recent call last):
  File "/usr/local/lib/python3.4/dist-packages/flask/app.py", line 1817, in wsgi_app
    response = self.full_dispatch_request()
  File "/usr/local/lib/python3.4/dist-packages/flask/app.py", line 1477, in full_dispatch_request
    rv = self.handle_user_exception(e)
  File "/usr/local/lib/python3.4/dist-packages/flask/app.py", line 1381, in handle_user_exception
    reraise(exc_type, exc_value, tb)
  File "/usr/local/lib/python3.4/dist-packages/flask/_compat.py", line 33, in reraise
    raise value
  File "/usr/local/lib/python3.4/dist-packages/flask/app.py", line 1475, in full_dispatch_request
    rv = self.dispatch_request()
  File "/usr/local/lib/python3.4/dist-packages/flask/app.py", line 1461, in dispatch_request
    return self.view_functions[rule.endpoint](**req.view_args)
  File "/service/timApp/routes/view.py", line 28, in view_document
    return view(doc_name, 'view_html.html', view_range)
  File "/service/timApp/routes/view.py", line 104, in view
    questions = timdb.questions.get_doc_questions(doc_id)
  File "<string>", line 2, in get_doc_questions
  File "/usr/local/lib/python3.4/dist-packages/contracts/main.py", line 266, in contracts_checker
    result = function_(*args, **kwargs)
  File "/service/timApp/timdb/questions.py", line 83, in get_doc_questions
    """, [doc_id])
sqlite3.OperationalError: no such column: doc_id
{"time":2015-04-13 06:19:24,365, "file": /usr/local/lib/python3.4/dist-packages/flask/app.py, "line" :1423, "messageLevel":  ERROR, "message": Exception on /view/testaus 3 [GET]}
Traceback (most recent call last):
  File "/usr/local/lib/python3.4/dist-packages/flask/app.py", line 1817, in wsgi_app
    response = self.full_dispatch_request()
  File "/usr/local/lib/python3.4/dist-packages/flask/app.py", line 1477, in full_dispatch_request
    rv = self.handle_user_exception(e)
  File "/usr/local/lib/python3.4/dist-packages/flask/app.py", line 1381, in handle_user_exception
    reraise(exc_type, exc_value, tb)
  File "/usr/local/lib/python3.4/dist-packages/flask/_compat.py", line 33, in reraise
    raise value
  File "/usr/local/lib/python3.4/dist-packages/flask/app.py", line 1475, in full_dispatch_request
    rv = self.dispatch_request()
  File "/usr/local/lib/python3.4/dist-packages/flask/app.py", line 1461, in dispatch_request
    return self.view_functions[rule.endpoint](**req.view_args)
  File "/service/timApp/routes/view.py", line 28, in view_document
    return view(doc_name, 'view_html.html', view_range)
  File "/service/timApp/routes/view.py", line 104, in view
    questions = timdb.questions.get_doc_questions(doc_id)
  File "<string>", line 2, in get_doc_questions
  File "/usr/local/lib/python3.4/dist-packages/contracts/main.py", line 266, in contracts_checker
    result = function_(*args, **kwargs)
  File "/service/timApp/timdb/questions.py", line 83, in get_doc_questions
    """, [doc_id])
sqlite3.OperationalError: no such column: doc_id
{"time":2015-04-13 06:19:27,980, "file": /usr/local/lib/python3.4/dist-packages/flask/app.py, "line" :1423, "messageLevel":  ERROR, "message": Exception on /view/testaus 3 [GET]}
Traceback (most recent call last):
  File "/usr/local/lib/python3.4/dist-packages/flask/app.py", line 1817, in wsgi_app
    response = self.full_dispatch_request()
  File "/usr/local/lib/python3.4/dist-packages/flask/app.py", line 1477, in full_dispatch_request
    rv = self.handle_user_exception(e)
  File "/usr/local/lib/python3.4/dist-packages/flask/app.py", line 1381, in handle_user_exception
    reraise(exc_type, exc_value, tb)
  File "/usr/local/lib/python3.4/dist-packages/flask/_compat.py", line 33, in reraise
    raise value
  File "/usr/local/lib/python3.4/dist-packages/flask/app.py", line 1475, in full_dispatch_request
    rv = self.dispatch_request()
  File "/usr/local/lib/python3.4/dist-packages/flask/app.py", line 1461, in dispatch_request
    return self.view_functions[rule.endpoint](**req.view_args)
  File "/service/timApp/routes/view.py", line 28, in view_document
    return view(doc_name, 'view_html.html', view_range)
  File "/service/timApp/routes/view.py", line 104, in view
    questions = timdb.questions.get_doc_questions(doc_id)
  File "<string>", line 2, in get_doc_questions
  File "/usr/local/lib/python3.4/dist-packages/contracts/main.py", line 266, in contracts_checker
    result = function_(*args, **kwargs)
  File "/service/timApp/timdb/questions.py", line 83, in get_doc_questions
    """, [doc_id])
sqlite3.OperationalError: no such column: doc_id
