/service/timber/sphinx/timApp.rst:19: WARNING: autodoc: failed to import module 'timApp.ReverseProxied'; the following exception was raised:
Traceback (most recent call last):
  File "/usr/local/lib/python3.5/dist-packages/sphinx/ext/autodoc.py", line 519, in import_object
    __import__(self.modname)
ImportError: No module named 'timApp'
/service/timber/sphinx/timApp.rst:27: WARNING: autodoc: failed to import module 'timApp.assessment_area'; the following exception was raised:
Traceback (most recent call last):
  File "/usr/local/lib/python3.5/dist-packages/sphinx/ext/autodoc.py", line 519, in import_object
    __import__(self.modname)
ImportError: No module named 'timApp'
/service/timber/sphinx/timApp.rst:35: WARNING: autodoc: failed to import module 'timApp.containerLink'; the following exception was raised:
Traceback (most recent call last):
  File "/usr/local/lib/python3.5/dist-packages/sphinx/ext/autodoc.py", line 519, in import_object
    __import__(self.modname)
ImportError: No module named 'timApp'
/service/timber/sphinx/timApp.rst:43: WARNING: autodoc: failed to import module 'timApp.debugconfig'; the following exception was raised:
Traceback (most recent call last):
  File "/usr/local/lib/python3.5/dist-packages/sphinx/ext/autodoc.py", line 519, in import_object
    __import__(self.modname)
ImportError: No module named 'timApp'
/service/timber/sphinx/timApp.rst:51: WARNING: autodoc: failed to import module 'timApp.decorators'; the following exception was raised:
Traceback (most recent call last):
  File "/usr/local/lib/python3.5/dist-packages/sphinx/ext/autodoc.py", line 519, in import_object
    __import__(self.modname)
ImportError: No module named 'timApp'
/service/timber/sphinx/timApp.rst:59: WARNING: autodoc: failed to import module 'timApp.defaultconfig'; the following exception was raised:
Traceback (most recent call last):
  File "/usr/local/lib/python3.5/dist-packages/sphinx/ext/autodoc.py", line 519, in import_object
    __import__(self.modname)
ImportError: No module named 'timApp'
/service/timber/sphinx/timApp.rst:67: WARNING: autodoc: failed to import module 'timApp.dumboclient'; the following exception was raised:
Traceback (most recent call last):
  File "/usr/local/lib/python3.5/dist-packages/sphinx/ext/autodoc.py", line 519, in import_object
    __import__(self.modname)
ImportError: No module named 'timApp'
/service/timber/sphinx/timApp.rst:75: WARNING: autodoc: failed to import module 'timApp.filemodehelper'; the following exception was raised:
Traceback (most recent call last):
  File "/usr/local/lib/python3.5/dist-packages/sphinx/ext/autodoc.py", line 519, in import_object
    __import__(self.modname)
ImportError: No module named 'timApp'
/service/timber/sphinx/timApp.rst:83: WARNING: autodoc: failed to import module 'timApp.gunicornconf'; the following exception was raised:
Traceback (most recent call last):
  File "/usr/local/lib/python3.5/dist-packages/sphinx/ext/autodoc.py", line 519, in import_object
    __import__(self.modname)
ImportError: No module named 'timApp'
/service/timber/sphinx/timApp.rst:91: WARNING: autodoc: failed to import module 'timApp.htmlSanitize'; the following exception was raised:
Traceback (most recent call last):
  File "/usr/local/lib/python3.5/dist-packages/sphinx/ext/autodoc.py", line 519, in import_object
    __import__(self.modname)
ImportError: No module named 'timApp'
/service/timber/sphinx/timApp.rst:99: WARNING: autodoc: failed to import module 'timApp.initdb2'; the following exception was raised:
Traceback (most recent call last):
  File "/usr/local/lib/python3.5/dist-packages/sphinx/ext/autodoc.py", line 519, in import_object
    __import__(self.modname)
ImportError: No module named 'timApp'
/service/timber/sphinx/timApp.rst:107: WARNING: autodoc: failed to import module 'timApp.launch'; the following exception was raised:
Traceback (most recent call last):
  File "/usr/local/lib/python3.5/dist-packages/sphinx/ext/autodoc.py", line 519, in import_object
    __import__(self.modname)
ImportError: No module named 'timApp'
/service/timber/sphinx/timApp.rst:115: WARNING: autodoc: failed to import module 'timApp.markdownconverter'; the following exception was raised:
Traceback (most recent call last):
  File "/usr/local/lib/python3.5/dist-packages/sphinx/ext/autodoc.py", line 519, in import_object
    __import__(self.modname)
ImportError: No module named 'timApp'
/service/timber/sphinx/timApp.rst:123: WARNING: autodoc: failed to import module 'timApp.mkfolders'; the following exception was raised:
Traceback (most recent call last):
  File "/usr/local/lib/python3.5/dist-packages/sphinx/ext/autodoc.py", line 519, in import_object
    __import__(self.modname)
ImportError: No module named 'timApp'
/service/timber/sphinx/timApp.rst:131: WARNING: autodoc: failed to import module 'timApp.models'; the following exception was raised:
Traceback (most recent call last):
  File "/usr/local/lib/python3.5/dist-packages/sphinx/ext/autodoc.py", line 519, in import_object
    __import__(self.modname)
ImportError: No module named 'timApp'
/service/timber/sphinx/timApp.rst:139: WARNING: autodoc: failed to import module 'timApp.options'; the following exception was raised:
Traceback (most recent call last):
  File "/usr/local/lib/python3.5/dist-packages/sphinx/ext/autodoc.py", line 519, in import_object
    __import__(self.modname)
ImportError: No module named 'timApp'
/service/timber/sphinx/timApp.rst:147: WARNING: autodoc: failed to import module 'timApp.plugin'; the following exception was raised:
Traceback (most recent call last):
  File "/usr/local/lib/python3.5/dist-packages/sphinx/ext/autodoc.py", line 519, in import_object
    __import__(self.modname)
ImportError: No module named 'timApp'
/service/timber/sphinx/timApp.rst:155: WARNING: autodoc: failed to import module 'timApp.pluginControl'; the following exception was raised:
Traceback (most recent call last):
  File "/usr/local/lib/python3.5/dist-packages/sphinx/ext/autodoc.py", line 519, in import_object
    __import__(self.modname)
ImportError: No module named 'timApp'
/service/timber/sphinx/timApp.rst:163: WARNING: autodoc: failed to import module 'timApp.productionconfig'; the following exception was raised:
Traceback (most recent call last):
  File "/usr/local/lib/python3.5/dist-packages/sphinx/ext/autodoc.py", line 519, in import_object
    __import__(self.modname)
ImportError: No module named 'timApp'
/service/timber/sphinx/timApp.rst:171: WARNING: autodoc: failed to import module 'timApp.profileconfig'; the following exception was raised:
Traceback (most recent call last):
  File "/usr/local/lib/python3.5/dist-packages/sphinx/ext/autodoc.py", line 519, in import_object
    __import__(self.modname)
ImportError: No module named 'timApp'
/service/timber/sphinx/timApp.rst:179: WARNING: autodoc: failed to import module 'timApp.query'; the following exception was raised:
Traceback (most recent call last):
  File "/usr/local/lib/python3.5/dist-packages/sphinx/ext/autodoc.py", line 519, in import_object
    __import__(self.modname)
ImportError: No module named 'timApp'
/service/timber/sphinx/timApp.rst:187: WARNING: autodoc: failed to import module 'timApp.test_answers'; the following exception was raised:
Traceback (most recent call last):
  File "/usr/local/lib/python3.5/dist-packages/sphinx/ext/autodoc.py", line 519, in import_object
    __import__(self.modname)
ImportError: No module named 'timApp'
/service/timber/sphinx/timApp.rst:195: WARNING: autodoc: failed to import module 'timApp.test_folders'; the following exception was raised:
Traceback (most recent call last):
  File "/usr/local/lib/python3.5/dist-packages/sphinx/ext/autodoc.py", line 519, in import_object
    __import__(self.modname)
ImportError: No module named 'timApp'
/service/timber/sphinx/timApp.rst:203: WARNING: autodoc: failed to import module 'timApp.test_groups'; the following exception was raised:
Traceback (most recent call last):
  File "/usr/local/lib/python3.5/dist-packages/sphinx/ext/autodoc.py", line 519, in import_object
    __import__(self.modname)
ImportError: No module named 'timApp'
/service/timber/sphinx/timApp.rst:211: WARNING: autodoc: failed to import module 'timApp.test_index'; the following exception was raised:
Traceback (most recent call last):
  File "/usr/local/lib/python3.5/dist-packages/sphinx/ext/autodoc.py", line 519, in import_object
    __import__(self.modname)
ImportError: No module named 'timApp'
/service/timber/sphinx/timApp.rst:219: WARNING: autodoc: failed to import module 'timApp.test_markdownconverter'; the following exception was raised:
Traceback (most recent call last):
  File "/usr/local/lib/python3.5/dist-packages/sphinx/ext/autodoc.py", line 519, in import_object
    __import__(self.modname)
ImportError: No module named 'timApp'
/service/timber/sphinx/timApp.rst:227: WARNING: autodoc: failed to import module 'timApp.test_plugins'; the following exception was raised:
Traceback (most recent call last):
  File "/usr/local/lib/python3.5/dist-packages/sphinx/ext/autodoc.py", line 519, in import_object
    __import__(self.modname)
ImportError: No module named 'timApp'
/service/timber/sphinx/timApp.rst:235: WARNING: autodoc: failed to import module 'timApp.test_readings'; the following exception was raised:
Traceback (most recent call last):
  File "/usr/local/lib/python3.5/dist-packages/sphinx/ext/autodoc.py", line 519, in import_object
    __import__(self.modname)
ImportError: No module named 'timApp'
/service/timber/sphinx/timApp.rst:243: WARNING: autodoc: failed to import module 'timApp.test_referencing'; the following exception was raised:
Traceback (most recent call last):
  File "/usr/local/lib/python3.5/dist-packages/sphinx/ext/autodoc.py", line 519, in import_object
    __import__(self.modname)
ImportError: No module named 'timApp'
/service/timber/sphinx/timApp.rst:251: WARNING: autodoc: failed to import module 'timApp.test_search'; the following exception was raised:
Traceback (most recent call last):
  File "/usr/local/lib/python3.5/dist-packages/sphinx/ext/autodoc.py", line 519, in import_object
    __import__(self.modname)
ImportError: No module named 'timApp'
/service/timber/sphinx/timApp.rst:259: WARNING: autodoc: failed to import module 'timApp.test_tim'; the following exception was raised:
Traceback (most recent call last):
  File "/usr/local/lib/python3.5/dist-packages/sphinx/ext/autodoc.py", line 519, in import_object
    __import__(self.modname)
ImportError: No module named 'timApp'
/service/timber/sphinx/timApp.rst:267: WARNING: autodoc: failed to import module 'timApp.test_upload'; the following exception was raised:
Traceback (most recent call last):
  File "/usr/local/lib/python3.5/dist-packages/sphinx/ext/autodoc.py", line 519, in import_object
    __import__(self.modname)
ImportError: No module named 'timApp'
/service/timber/sphinx/timApp.rst:275: WARNING: autodoc: failed to import module 'timApp.test_users'; the following exception was raised:
Traceback (most recent call last):
  File "/usr/local/lib/python3.5/dist-packages/sphinx/ext/autodoc.py", line 519, in import_object
    __import__(self.modname)
ImportError: No module named 'timApp'
/service/timber/sphinx/timApp.rst:283: WARNING: autodoc: failed to import module 'timApp.test_velp'; the following exception was raised:
Traceback (most recent call last):
  File "/usr/local/lib/python3.5/dist-packages/sphinx/ext/autodoc.py", line 519, in import_object
    __import__(self.modname)
ImportError: No module named 'timApp'
/service/timber/sphinx/timApp.rst:291: WARNING: autodoc: failed to import module 'timApp.testhelper'; the following exception was raised:
Traceback (most recent call last):
  File "/usr/local/lib/python3.5/dist-packages/sphinx/ext/autodoc.py", line 519, in import_object
    __import__(self.modname)
ImportError: No module named 'timApp'
/service/timber/sphinx/timApp.rst:299: WARNING: autodoc: failed to import module 'timApp.theme'; the following exception was raised:
Traceback (most recent call last):
  File "/usr/local/lib/python3.5/dist-packages/sphinx/ext/autodoc.py", line 519, in import_object
    __import__(self.modname)
ImportError: No module named 'timApp'
/service/timber/sphinx/timApp.rst:307: WARNING: autodoc: failed to import module 'timApp.tim'; the following exception was raised:
Traceback (most recent call last):
  File "/usr/local/lib/python3.5/dist-packages/sphinx/ext/autodoc.py", line 519, in import_object
    __import__(self.modname)
ImportError: No module named 'timApp'
/service/timber/sphinx/timApp.rst:315: WARNING: autodoc: failed to import module 'timApp.tim_app'; the following exception was raised:
Traceback (most recent call last):
  File "/usr/local/lib/python3.5/dist-packages/sphinx/ext/autodoc.py", line 519, in import_object
    __import__(self.modname)
ImportError: No module named 'timApp'
/service/timber/sphinx/timApp.rst:323: WARNING: autodoc: failed to import module 'timApp.timdbtest'; the following exception was raised:
Traceback (most recent call last):
  File "/usr/local/lib/python3.5/dist-packages/sphinx/ext/autodoc.py", line 519, in import_object
    __import__(self.modname)
ImportError: No module named 'timApp'
/service/timber/sphinx/timApp.rst:331: WARNING: autodoc: failed to import module 'timApp.timroutetest'; the following exception was raised:
Traceback (most recent call last):
  File "/usr/local/lib/python3.5/dist-packages/sphinx/ext/autodoc.py", line 519, in import_object
    __import__(self.modname)
ImportError: No module named 'timApp'
/service/timber/sphinx/timApp.rst:339: WARNING: autodoc: failed to import module 'timApp.update_pars'; the following exception was raised:
Traceback (most recent call last):
  File "/usr/local/lib/python3.5/dist-packages/sphinx/ext/autodoc.py", line 519, in import_object
    __import__(self.modname)
ImportError: No module named 'timApp'
/service/timber/sphinx/timApp.rst:347: WARNING: autodoc: failed to import module 'timApp.utils'; the following exception was raised:
Traceback (most recent call last):
  File "/usr/local/lib/python3.5/dist-packages/sphinx/ext/autodoc.py", line 519, in import_object
    __import__(self.modname)
ImportError: No module named 'timApp'
/service/timber/sphinx/timApp.rst:356: WARNING: autodoc: failed to import module 'timApp'; the following exception was raised:
Traceback (most recent call last):
  File "/usr/local/lib/python3.5/dist-packages/sphinx/ext/autodoc.py", line 519, in import_object
    __import__(self.modname)
ImportError: No module named 'timApp'
/service/timber/sphinx/timApp.documentmodel.rst:10: WARNING: autodoc: failed to import module 'timApp.documentmodel.attributeparser'; the following exception was raised:
Traceback (most recent call last):
  File "/usr/local/lib/python3.5/dist-packages/sphinx/ext/autodoc.py", line 519, in import_object
    __import__(self.modname)
ImportError: No module named 'timApp'
/service/timber/sphinx/timApp.documentmodel.rst:18: WARNING: autodoc: failed to import module 'timApp.documentmodel.clipboard'; the following exception was raised:
Traceback (most recent call last):
  File "/usr/local/lib/python3.5/dist-packages/sphinx/ext/autodoc.py", line 519, in import_object
    __import__(self.modname)
ImportError: No module named 'timApp'
/service/timber/sphinx/timApp.documentmodel.rst:26: WARNING: autodoc: failed to import module 'timApp.documentmodel.docparagraph'; the following exception was raised:
Traceback (most recent call last):
  File "/usr/local/lib/python3.5/dist-packages/sphinx/ext/autodoc.py", line 519, in import_object
    __import__(self.modname)
ImportError: No module named 'timApp'
/service/timber/sphinx/timApp.documentmodel.rst:34: WARNING: autodoc: failed to import module 'timApp.documentmodel.docparagraphencoder'; the following exception was raised:
Traceback (most recent call last):
  File "/usr/local/lib/python3.5/dist-packages/sphinx/ext/autodoc.py", line 519, in import_object
    __import__(self.modname)
ImportError: No module named 'timApp'
/service/timber/sphinx/timApp.documentmodel.rst:42: WARNING: autodoc: failed to import module 'timApp.documentmodel.docsettings'; the following exception was raised:
Traceback (most recent call last):
  File "/usr/local/lib/python3.5/dist-packages/sphinx/ext/autodoc.py", line 519, in import_object
    __import__(self.modname)
ImportError: No module named 'timApp'
/service/timber/sphinx/timApp.documentmodel.rst:50: WARNING: autodoc: failed to import module 'timApp.documentmodel.document'; the following exception was raised:
Traceback (most recent call last):
  File "/usr/local/lib/python3.5/dist-packages/sphinx/ext/autodoc.py", line 519, in import_object
    __import__(self.modname)
ImportError: No module named 'timApp'
/service/timber/sphinx/timApp.documentmodel.rst:58: WARNING: autodoc: failed to import module 'timApp.documentmodel.documentparser'; the following exception was raised:
Traceback (most recent call last):
  File "/usr/local/lib/python3.5/dist-packages/sphinx/ext/autodoc.py", line 519, in import_object
    __import__(self.modname)
ImportError: No module named 'timApp'
/service/timber/sphinx/timApp.documentmodel.rst:66: WARNING: autodoc: failed to import module 'timApp.documentmodel.documentparseroptions'; the following exception was raised:
Traceback (most recent call last):
  File "/usr/local/lib/python3.5/dist-packages/sphinx/ext/autodoc.py", line 519, in import_object
    __import__(self.modname)
ImportError: No module named 'timApp'
/service/timber/sphinx/timApp.documentmodel.rst:74: WARNING: autodoc: failed to import module 'timApp.documentmodel.documentversion'; the following exception was raised:
Traceback (most recent call last):
  File "/usr/local/lib/python3.5/dist-packages/sphinx/ext/autodoc.py", line 519, in import_object
    __import__(self.modname)
ImportError: No module named 'timApp'
/service/timber/sphinx/timApp.documentmodel.rst:82: WARNING: autodoc: failed to import module 'timApp.documentmodel.documentwriter'; the following exception was raised:
Traceback (most recent call last):
  File "/usr/local/lib/python3.5/dist-packages/sphinx/ext/autodoc.py", line 519, in import_object
    __import__(self.modname)
ImportError: No module named 'timApp'
/service/timber/sphinx/timApp.documentmodel.rst:90: WARNING: autodoc: failed to import module 'timApp.documentmodel.exceptions'; the following exception was raised:
Traceback (most recent call last):
  File "/usr/local/lib/python3.5/dist-packages/sphinx/ext/autodoc.py", line 519, in import_object
    __import__(self.modname)
ImportError: No module named 'timApp'
/service/timber/sphinx/timApp.documentmodel.rst:98: WARNING: autodoc: failed to import module 'timApp.documentmodel.randutils'; the following exception was raised:
Traceback (most recent call last):
  File "/usr/local/lib/python3.5/dist-packages/sphinx/ext/autodoc.py", line 519, in import_object
    __import__(self.modname)
ImportError: No module named 'timApp'
/service/timber/sphinx/timApp.documentmodel.rst:106: WARNING: autodoc: failed to import module 'timApp.documentmodel.test_attributeparser'; the following exception was raised:
Traceback (most recent call last):
  File "/usr/local/lib/python3.5/dist-packages/sphinx/ext/autodoc.py", line 519, in import_object
    __import__(self.modname)
ImportError: No module named 'timApp'
/service/timber/sphinx/timApp.documentmodel.rst:114: WARNING: autodoc: failed to import module 'timApp.documentmodel.test_clipboard'; the following exception was raised:
Traceback (most recent call last):
  File "/usr/local/lib/python3.5/dist-packages/sphinx/ext/autodoc.py", line 519, in import_object
    __import__(self.modname)
ImportError: No module named 'timApp'
/service/timber/sphinx/timApp.documentmodel.rst:122: WARNING: autodoc: failed to import module 'timApp.documentmodel.test_document'; the following exception was raised:
Traceback (most recent call last):
  File "/usr/local/lib/python3.5/dist-packages/sphinx/ext/autodoc.py", line 519, in import_object
    __import__(self.modname)
ImportError: No module named 'timApp'
/service/timber/sphinx/timApp.documentmodel.rst:130: WARNING: autodoc: failed to import module 'timApp.documentmodel.test_documentparser'; the following exception was raised:
Traceback (most recent call last):
  File "/usr/local/lib/python3.5/dist-packages/sphinx/ext/autodoc.py", line 519, in import_object
    __import__(self.modname)
ImportError: No module named 'timApp'
/service/timber/sphinx/timApp.documentmodel.rst:138: WARNING: autodoc: failed to import module 'timApp.documentmodel.test_references'; the following exception was raised:
Traceback (most recent call last):
  File "/usr/local/lib/python3.5/dist-packages/sphinx/ext/autodoc.py", line 519, in import_object
    __import__(self.modname)
ImportError: No module named 'timApp'
/service/timber/sphinx/timApp.documentmodel.rst:147: WARNING: autodoc: failed to import module 'timApp.documentmodel'; the following exception was raised:
Traceback (most recent call last):
  File "/usr/local/lib/python3.5/dist-packages/sphinx/ext/autodoc.py", line 519, in import_object
    __import__(self.modname)
ImportError: No module named 'timApp'
/service/timber/sphinx/timApp.routes.rst:10: WARNING: autodoc: failed to import module 'timApp.routes.annotation'; the following exception was raised:
Traceback (most recent call last):
  File "/usr/local/lib/python3.5/dist-packages/sphinx/ext/autodoc.py", line 519, in import_object
    __import__(self.modname)
ImportError: No module named 'timApp'
/service/timber/sphinx/timApp.routes.rst:18: WARNING: autodoc: failed to import module 'timApp.routes.answer'; the following exception was raised:
Traceback (most recent call last):
  File "/usr/local/lib/python3.5/dist-packages/sphinx/ext/autodoc.py", line 519, in import_object
    __import__(self.modname)
ImportError: No module named 'timApp'
/service/timber/sphinx/timApp.routes.rst:26: WARNING: autodoc: failed to import module 'timApp.routes.cache'; the following exception was raised:
Traceback (most recent call last):
  File "/usr/local/lib/python3.5/dist-packages/sphinx/ext/autodoc.py", line 519, in import_object
    __import__(self.modname)
ImportError: No module named 'timApp'
/service/timber/sphinx/timApp.routes.rst:34: WARNING: autodoc: failed to import module 'timApp.routes.clipboard'; the following exception was raised:
Traceback (most recent call last):
  File "/usr/local/lib/python3.5/dist-packages/sphinx/ext/autodoc.py", line 519, in import_object
    __import__(self.modname)
ImportError: No module named 'timApp'
/service/timber/sphinx/timApp.routes.rst:42: WARNING: autodoc: failed to import module 'timApp.routes.common'; the following exception was raised:
Traceback (most recent call last):
  File "/usr/local/lib/python3.5/dist-packages/sphinx/ext/autodoc.py", line 519, in import_object
    __import__(self.modname)
ImportError: No module named 'timApp'
/service/timber/sphinx/timApp.routes.rst:50: WARNING: autodoc: failed to import module 'timApp.routes.edit'; the following exception was raised:
Traceback (most recent call last):
  File "/usr/local/lib/python3.5/dist-packages/sphinx/ext/autodoc.py", line 519, in import_object
    __import__(self.modname)
ImportError: No module named 'timApp'
/service/timber/sphinx/timApp.routes.rst:58: WARNING: autodoc: failed to import module 'timApp.routes.filters'; the following exception was raised:
Traceback (most recent call last):
  File "/usr/local/lib/python3.5/dist-packages/sphinx/ext/autodoc.py", line 519, in import_object
    __import__(self.modname)
ImportError: No module named 'timApp'
/service/timber/sphinx/timApp.routes.rst:66: WARNING: autodoc: failed to import module 'timApp.routes.groups'; the following exception was raised:
Traceback (most recent call last):
  File "/usr/local/lib/python3.5/dist-packages/sphinx/ext/autodoc.py", line 519, in import_object
    __import__(self.modname)
ImportError: No module named 'timApp'
/service/timber/sphinx/timApp.routes.rst:74: WARNING: autodoc: failed to import module 'timApp.routes.lecture'; the following exception was raised:
Traceback (most recent call last):
  File "/usr/local/lib/python3.5/dist-packages/sphinx/ext/autodoc.py", line 519, in import_object
    __import__(self.modname)
ImportError: No module named 'timApp'
/service/timber/sphinx/timApp.routes.rst:82: WARNING: autodoc: failed to import module 'timApp.routes.logger'; the following exception was raised:
Traceback (most recent call last):
  File "/usr/local/lib/python3.5/dist-packages/sphinx/ext/autodoc.py", line 519, in import_object
    __import__(self.modname)
ImportError: No module named 'timApp'
/service/timber/sphinx/timApp.routes.rst:90: WARNING: autodoc: failed to import module 'timApp.routes.login'; the following exception was raised:
Traceback (most recent call last):
  File "/usr/local/lib/python3.5/dist-packages/sphinx/ext/autodoc.py", line 519, in import_object
    __import__(self.modname)
ImportError: No module named 'timApp'
/service/timber/sphinx/timApp.routes.rst:98: WARNING: autodoc: failed to import module 'timApp.routes.manage'; the following exception was raised:
Traceback (most recent call last):
  File "/usr/local/lib/python3.5/dist-packages/sphinx/ext/autodoc.py", line 519, in import_object
    __import__(self.modname)
ImportError: No module named 'timApp'
/service/timber/sphinx/timApp.routes.rst:106: WARNING: autodoc: failed to import module 'timApp.routes.notes'; the following exception was raised:
Traceback (most recent call last):
  File "/usr/local/lib/python3.5/dist-packages/sphinx/ext/autodoc.py", line 519, in import_object
    __import__(self.modname)
ImportError: No module named 'timApp'
/service/timber/sphinx/timApp.routes.rst:114: WARNING: autodoc: failed to import module 'timApp.routes.notify'; the following exception was raised:
Traceback (most recent call last):
  File "/usr/local/lib/python3.5/dist-packages/sphinx/ext/autodoc.py", line 519, in import_object
    __import__(self.modname)
ImportError: No module named 'timApp'
/service/timber/sphinx/timApp.routes.rst:122: WARNING: autodoc: failed to import module 'timApp.routes.readings'; the following exception was raised:
Traceback (most recent call last):
  File "/usr/local/lib/python3.5/dist-packages/sphinx/ext/autodoc.py", line 519, in import_object
    __import__(self.modname)
ImportError: No module named 'timApp'
/service/timber/sphinx/timApp.routes.rst:130: WARNING: autodoc: failed to import module 'timApp.routes.search'; the following exception was raised:
Traceback (most recent call last):
  File "/usr/local/lib/python3.5/dist-packages/sphinx/ext/autodoc.py", line 519, in import_object
    __import__(self.modname)
ImportError: No module named 'timApp'
/service/timber/sphinx/timApp.routes.rst:138: WARNING: autodoc: failed to import module 'timApp.routes.settings'; the following exception was raised:
Traceback (most recent call last):
  File "/usr/local/lib/python3.5/dist-packages/sphinx/ext/autodoc.py", line 519, in import_object
    __import__(self.modname)
ImportError: No module named 'timApp'
/service/timber/sphinx/timApp.routes.rst:146: WARNING: autodoc: failed to import module 'timApp.routes.upload'; the following exception was raised:
Traceback (most recent call last):
  File "/usr/local/lib/python3.5/dist-packages/sphinx/ext/autodoc.py", line 519, in import_object
    __import__(self.modname)
ImportError: No module named 'timApp'
/service/timber/sphinx/timApp.routes.rst:154: WARNING: autodoc: failed to import module 'timApp.routes.velp'; the following exception was raised:
Traceback (most recent call last):
  File "/usr/local/lib/python3.5/dist-packages/sphinx/ext/autodoc.py", line 519, in import_object
    __import__(self.modname)
ImportError: No module named 'timApp'
/service/timber/sphinx/timApp.routes.rst:162: WARNING: autodoc: failed to import module 'timApp.routes.view'; the following exception was raised:
Traceback (most recent call last):
  File "/usr/local/lib/python3.5/dist-packages/sphinx/ext/autodoc.py", line 519, in import_object
    __import__(self.modname)
ImportError: No module named 'timApp'
/service/timber/sphinx/timApp.routes.rst:171: WARNING: autodoc: failed to import module 'timApp.routes'; the following exception was raised:
Traceback (most recent call last):
  File "/usr/local/lib/python3.5/dist-packages/sphinx/ext/autodoc.py", line 519, in import_object
    __import__(self.modname)
ImportError: No module named 'timApp'
/service/timber/sphinx/timApp.timdb.rst:10: WARNING: autodoc: failed to import module 'timApp.timdb.annotations'; the following exception was raised:
Traceback (most recent call last):
  File "/usr/local/lib/python3.5/dist-packages/sphinx/ext/autodoc.py", line 519, in import_object
    __import__(self.modname)
ImportError: No module named 'timApp'
/service/timber/sphinx/timApp.timdb.rst:18: WARNING: autodoc: failed to import module 'timApp.timdb.answers'; the following exception was raised:
Traceback (most recent call last):
  File "/usr/local/lib/python3.5/dist-packages/sphinx/ext/autodoc.py", line 519, in import_object
    __import__(self.modname)
ImportError: No module named 'timApp'
/service/timber/sphinx/timApp.timdb.rst:26: WARNING: autodoc: failed to import module 'timApp.timdb.documents'; the following exception was raised:
Traceback (most recent call last):
  File "/usr/local/lib/python3.5/dist-packages/sphinx/ext/autodoc.py", line 519, in import_object
    __import__(self.modname)
ImportError: No module named 'timApp'
/service/timber/sphinx/timApp.timdb.rst:34: WARNING: autodoc: failed to import module 'timApp.timdb.files'; the following exception was raised:
Traceback (most recent call last):
  File "/usr/local/lib/python3.5/dist-packages/sphinx/ext/autodoc.py", line 519, in import_object
    __import__(self.modname)
ImportError: No module named 'timApp'
/service/timber/sphinx/timApp.timdb.rst:42: WARNING: autodoc: failed to import module 'timApp.timdb.folders'; the following exception was raised:
Traceback (most recent call last):
  File "/usr/local/lib/python3.5/dist-packages/sphinx/ext/autodoc.py", line 519, in import_object
    __import__(self.modname)
ImportError: No module named 'timApp'
/service/timber/sphinx/timApp.timdb.rst:50: WARNING: autodoc: failed to import module 'timApp.timdb.icons'; the following exception was raised:
Traceback (most recent call last):
  File "/usr/local/lib/python3.5/dist-packages/sphinx/ext/autodoc.py", line 519, in import_object
    __import__(self.modname)
ImportError: No module named 'timApp'
/service/timber/sphinx/timApp.timdb.rst:58: WARNING: autodoc: failed to import module 'timApp.timdb.images'; the following exception was raised:
Traceback (most recent call last):
  File "/usr/local/lib/python3.5/dist-packages/sphinx/ext/autodoc.py", line 519, in import_object
    __import__(self.modname)
ImportError: No module named 'timApp'
/service/timber/sphinx/timApp.timdb.rst:66: WARNING: autodoc: failed to import module 'timApp.timdb.lectureanswers'; the following exception was raised:
Traceback (most recent call last):
  File "/usr/local/lib/python3.5/dist-packages/sphinx/ext/autodoc.py", line 519, in import_object
    __import__(self.modname)
ImportError: No module named 'timApp'
/service/timber/sphinx/timApp.timdb.rst:74: WARNING: autodoc: failed to import module 'timApp.timdb.lectures'; the following exception was raised:
Traceback (most recent call last):
  File "/usr/local/lib/python3.5/dist-packages/sphinx/ext/autodoc.py", line 519, in import_object
    __import__(self.modname)
ImportError: No module named 'timApp'
/service/timber/sphinx/timApp.timdb.rst:82: WARNING: autodoc: failed to import module 'timApp.timdb.messages'; the following exception was raised:
Traceback (most recent call last):
  File "/usr/local/lib/python3.5/dist-packages/sphinx/ext/autodoc.py", line 519, in import_object
    __import__(self.modname)
ImportError: No module named 'timApp'
/service/timber/sphinx/timApp.timdb.rst:90: WARNING: autodoc: failed to import module 'timApp.timdb.newanswers'; the following exception was raised:
Traceback (most recent call last):
  File "/usr/local/lib/python3.5/dist-packages/sphinx/ext/autodoc.py", line 519, in import_object
    __import__(self.modname)
ImportError: No module named 'timApp'
/service/timber/sphinx/timApp.timdb.rst:98: WARNING: autodoc: failed to import module 'timApp.timdb.notes'; the following exception was raised:
Traceback (most recent call last):
  File "/usr/local/lib/python3.5/dist-packages/sphinx/ext/autodoc.py", line 519, in import_object
    __import__(self.modname)
ImportError: No module named 'timApp'
/service/timber/sphinx/timApp.timdb.rst:106: WARNING: autodoc: failed to import module 'timApp.timdb.questions'; the following exception was raised:
Traceback (most recent call last):
  File "/usr/local/lib/python3.5/dist-packages/sphinx/ext/autodoc.py", line 519, in import_object
    __import__(self.modname)
ImportError: No module named 'timApp'
/service/timber/sphinx/timApp.timdb.rst:114: WARNING: autodoc: failed to import module 'timApp.timdb.readings'; the following exception was raised:
Traceback (most recent call last):
  File "/usr/local/lib/python3.5/dist-packages/sphinx/ext/autodoc.py", line 519, in import_object
    __import__(self.modname)
ImportError: No module named 'timApp'
/service/timber/sphinx/timApp.timdb.rst:122: WARNING: autodoc: failed to import module 'timApp.timdb.runningquestion'; the following exception was raised:
Traceback (most recent call last):
  File "/usr/local/lib/python3.5/dist-packages/sphinx/ext/autodoc.py", line 519, in import_object
    __import__(self.modname)
ImportError: No module named 'timApp'
/service/timber/sphinx/timApp.timdb.rst:130: WARNING: autodoc: failed to import module 'timApp.timdb.showpoints'; the following exception was raised:
Traceback (most recent call last):
  File "/usr/local/lib/python3.5/dist-packages/sphinx/ext/autodoc.py", line 519, in import_object
    __import__(self.modname)
ImportError: No module named 'timApp'
/service/timber/sphinx/timApp.timdb.rst:138: WARNING: autodoc: failed to import module 'timApp.timdb.slidestatus'; the following exception was raised:
Traceback (most recent call last):
  File "/usr/local/lib/python3.5/dist-packages/sphinx/ext/autodoc.py", line 519, in import_object
    __import__(self.modname)
ImportError: No module named 'timApp'
/service/timber/sphinx/timApp.timdb.rst:146: WARNING: autodoc: failed to import module 'timApp.timdb.temp_info_for_user'; the following exception was raised:
Traceback (most recent call last):
  File "/usr/local/lib/python3.5/dist-packages/sphinx/ext/autodoc.py", line 519, in import_object
    __import__(self.modname)
ImportError: No module named 'timApp'
/service/timber/sphinx/timApp.timdb.rst:154: WARNING: autodoc: failed to import module 'timApp.timdb.tempdbbase'; the following exception was raised:
Traceback (most recent call last):
  File "/usr/local/lib/python3.5/dist-packages/sphinx/ext/autodoc.py", line 519, in import_object
    __import__(self.modname)
ImportError: No module named 'timApp'
/service/timber/sphinx/timApp.timdb.rst:162: WARNING: autodoc: failed to import module 'timApp.timdb.timdb2'; the following exception was raised:
Traceback (most recent call last):
  File "/usr/local/lib/python3.5/dist-packages/sphinx/ext/autodoc.py", line 519, in import_object
    __import__(self.modname)
ImportError: No module named 'timApp'
/service/timber/sphinx/timApp.timdb.rst:170: WARNING: autodoc: failed to import module 'timApp.timdb.timdbbase'; the following exception was raised:
Traceback (most recent call last):
  File "/usr/local/lib/python3.5/dist-packages/sphinx/ext/autodoc.py", line 519, in import_object
    __import__(self.modname)
ImportError: No module named 'timApp'
/service/timber/sphinx/timApp.timdb.rst:178: WARNING: autodoc: failed to import module 'timApp.timdb.useractivity'; the following exception was raised:
Traceback (most recent call last):
  File "/usr/local/lib/python3.5/dist-packages/sphinx/ext/autodoc.py", line 519, in import_object
    __import__(self.modname)
ImportError: No module named 'timApp'
/service/timber/sphinx/timApp.timdb.rst:186: WARNING: autodoc: failed to import module 'timApp.timdb.users'; the following exception was raised:
Traceback (most recent call last):
  File "/usr/local/lib/python3.5/dist-packages/sphinx/ext/autodoc.py", line 519, in import_object
    __import__(self.modname)
ImportError: No module named 'timApp'
/service/timber/sphinx/timApp.timdb.rst:194: WARNING: autodoc: failed to import module 'timApp.timdb.velpgrouplabels'; the following exception was raised:
Traceback (most recent call last):
  File "/usr/local/lib/python3.5/dist-packages/sphinx/ext/autodoc.py", line 519, in import_object
    __import__(self.modname)
ImportError: No module named 'timApp'
/service/timber/sphinx/timApp.timdb.rst:202: WARNING: autodoc: failed to import module 'timApp.timdb.velpgroups'; the following exception was raised:
Traceback (most recent call last):
  File "/usr/local/lib/python3.5/dist-packages/sphinx/ext/autodoc.py", line 519, in import_object
    __import__(self.modname)
ImportError: No module named 'timApp'
/service/timber/sphinx/timApp.timdb.rst:210: WARNING: autodoc: failed to import module 'timApp.timdb.velps'; the following exception was raised:
Traceback (most recent call last):
  File "/usr/local/lib/python3.5/dist-packages/sphinx/ext/autodoc.py", line 519, in import_object
    __import__(self.modname)
ImportError: No module named 'timApp'
/service/timber/sphinx/timApp.timdb.rst:219: WARNING: autodoc: failed to import module 'timApp.timdb'; the following exception was raised:
Traceback (most recent call last):
  File "/usr/local/lib/python3.5/dist-packages/sphinx/ext/autodoc.py", line 519, in import_object
    __import__(self.modname)
ImportError: No module named 'timApp'
/service/timber/sphinx/modules.rst:: WARNING: document isn't included in any toctree
